Workbook

Sheet декабрь 2023
B1: ОТГРУЗКИ ПРОДУКЦИИ | C1: 45261
A2: заметки | B2: НОМЕР ЗАКАЗА | C2: КЛИЕНТ | D2: ПРОДУКТ | E2: ПАРТИЯ | F2: КОЛИЧЕСТВО | H2: ПУНКТ НАЗНАЧЕНИЯ | I2: СТАТУС | J2: ДАТА ОТГРУЗКИ | K2: АВТОДОСТАВКА | N2: ЖД ДОСТАВКА | O2: ИТОГО ОТГРУЖЕНО | R2: АКТЫ
F3: КГ | G3: мешков/бочек | K3: № АВТО | L3: ТЕЛ. ВОДИТЕЛЯ | M3: ВОДИТЕЛЬ | N3: № КОНТЕЙНЕРА | O3: ЧП | P3: ИНАЯ | Q3: Жидкий | S3: Цена со склада за 1 тонну | T3: Итого
B4: Спец№75 | C4: СБМ | D4: СБМСУЛЬФ | E4: 161123 | F4: 20000 | G4: 800 | H4: самовывоз | I4: отгружено | J4: 45261 | K4: Камаз А 317 УА 33 | L4: 8920-013-08-45 | M4: Тимофеев Анатолий | O4: 20000 | R4: + | S4: 41000 | T4: =S4*(F4/1000) -> 820000
A5: авто | B5: ИСК20618-20 | C5: Петроинжиниринг | D5: BLACKTROL ж - 200 кг п/эт | E5: 171023 | F5: 8000 | G5: 40 | H5: Ноябрьск | I5: отгружено | J5: 45261 | K5: Вольво С 931 ЕМ 51 | L5: 8921-297-46-13 | M5: Киреев Сергей | Q5: 8000 | R5: + | S5: 82000 | T5: =S5*(F5/1000) -> 656000
B6: ИСК20618-20 | C6: Петроинжиниринг | D6: BLACKTROL ж - 200 кг п/эт | E6: 181023 | F6: 7200 | G6: 36 | H6: Ноябрьск | I6: отгружено | J6: 45261 | Q6: 7200 | R6: + | S6: 82000 | T6: =S6*(F6/1000) -> 590400
B7: ИСК20618-20 | C7: Петроинжиниринг | D7: BLACKTROL ж - 200 кг п/эт | E7: 191023 | F7: 1600 | G7: 8 | H7: Ноябрьск | I7: отгружено | J7: 45261 | Q7: 1600 | R7: + | S7: 82000 | T7: =S7*(F7/1000) -> 131200
B8: ИСК20618-20 | C8: Петроинжиниринг | D8: BLACKTROL ж - 200 кг п/эт | E8: 221023 | F8: 600 | G8: 3 | H8: Ноябрьск | I8: отгружено | J8: 45261 | Q8: 600 | R8: + | S8: 82000 | T8: =S8*(F8/1000) -> 49200
B9: ИСК20618-20 | C9: Петроинжиниринг | D9: BLACKTROL ж - 200 кг п/эт | E9: 241023 | F9: 200 | G9: 1 | H9: Ноябрьск | I9: отгружено | J9: 45261 | Q9: 200 | R9: + | S9: 82000 | T9: =S9*(F9/1000) -> 16400
B10: Спец№5 | C10: КомплексОйл | D10: ЛИКВИТРОЛ - 200 кг мет | E10: 25/23 | F10: 4000 | G10: 20 | H10: Архангельск | I10: отгружено | J10: 45261 | K10: Камаз М 608 СТ 29 | L10: 8902-285-18-36 | M10: Детков Ян | Q10: 4000 | R10: + | S10: 167000 | T10: =S10*(F10/1000) -> 668000
A11: авто | B11: БС-40625 | C11: БурСервис | D11: BaraFLC | E11: 301123 | F11: 19845 | G11: 875 | H11: Пыть-ях | I11: отгружено | J11: 45264 | K11: DAF О 922 КМ 29 | L11: 8911-685-32-02 | M11: Журавлёв Николай | O11: 19845 | R11: + | S11: 49500 | T11: =S11*(F11/1000) -> 982327.5
B12: Спец№26 | C12: Энергоресурс | D12: BLACKTROL ж - 200 кг мет | E12: 241023 | F12: 4000 | G12: 20 | H12: самовывоз | I12: отгружено | J12: 45264 | K12: Скания Н 604 ХО 159 | L12: 8919-468-42-88 | M12: Заярный Евгений Анатольевич | Q12: 4000 | R12: + | S12: 89900 | T12: =S12*(F12/1000) -> 359600
A13: Сборка | B13: Спец№26 | C13: Энергоресурс | D13: BLACKTROL ж - 200 кг мет | E13: 051123 | F13: 200 | G13: 1 | H13: самовывоз | I13: отгружено | J13: 45264 | L13: 8922-246-86-86 | Q13: 200 | R13: + | S13: 89900 | T13: =S13*(F13/1000) -> 17980
B14: Спец№26 | C14: Энергоресурс | D14: BLACKTROL ж - 200 кг мет | E14: 061123 | F14: 600 | G14: 3 | H14: самовывоз | I14: отгружено | J14: 45264 | Q14: 600 | R14: + | S14: 89900 | T14: =S14*(F14/1000) -> 53940
B15: Спец№26 | C15: Энергоресурс | D15: Стабилайт II п/проп 25 кг | E15: 156 | F15: 16000 | G15: 640 | H15: самовывоз | I15: отгружено | J15: 45264 | O15: 16000 | R15: + | S15: 45000 | T15: =S15*(F15/1000) -> 720000
B16: Спец№75 | C16: СБМ | D16: СБМСУЛЬФ | E16: 271123 | F16: 20000 | G16: 800 | H16: самовывоз | I16: отгружено | J16: 45264 | K16: Вольво У 711 МВ 45 | L16: 8912-836-51-97 | M16: Дендя Роман | O16: 20000 | R16: + | S16: 41000 | T16: =S16*(F16/1000) -> 820000
A17: авто | B17: БС-40625 | C17: БурСервис | D17: BaraFLC | E17: 291123 | F17: 19845 | G17: 875 | H17: Пыть-ях | I17: отгружено | J17: 45265 | K17: Мерседес С 094 УХ 72 | L17: 8912-995-38-89 | M17: Новоселов Виктор | O17: 19845 | R17: + | S17: 49500 | T17: =S17*(F17/1000) -> 982327.5
B18: Спец№16К | C18: ОМАС | D18: Сульфированный асфальт | E18: 09/2023 | F18: 20000 | G18: 800 | H18: Бузулук | I18: отгружено | J18: 45266 | K18: DAF К 802 ХЕ 35 | L18: 8911-047-16-40 | M18: Лишенко Игорь | O18: 20000 | R18: + | S18: 36200 | T18: =S18*(F18/1000) -> 724000
A19: конт | B19: БС-41315 | C19: БурСервис | D19: BaraFLC | E19: 011223 | F19: 13494.6 | G19: 595 | H19: Пурпе | I19: отгружено | J19: 45268 | N19: TKRU3347636 | O19: 13494.6 | R19: + | S19: 49500 | T19: =S19*(F19/1000) -> 667982.7
B20: БС-43622 | C20: БурСервис | D20: EZ-MUD DP (Поликап) бум 25 кг | E20: 101123 | F20: 2250 | G20: 90 | H20: Пурпе | I20: отгружено | J20: 45268 | N20: TKRU3347636 | P20: 2250 | R20: + | S20: 275000 | T20: =S20*(F20/1000) -> 618750
A21: конт | B21: БС-44296 | C21: БурСервис | D21: BaraFLC | E21: 021223 | F21: 15876 | G21: 700 | H21: Пурпе | I21: отгружено | J21: 45268 | N21: TKRU3456283 | O21: 15876 | R21: + | S21: 49500 | T21: =S21*(F21/1000) -> 785862
A22: авто | B22: Спец№1 | C22: ОМАС | D22: Сульфированный асфальт | E22: 09/2023 | F22: 20000 | G22: 800 | H22: Уральск | I22: отгружено | J22: 45271 | K22: Мерседес О 119 КУ 790 | L22: 8960-834-08-79 | M22: Дягтерев Андрей | O22: 20000 | R22: + | S22: 36200 | T22: =S22*(F22/1000) -> 724000
A23: авто | B23: Спец№8 | C23: KazPetroDrilling | D23: Оптитрол Ж - 200 кг п/эт | E23: 131023 | F23: 4800 | G23: 24 | H23: Жанаозен | I23: отгружено | J23: 45271 | K23: DAF У 690 РК 790 | L23: 8927-381-78-12 | M23: Портнов Дмитрий | Q23: 4800 | R23: + | S23: 69000 | T23: =S23*(F23/1000) -> 331200
B24: Спец№8 | C24: KazPetroDrilling | D24: Оптитрол Ж - 200 кг п/эт | E24: 141023 | F24: 6400 | G24: 32 | H24: Жанаозен | I24: отгружено | J24: 45271 | Q24: 6400 | R24: + | S24: 69000 | T24: =S24*(F24/1000) -> 441600
B25: Спец№8 | C25: KazPetroDrilling | D25: Оптитрол Ж - 200 кг п/эт | E25: 141023/1 | F25: 6400 | G25: 32 | H25: Жанаозен | I25: отгружено | J25: 45271 | Q25: 6400 | R25: + | S25: 69000 | T25: =S25*(F25/1000) -> 441600
B26: Спец№8 | C26: KazPetroDrilling | D26: Оптитрол Ж - 200 кг п/эт | E26: 261023 | F26: 4800 | G26: 24 | H26: Жанаозен | I26: отгружено | J26: 45271 | K26: DAF Е 375 АМ 198 | L26: 8927-090-86-60 | M26: Каражан Арман | Q26: 4800 | R26: + | S26: 69000 | T26: =S26*(F26/1000) -> 331200
B27: Спец№8 | C27: KazPetroDrilling | D27: Оптитрол Ж - 200 кг п/эт | E27: 071123 | F27: 5600 | G27: 28 | H27: Жанаозен | I27: отгружено | J27: 45271 | Q27: 5600 | R27: + | S27: 69000 | T27: =S27*(F27/1000) -> 386400
B28: Спец№8 | C28: KazPetroDrilling | D28: Оптитрол Ж - 200 кг п/эт | E28: 211023 | F28: 6400 | G28: 32 | H28: Жанаозен | I28: отгружено | J28: 45271 | Q28: 6400 | R28: + | S28: 69000 | T28: =S28*(F28/1000) -> 441600
A29: сборка | B29: Спец№8 | C29: KazPetroDrilling | D29: Оптитрол Ж - 200 кг п/эт | E29: 131023 | F29: 200 | G29: 1 | H29: Жанаозен | I29: отгружено | J29: 45271 | Q29: 200 | R29: + | S29: 69000 | T29: =S29*(F29/1000) -> 13800
B30: Спец№8 | C30: KazPetroDrilling | D30: Оптитрол Ж - 200 кг п/эт | E30: 141023 | F30: 600 | G30: 3 | H30: Жанаозен | I30: отгружено | J30: 45271 | Q30: 600 | R30: + | S30: 69000 | T30: =S30*(F30/1000) -> 41400
B31: Спец№21 | C31: Буринтех | D31: СУЛЬФОБИТ бум 25 кг | E31: 061223 | F31: 20000 | G31: 800 | H31: Пыть-Ях | I31: отгружено | J31: 45271 | K31: Шакман М 544 ЕН 35 | L31: 8911-503-68-69 | M31: Пелешанко/Останков | O31: 20000 | R31: + | S31: 39000 | T31: =S31*(F31/1000) -> 780000
B32: Спец№2 | C32: ПУХК | D32: Сульфированный асфальт | E32: 141123 | F32: 20000 | G32: 800 | H32: самовывоз | I32: отгружено | J32: 45271 | K32: FORD К 402 УХ 35 | L32: 8911-546-03-09 | M32: Волков Игорь | O32: 20000 | R32: + | S32: 39000 | T32: =S32*(F32/1000) -> 780000
B33: Спец№5 | C33: ТМГ Технолоджи | D33: СУПЕРСЛАЙДЕР ГОЛД - 180 кг мет | E33: 101223 | F33: 4320 | G33: 24 | H33: Самовывоз | I33: отгружено | J33: 45272 | K33: Мерседес Т 882 РН 31 | L33: 8-919-223-23-67 | M33: Малюков Александр | Q33: 4320 | R33: + | S33: 110000 | T33: =S33*(F33/1000) -> 475200
B34: Спец№20К | C34: ОМАС | D34: ДЖИ-ДРИЛЛ | E34: 10/2023 | F34: 17600 | G34: 88 | H34: Пыть-Ях | I34: отгружено | J34: 45273 | K34: Ивеко А 173 АС 702 | L34: 8927-089-57-41 | M34: Саитбаталов Руслан | Q34: 17600 | R34: + | S34: 95000 | T34: =S34*(F34/1000) -> 1672000
A35: конт | B35: БС-44296 | C35: БурСервис | D35: BaraFLC | E35: 031223 | F35: 15876 | G35: 700 | H35: Пурпе | I35: отгружено | J35: 45273 | N35: TKRU3132160 | O35: 15876 | R35: + | S35: 49500 | T35: =S35*(F35/1000) -> 785862
A36: конт | B36: БС-47126 | C36: БурСервис | D36: TORQ TRIM II PLUS (СС Голд) - 185 кг мет | E36: 281123 | F36: 7030 | G36: 38 | H36: Пурпе | I36: отгружено | J36: 45273 | N36: TKRU3138220 | Q36: 7030 | R36: + | S36: 110800 | T36: =S36*(F36/1000) -> 778924
B37: БС-47126 | C37: БурСервис | D37: TORQ TRIM II PLUS (СС Голд) - 185 кг мет | E37: 291123 | F37: 7770 | G37: 42 | H37: Пурпе | I37: отгружено | J37: 45273 | N37: TKRU3138220 | Q37: 7770 | R37: + | S37: 110800 | T37: =S37*(F37/1000) -> 860916
A38: Конт | B38: Спец№22 | C38: Буринтех | D38: СУЛЬФОБИТ бум 25 кг | E38: 101223 | F38: 17500 | G38: 700 | H38: Пурпе | I38: отгружено | J38: 45278 | N38: RZDU0463982 | O38: 17500 | R38: + | S38: 41000 | T38: =S38*(F38/1000) -> 717500
A39: Конт | B39: Спец№22 | C39: Буринтех | D39: СУЛЬФОБИТ бум 25 кг | E39: 121223 | F39: 17500 | G39: 700 | H39: Пурпе | I39: отгружено | J39: 45278 | N39: RZDU0713968 | O39: 17500 | R39: + | S39: 41000 | T39: =S39*(F39/1000) -> 717500
A40: авто | B40: Спец№784/4 | C40: Татнефть | D40: Стабилайт II марк 25 кг | E40: 141223 | F40: 20000 | G40: 800 | H40: Бугульма | I40: отгружено | J40: 45279 | K40: Мерседес Е 324 ТУ 73 | L40: 8-962-634-7052 | M40: Айдаркин Сергей | O40: 20000 | R40: + | S40: 45000 | T40: =S40*(F40/1000) -> 900000
...

Sheet ноябрь 2023
B1: ОТГРУЗКИ ПРОДУКЦИИ | C1: 45231
A2: заметки | B2: НОМЕР ЗАКАЗА | C2: КЛИЕНТ | D2: ПРОДУКТ | E2: ПАРТИЯ | F2: КОЛИЧЕСТВО | H2: ПУНКТ НАЗНАЧЕНИЯ | I2: СТАТУС | J2: ДАТА ОТГРУЗКИ | K2: АВТОДОСТАВКА | N2: ЖД ДОСТАВКА | O2: ИТОГО ОТГРУЖЕНО | R2: АКТЫ
F3: КГ | G3: мешков/бочек | K3: № АВТО | L3: ТЕЛ. ВОДИТЕЛЯ | M3: ВОДИТЕЛЬ | N3: № КОНТЕЙНЕРА | O3: ЧП | P3: ИНАЯ | Q3: Жидкий | S3: Цена со склада за 1 тонну | T3: Итого
A4: Контейнер | B4: БС-41315 | C4: БурСервис | D4: BaraFLC | E4: 301023 | F4: =G4*22.68 -> 15876 | G4: 700 | H4: Пурпе | I4: отгружено | J4: 45231 | N4: RZDU0642801 | O4: =F4 -> 15876 | R4: + | S4: 49500 | T4: =S4*(F4/1000) -> 785862
A5: Контейнер | B5: БС-43314 | C5: БурСервис | D5: ADAPTA II (Ликвитрол) - 25 кг канистра | E5: 251023 | F5: 12000 | G5: 480 | H5: Пурпе | I5: отгружено | J5: 45231 | N5: RZDU0482257 | Q5: 12000 | R5: + | S5: 165000 | T5: =S5*(F5/1000) -> 1980000
A6: Контейнер | B6: БС-43622 | C6: БурСервис | D6: TORQ TRIM II PLUS (СС Голд) - 185 кг мет | E6: 301023 | F6: 7400 | G6: 40 | H6: Пурпе | I6: отгружено | J6: 45231 | N6: RZDU0708112 | Q6: 7400 | R6: + | S6: 110800 | T6: =S6*(F6/1000) -> 819920
A7: Контейнер | B7: БС-43622 | C7: БурСервис | D7: TORQ TRIM II PLUS (СС Голд) - 185 кг мет | E7: 311023 | F7: 7400 | G7: 40 | H7: Пурпе | I7: отгружено | J7: 45231 | N7: RZDU0708112 | Q7: 7400 | R7: + | S7: 110800 | T7: =S7*(F7/1000) -> 819920
A8: Контейнер | B8: БС-43314 | C8: БурСервис | D8: ADAPTA II (Ликвитрол) - 25 кг канистра | E8: 251023 | F8: 600 | G8: 24 | H8: Пурпе | I8: отгружено | J8: 45233 | N8: RZDU0173664 | Q8: 600 | R8: + | S8: 165000 | T8: =S8*(F8/1000) -> 99000
B9: БС-42033 | C9: БурСервис | D9: BaraFLC | E9: 281023 | F9: 11907 | G9: 525 | H9: Пурпе | I9: отгружено | J9: 45233 | N9: RZDU0173664 | O9: 11907 | R9: + | S9: 49500 | T9: =S9*(F9/1000) -> 589396.5
B10: БС-43490 | C10: БурСервис | D10: ADAPTA II (Ликвитрол) - 25 кг канистра | E10: 291023 | F10: 2400 | G10: 96 | H10: Пурпе | I10: отгружено | J10: 45233 | N10: RZDU0173664 | Q10: 2400 | R10: + | S10: 165000 | T10: =S10*(F10/1000) -> 396000
A11: Контейнер | B11: БС-43490 | C11: БурСервис | D11: BaraFLC | E11: 311023 | F11: 15876 | G11: 700 | H11: Пурпе | I11: отгружено | J11: 45233 | N11: RZDU0674856 | O11: 15876 | R11: + | S11: 49500 | T11: =S11*(F11/1000) -> 785862
A12: Контейнер | B12: БС-43622 | C12: БурСервис | D12: TORQ TRIM II PLUS (СС Голд) - 185 кг мет | E12: 011123 | F12: 7400 | G12: 40 | H12: Пурпе | I12: отгружено | J12: 45233 | N12: RZDU0710439 | Q12: 7400 | R12: + | S12: 110800 | T12: =S12*(F12/1000) -> 819920
A13: Контейнер | B13: БС-43622 | C13: БурСервис | D13: TORQ TRIM II PLUS (СС Голд) - 185 кг мет | E13: 021123 | F13: 7400 | G13: 40 | H13: Пурпе | I13: отгружено | J13: 45233 | N13: RZDU0710439 | Q13: 7400 | R13: + | S13: 110800 | T13: =S13*(F13/1000) -> 819920
B14: Спец№4 | C14: КомплексОйл | D14: АДВАНТА ж | E14: 24/23 | F14: 8000 | G14: 40 | H14: самовывоз | I14: отгружено | J14: 45233 | K14: Вольво О 801 НМ 29 | M14: Вечеславов Юрий | Q14: 8000 | R14: + | S14: 211000 | T14: =S14*(F14/1000) -> 1688000
A15: контейнер | B15: БС-42732 | C15: БурСервис | D15: EZ MUL NTR (Экстрамул-2000) - 190 кг мет | E15: 241023 | F15: 5320 | G15: 28 | H15: Красноярск | I15: отгружено | J15: 45237 | N15: RZDU0700092 | Q15: 5320 | R15: + | S15: 115000 | T15: =S15*(F15/1000) -> 611800
B16: БС-42732 | C16: БурСервис | D16: EZ MUL NTR (Экстрамул-2000) - 190 кг мет | E16: 220923 | F16: 3040 | G16: 16 | H16: Красноярск | I16: отгружено | J16: 45237 | N16: RZDU0700092 | Q16: 3040 | R16: + | S16: 115000 | T16: =S16*(F16/1000) -> 349600
B17: БС-42732 | C17: БурСервис | D17: EZ MUL NTR (Экстрамул-2000) - 190 кг мет | E17: 020923 | F17: 6840 | G17: 36 | H17: Красноярск | I17: отгружено | J17: 45237 | N17: RZDU0700092 | Q17: 6840 | R17: + | S17: 115000 | T17: =S17*(F17/1000) -> 786600
A18: Контейнер | B18: БС-41315 | C18: БурСервис | D18: BaraFLC | E18: 021123 | F18: 15876 | G18: 700 | H18: Пурпе | I18: отгружено | J18: 45237 | N18: RZDU0713171 | O18: 15876 | R18: + | S18: 49500 | T18: =S18*(F18/1000) -> 785862
A19: Контейнер | B19: БС-41315 | C19: БурСервис | D19: BaraFLC | E19: 011123 | F19: 15876 | G19: 700 | H19: Пурпе | I19: отгружено | J19: 45237 | N19: RZDU0710819 | O19: 15876 | R19: + | S19: 49500 | T19: =S19*(F19/1000) -> 785862
A20: Контейнер | B20: БС-43622 | C20: БурСервис | D20: TORQ TRIM II PLUS (СС Голд) - 185 кг мет | E20: 031123 | F20: 7585 | G20: 41 | H20: Пурпе | I20: отгружено | J20: 45237 | N20: TKRU3029580 | Q20: 7585 | R20: + | S20: 110800 | T20: =S20*(F20/1000) -> 840418
A21: Контейнер | B21: БС-43622 | C21: БурСервис | D21: TORQ TRIM II PLUS (СС Голд) - 185 кг мет | E21: 041123 | F21: 7215 | G21: 39 | H21: Пурпе | I21: отгружено | J21: 45237 | N21: TKRU3029580 | Q21: 7215 | R21: + | S21: 110800 | T21: =S21*(F21/1000) -> 799422
B22: Спец№71 | C22: СБМ | D22: СБМСУЛЬФ | E22: 191023 | F22: 20000 | G22: 800 | H22: самовывоз | I22: отгружено | J22: 45237 | K22: Мерседес Н 409 АН 79 | L22: 8 911-560-41-02 | M22: Хижин Анатолий | O22: 20000 | R22: + | S22: 41000 | T22: =S22*(F22/1000) -> 820000
A23: Авто | B23: Спец№12 | C23: МКО | D23: BLACKTROL ж - 200 кг мет | E23: 150923 | F23: 800 | G23: 4 | H23: самовывоз | I23: отгружено | J23: 45238 | K23: DAF В 577 СТ 18 | M23: Чернобровкин Алексей | Q23: 800 | R23: + | S23: 90000 | T23: =S23*(F23/1000) -> 72000
B24: Спец№12 | C24: МКО | D24: BLACKTROL ж - 200 кг мет | E24: 160923 | F24: 8800 | G24: 44 | H24: самовывоз | I24: отгружено | J24: 45238 | Q24: 8800 | R24: + | S24: 90000 | T24: =S24*(F24/1000) -> 792000
B25: Спец№12 | C25: МКО | D25: BLACKTROL ж - 200 кг мет | E25: 170923 | F25: 8000 | G25: 40 | H25: самовывоз | I25: отгружено | J25: 45238 | Q25: 8000 | R25: + | S25: 90000 | T25: =S25*(F25/1000) -> 720000
A26: авто | B26: Спец№68 | C26: СБМ | D26: СБМСУЛЬФ | E26: 201023 | F26: 18000 | G26: 720 | H26: Пыть-ях | I26: отгружено | J26: 45238 | K26: Мерседес С 094 УХ 72 | L26: 8912-995-38-89 | M26: Новоселов Виктор | O26: 18000 | R26: + | S26: 41000 | T26: =S26*(F26/1000) -> 738000
B27: Спец№69 | C27: СБМ | D27: СБМОЙЛРЕО В (Реомод ж) - 180 кг мет | E27: 120523 | F27: 2520 | G27: 14 | H27: Пыть-ях | I27: отгружено | J27: 45238 | Q27: 2520 | R27: + | S27: 320000 | T27: =S27*(F27/1000) -> 806400
A28: авто | B28: БС-42033 | C28: БурСервис | D28: EZ-MUD DP (Поликап) бум 25 кг | E28: 251023 | F28: 17500 | G28: 700 | H28: Пурпе | I28: отгружено | J28: 45238 | K28: Вольво О 618 СМ 29 | L28: 8962-015-57-52 | M28: Вахтомин Иван | P28: 17500 | R28: + | S28: 275000 | T28: =S28*(F28/1000) -> 4812500
B29: БС-43226 | C29: БурСервис | D29: EZ-MUD DP (Поликап) бум 25 кг | E29: 261023 | F29: 2250 | G29: 90 | H29: Пурпе | I29: отгружено | J29: 45238 | P29: 2250 | R29: + | S29: 275000 | T29: =S29*(F29/1000) -> 618750
B30: Счёт.№407 | C30: ПУХК | D30: Сульфированный асфальт | E30: 301023 | F30: 4000 | G30: 160 | H30: самовывоз | I30: отгружено | J30: 45238 | K30: Газон Некст С 431 ВЕ 152 | M30: Калдышкин Роман | O30: 4000 | R30: + | S30: 39000 | T30: =S30*(F30/1000) -> 156000
A31: Контейнер | B31: БС-43622 | C31: БурСервис | D31: BaraFLC | E31: 031123 | F31: 9072 | G31: 400 | H31: Пурпе | I31: отгружено | J31: 45239 | N31: RZDU0653426 | O31: 9072 | R31: + | S31: 49500 | T31: =S31*(F31/1000) -> 449064 | U31: 4*30+8*35
B32: БС-43490 | C32: БурСервис | D32: BaraFLC | E32: 041123 | F32: 6010.2 | G32: 265 | H32: Пурпе | I32: отгружено | J32: 45239 | N32: RZDU0653426 | O32: 6010.2 | R32: + | S32: 49500 | T32: =S32*(F32/1000) -> 297504.9 | U32: 3*30+5*35
A33: Контейнер | B33: БС-41315 | C33: БурСервис | D33: BaraFLC | E33: 041123 | F33: 15876 | G33: 700 | H33: Пурпе | I33: отгружено | J33: 45239 | N33: RZDU0734678 | O33: 15876 | R33: + | S33: 49500 | T33: =S33*(F33/1000) -> 785862
A34: авто | B34: ИСК20577-15 | C34: Петроинжиниринг | D34: BLACKTROL ж - 200 кг п/эт | E34: 201023 | F34: 7200 | G34: 36 | H34: Нижневартовск | I34: отгружено | J34: 45239 | K34: DAF К 298 МО 45 | L34: 8919-569-78-88 | M34: Шмаков Александр | Q34: 7200 | R34: + | S34: 82000 | T34: =S34*(F34/1000) -> 590400
B35: ИСК20577-15 | C35: Петроинжиниринг | D35: BLACKTROL ж - 200 кг п/эт | E35: 211023 | F35: 8000 | G35: 40 | H35: Нижневартовск | I35: отгружено | J35: 45239 | Q35: 8000 | R35: + | S35: 82000 | T35: =S35*(F35/1000) -> 656000
B36: ИСК20577-15 | C36: Петроинжиниринг | D36: BLACKTROL ж - 200 кг п/эт | E36: 241023 | F36: 800 | G36: 4 | H36: Нижневартовск | I36: отгружено | J36: 45239 | Q36: 800 | R36: + | S36: 82000 | T36: =S36*(F36/1000) -> 65600
B37: ИСК20577-15 | C37: Петроинжиниринг | D37: BLACKTROL ж - 200 кг п/эт | E37: 171023 | F37: 200 | G37: 1 | H37: Нижневартовск | I37: отгружено | J37: 45239 | Q37: 200 | R37: + | S37: 82000 | T37: =S37*(F37/1000) -> 16400
B38: ИСК20577-15 | C38: Петроинжиниринг | D38: BLACKTROL ж - 200 кг п/эт | E38: 181023 | F38: 600 | G38: 3 | H38: Нижневартовск | I38: отгружено | J38: 45239 | Q38: 600 | R38: + | S38: 82000 | T38: =S38*(F38/1000) -> 49200
B39: ИСК20577-15 | C39: Петроинжиниринг | D39: BLACKTROL ж - 200 кг п/эт | E39: 181023 | F39: 200 | G39: 1 | H39: Нижневартовск | I39: отгружено | J39: 45239 | Q39: 200 | R39: + | S39: 82000 | T39: =S39*(F39/1000) -> 16400
B40: ИСК20577-15 | C40: Петроинжиниринг | D40: BLACKTROL ж - 200 кг п/эт | E40: 191023 | F40: 600 | G40: 3 | H40: Нижневартовск | I40: отгружено | J40: 45239 | Q40: 600 | R40: + | S40: 82000 | T40: =S40*(F40/1000) -> 49200
...

Sheet октябрь 2023
B1: ОТГРУЗКИ ПРОДУКЦИИ | C1: 45200
A2: заметки | B2: НОМЕР ЗАКАЗА | C2: КЛИЕНТ | D2: ПРОДУКТ | E2: ПАРТИЯ | F2: КОЛИЧЕСТВО | H2: ПУНКТ НАЗНАЧЕНИЯ | I2: СТАТУС | J2: ДАТА ОТГРУЗКИ | K2: АВТОДОСТАВКА | N2: ЖД ДОСТАВКА | O2: ИТОГО ОТГРУЖЕНО | R2: АКТЫ
F3: КГ | G3: мешков/бочек | K3: № АВТО | L3: ТЕЛ. ВОДИТЕЛЯ | M3: ВОДИТЕЛЬ | N3: № КОНТЕЙНЕРА | O3: ЧП | P3: ИНАЯ | Q3: Жидкий | S3: Цена со склада за 1 тонну | T3: Итого
B4: ИСК20646-04 | C4: Петроинжиниринг | D4: EWO MUL2 - 200 кг п/эт | E4: 210923 | F4: 7200 | G4: 36 | H4: Нефтеюганск | I4: отгружено | J4: 45201 | K4: Даф О922 КМ 29 | L4: 8 911 685 32 02 | M4: Журавлёв Николай | Q4: 7200 | S4: 180000 | T4: =S4*(F4/1000) -> 1296000
B5: ИСК20646-04 | C5: Петроинжиниринг | D5: EWO MUL2 - 200 кг п/эт | E5: 220923 | F5: 10400 | G5: 52 | H5: Нефтеюганск | I5: отгружено | J5: 45201 | K5: Даф О922 КМ 29 | Q5: 10400 | S5: 180000 | T5: =S5*(F5/1000) -> 1872000
B6: Спец№4 | C6: МадСервис | D6: СУПЕРСЛАЙДЕР ГОЛД - 180 кг мет | E6: 230923 | F6: 5040 | G6: 28 | H6: Самара | I6: отгружено | J6: 45201 | K6: Камаз Е950 СЕ 73 | L6: 8 909 358 23 60 | M6: Мышляев Денис | Q6: 5040 | S6: 110000 | T6: =S6*(F6/1000) -> 554400
B7: Спец№71 | C7: СБМ | D7: СБМСУЛЬФ | E7: 070923 | F7: 20000 | G7: 800 | H7: самовывоз | I7: отгружено | J7: 45201 | K7: Камаз О218 АР 68 | L7: 8 910 651 00 62 | M7: Бахшиев Раян | O7: 20000 | S7: 41000 | T7: =S7*(F7/1000) -> 820000
B8: Спец№71 | C8: СБМ | D8: СБМСУЛЬФ | E8: 290923 | F8: 20000 | G8: 800 | H8: самовывоз | I8: отгружено | J8: 45201 | K8: Вольво В395 ВХ 797 | L8: 8 999 250 94 84 | M8: Голуб Владимир | O8: 20000 | S8: 41000 | T8: =S8*(F8/1000) -> 820000
B9: Спец№30 | C9: Химпром | D9: Оптитрол Пор | E9: BJ0094-23 | F9: 10000 | G9: 500 | H9: самовывоз | I9: отгружено | J9: 45202 | K9: Рено М841 МТ 18 | L9: 8 912 756 51 88 | M9: Лебедев Андрей | P9: 10000 | S9: 79000 | T9: =S9*(F9/1000) -> 790000
B10: Спец№30 | C10: Химпром | D10: АСФАСОЛ | E10: BJ0095-23 | F10: 10000 | G10: 400 | H10: самовывоз | I10: отгружено | J10: 45202 | K10: Рено М841 МТ 18 | O10: 10000 | S10: 45000 | T10: =S10*(F10/1000) -> 450000
B11: ИСК20535-04 | C11: Петроинжиниринг | D11: EWO MUL2 - 200 кг п/эт | E11: 150923 | F11: 14400 | G11: 72 | H11: Коротчаево | I11: отгружено | J11: 45202 | K11: Скания Н166 МН 159 | L11: 8 922 374 36 58 | M11: Устинов Алексей | Q11: 14400 | S11: 180000 | T11: =S11*(F11/1000) -> 2592000
B12: ИСК20535-04 | C12: Петроинжиниринг | D12: EWO MUL2 - 200 кг п/эт | E12: 160923 | F12: 3200 | G12: 16 | H12: Коротчаево | I12: отгружено | J12: 45202 | K12: Скания Н166 МН 159 | Q12: 3200 | S12: 180000 | T12: =S12*(F12/1000) -> 576000
B13: Спец№19 | C13: Буринтех | D13: СУЛЬФОБИТ бум 25 кг | E13: 200923 | F13: 20000 | G13: 800 | H13: Пыть-Ях | I13: отгружено | J13: 45202 | K13: Вольво М552 КК 29 | L13: 8 911 874 49 00 | M13: Суров Сергей | O13: 20000 | S13: 39000 | T13: =S13*(F13/1000) -> 780000
B14: Спец№68 | C14: СБМ | D14: СБМСУЛЬФ | E14: 060923 | F14: 20000 | G14: 800 | H14: Пыть-Ях | I14: отгружено | J14: 45202 | K14: Скания В987 ЕК 156 | L14: 8 919 853 01 26 | M14: Семенов Александр | O14: 20000 | S14: 41000 | T14: =S14*(F14/1000) -> 820000
B15: ИСК20652-03 | C15: Петроинжиниринг | D15: EWO MUL2 - 200 кг п/эт | E15: 220923 | F15: 3200 | G15: 16 | H15: Демьянка | I15: отгружено | J15: 45202 | K15: Даф К298 МО 45 | L15: 8 919 569 78 88 | M15: Шмаков Александр | Q15: 3200 | S15: 180000 | T15: =S15*(F15/1000) -> 576000
B16: ИСК20652-03 | C16: Петроинжиниринг | D16: EWO MUL2 - 200 кг п/эт | E16: 240923 | F16: 14400 | G16: 72 | H16: Демьянка | I16: отгружено | J16: 45202 | K16: Даф К298 МО 45 | Q16: 14400 | S16: 180000 | T16: =S16*(F16/1000) -> 2592000
B17: Спец№17 | C17: Инко-Сервис | D17: ВЕЛЛТРИТ - 180 кг мет | E17: 14092023-9 | F17: 2160 | G17: 12 | H17: Волгоград | I17: отгружено | J17: 45202 | K17: Камаз Н056 МК 73 | L17: 8 927 822 60 48 | M17: Белов Андрей | Q17: 2160 | S17: 158000 | T17: =S17*(F17/1000) -> 341280
B18: Спец№17 | C18: Инко-Сервис | D18: ЭКСТРАМУЛ-2000 - 180 кг мет | E18: 18092023-5 | F18: 13680 | G18: 76 | H18: Волгоград | I18: отгружено | J18: 45202 | K18: Камаз Н056 МК 73 | Q18: 13680 | S18: 125000 | T18: =S18*(F18/1000) -> 1710000
B19: Спец№7 | C19: KazPetroDrilling | D19: Оптитрол Ж - 200 кг п/эт | E19: 020923 | F19: 3400 | G19: 17 | H19: Жанаозен | I19: отгружено | J19: 45203 | K19: Даф Е375 АМ 198 | L19: 8 927 090 86 60 | M19: Каражан Арман | Q19: 3400 | S19: 70668 | T19: =S19*(F19/1000) -> 240271.2
B20: Спец№7 | C20: KazPetroDrilling | D20: Оптитрол Ж - 200 кг п/эт | E20: 030923 | F20: 7200 | G20: 36 | H20: Жанаозен | I20: отгружено | J20: 45203 | K20: Даф Е375 АМ 198 | Q20: 7200 | S20: 70668 | T20: =S20*(F20/1000) -> 508809.6
B21: Спец№7 | C21: KazPetroDrilling | D21: Оптитрол Ж - 200 кг п/эт | E21: 090923 | F21: 7000 | G21: 35 | H21: Жанаозен | I21: отгружено | J21: 45203 | K21: Даф Е375 АМ 198 | Q21: 7000 | S21: 70668 | T21: =S21*(F21/1000) -> 494676
B22: Спец№68 | C22: СБМ | D22: СБМСУЛЬФ | E22: 021023 | F22: 20000 | G22: 800 | H22: Пыть-Ях | I22: отгружено | J22: 45204 | K22: Даф М547 НЕ 29 | L22: 8 999 250 87 92 | M22: Грязов Руслан | O22: 20000 | S22: 41000 | T22: =S22*(F22/1000) -> 820000
B23: Спец№70 | C23: СБМ | D23: СБМЛУБ ПЛЮС (СС Платинум) - 185 кг п/эт | E23: 190923 | F23: 8140 | G23: 44 | H23: Новый Уренгой | I23: отгружено | J23: 45204 | K23: Фав С982 ЕТ 196 | L23: 8 919 597 57 97 | M23: Абабков Сергей | Q23: 8140 | S23: 230000 | T23: =S23*(F23/1000) -> 1872200
B24: Спец№70 | C24: СБМ | D24: СБМЛУБ ПЛЮС (СС Платинум) - 185 кг п/эт | E24: 200923 | F24: 8140 | G24: 44 | H24: Новый Уренгой | I24: отгружено | J24: 45204 | K24: Фав С982 ЕТ 196 | Q24: 8140 | S24: 230000 | T24: =S24*(F24/1000) -> 1872200
B25: Спец№10 | C25: ERIELL | D25: ТЕРРАПАН | E25: 280823 | F25: 20000 | G25: 800 | H25: самовывоз | I25: отгружено | J25: 45204 | K25: Даф 50L217TA | M25: Иброхимов Иссокхон | P25: 20000 | S25: 245000 | T25: =S25*(F25/1000) -> 4900000
B26: 43273 | C26: ТКШ | D26: Реасолт | E26: 160923 | F26: 15890 | G26: 700 | H26: Пурпе | I26: отгружено | J26: 45206 | N26: RZDU0717201 | O26: 15890 | S26: 42500 | T26: =S26*(F26/1000) -> 675325
B27: БС-40629 | C27: БурСервис | D27: TORQ TRIM II PLUS (СС Голд) - 185 кг п/эт | E27: 300923 | F27: 8140 | G27: 44 | H27: Пыть-Ях | I27: отгружено | J27: 45208 | K27: DAF К008МА 29 | L27: 89212944049 | M27: Белоцерковский Алексей | Q27: 8140 | S27: 110800 | T27: =S27*(F27/1000) -> 901912
B28: БС-40629 | C28: БурСервис | D28: TORQ TRIM II PLUS (СС Голд) - 185 кг п/эт | E28: 011029 | F28: 7955 | G28: 43 | H28: Пыть-Ях | I28: отгружено | J28: 45208 | K28: DAF К008МА 29 | Q28: 7955 | S28: 110800 | T28: =S28*(F28/1000) -> 881414
B29: БС-40629 | C29: БурСервис | D29: TORQ TRIM II PLUS (СС Голд) - 185 кг п/эт | E29: 290923 | F29: 185 | G29: 1 | H29: Пыть-Ях | I29: отгружено | J29: 45208 | K29: DAF К008МА 29 | Q29: 185 | S29: 110800 | T29: =S29*(F29/1000) -> 20498
B30: Спец№11 | C30: МКО | D30: BLACKTROL ж - 200 кг мет | E30: 080923 | F30: 200 | G30: 1 | H30: самовывоз | I30: отгружено | J30: 45208 | K30: Даф О272 УС 18 | M30: Данилов Дмитрий | Q30: 200 | S30: 90000 | T30: =S30*(F30/1000) -> 18000
B31: Спец№11 | C31: МКО | D31: BLACKTROL ж - 200 кг мет | E31: 120923 | F31: 1600 | G31: 8 | H31: самовывоз | I31: отгружено | J31: 45208 | K31: Даф О272 УС 18 | Q31: 1600 | S31: 90000 | T31: =S31*(F31/1000) -> 144000
B32: Спец№11 | C32: МКО | D32: BLACKTROL ж - 200 кг мет | E32: 130923 | F32: 8800 | G32: 44 | H32: самовывоз | I32: отгружено | J32: 45208 | K32: Даф О272 УС 18 | Q32: 8800 | S32: 90000 | T32: =S32*(F32/1000) -> 792000
B33: Спец№11 | C33: МКО | D33: BLACKTROL ж - 200 кг мет | E33: 140923 | F33: 7000 | G33: 35 | H33: самовывоз | I33: отгружено | J33: 45208 | K33: Даф О272 УС 18 | Q33: 7000 | S33: 90000 | T33: =S33*(F33/1000) -> 630000
B34: Спец№2 | C34: BioEnergy | D34: ЭКСТРАМУЛ-2000 - 180 кг мет | E34: 290923 | F34: 14400 | G34: 80 | H34: самовывоз | I34: отгружено | J34: 45209 | K34: RENAULT А861ЕР 198 | L34: 8 911 760-77-92 | M34: Абдулгалимов Марат | Q34: 14400 | S34: 115000 | T34: =S34*(F34/1000) -> 1656000
B35: Спец№2 | C35: BioEnergy | D35: СУПЕРСЛАЙДЕР ГОЛД - 180 кг мет | E35: 280923 | F35: 14400 | G35: 80 | H35: самовывоз | I35: отгружено | J35: 45209 | K35: VOLVO О201НК29 | M35: Гладышев Артём | Q35: 14400 | S35: 73000 | T35: =S35*(F35/1000) -> 1051200
B36: Спец№2 | C36: BioEnergy | D36: ЭКСТРАМУЛ-2000 - 180 кг мет | E36: 250923 | F36: 14400 | G36: 80 | H36: самовывоз | I36: отгружено | J36: 45208 | K36: SCANIA М870КУ 198 | L36: 8921-674-72-34 | M36: Осокин Дмитрий | Q36: 14400 | S36: 115000 | T36: =S36*(F36/1000) -> 1656000
B37: Спец№2 | C37: BioEnergy | D37: ЭКСТРАМУЛ-2000 - 180 кг мет | E37: 270923 | F37: 14400 | G37: 80 | H37: самовывоз | I37: отгружено | J37: 45208 | K37: DAF Р167МС 178 | L37: 8921-49-39-704 | M37: Соснин Иван | Q37: 14400 | S37: 115000 | T37: =S37*(F37/1000) -> 1656000
A38: контейнер | B38: БС-40817 | C38: БурСервис | D38: ADAPTA LE (Адванта ж) - 25 кг канистра | E38: 051023 | F38: 3600 | G38: 144 | H38: Усинск | I38: отгружено | J38: 45210 | N38: RZDU0709870 | Q38: 3600 | S38: 220000 | T38: =S38*(F38/1000) -> 792000
B39: БС-41789 | C39: БурСервис | D39: BaraFLC (0) | E39: 051023 | F39: 11113.2 | G39: 490 | H39: Усинск | I39: отгружено | J39: 45210 | N39: RZDU0709870 | O39: 11113.2 | S39: 49500 | T39: =S39*(F39/1000) -> 550103.4
B40: Спец№7 | C40: KazPetroDrilling | D40: Оптитрол Ж - 200 кг п/эт | E40: 090923 | F40: 200 | G40: 1 | H40: Жанаозен | I40: отгружено | J40: 45210 | K40: Мерседес О119 КУ 790 | L40: 8 960 834 08 79 | M40: Дегтярёв Андрей | Q40: 200 | S40: 70668 | T40: =S40*(F40/1000) -> 14133.6
...

Sheet сентябрь 2023
B1: ОТГРУЗКИ ПРОДУКЦИИ | C1: 45170
A2: заметки | B2: НОМЕР ЗАКАЗА | C2: КЛИЕНТ | D2: ПРОДУКТ | E2: ПАРТИЯ | F2: КОЛИЧЕСТВО | H2: ПУНКТ НАЗНАЧЕНИЯ | I2: СТАТУС | J2: ДАТА ОТГРУЗКИ | K2: АВТОДОСТАВКА | N2: ЖД ДОСТАВКА | O2: ИТОГО ОТГРУЖЕНО | R2: АКТЫ
F3: КГ | G3: мешков/бочек | K3: № АВТО | L3: ТЕЛ. ВОДИТЕЛЯ | M3: ВОДИТЕЛЬ | N3: № КОНТЕЙНЕРА | O3: ЧП | P3: ИНАЯ | Q3: Жидкий | S3: Цена со склада за 1 тонну | T3: Итого
B4: Спец№135 | C4: Акрос | D4: MEX GL-LUBE (СС Голд) - 200 кг п/эт | E4: 260823 | F4: 8800 | G4: 44 | H4: Пыть-Ях | I4: отгружено | J4: 45170 | K4: DAF K 008 MA 29 | L4: 8 911 682 59 92 | M4: Белоцерковский Алексей | Q4: 8800 | R4: + | S4: 110000 | T4: =S4*(F4/1000) -> 968000
B5: Спец№135 | C5: Акрос | D5: MEX GL-LUBE (СС Голд) - 200 кг п/эт | E5: 270823 | F5: 8800 | G5: 44 | H5: Пыть-Ях | I5: отгружено | J5: 45170 | Q5: 8800 | R5: + | S5: 110000 | T5: =S5*(F5/1000) -> 968000
A6: отгрузка с Усть-Кут | B6: Спец№10К | C6: ОМАС | D6: СУПЕРСЛАЙДЕР ГОЛД - 180 кг мет | E6: 210122 | F6: 10080 | G6: 56 | H6: Пыть-Ях | I6: отгружено | J6: 04.09.2023* | K6: Вольво М577 МР 96 | L6: 8 912 222 25 57 | M6: Комаров Константин | Q6: 10080 | S6: 90000 | T6: =S6*(F6/1000) -> 907200
A7: отгрузка с Усть-Кут | B7: Спец№10К | C7: ОМАС | D7: СУПЕРСЛАЙДЕР ГОЛД - 180 кг мет | E7: 260122 | F7: 4320 | G7: 24 | H7: Пыть-Ях | I7: отгружено | J7: 04.09.2023* | K7: Вольво М577 МР 96 | Q7: 4320 | S7: 90000 | T7: =S7*(F7/1000) -> 388800
A8: отгрузка с Усть-Кут | B8: Спец№10К | C8: ОМАС | D8: СУПЕРСЛАЙДЕР ГОЛД - 180 кг мет | E8: 030222 | F8: 1440 | G8: 8 | H8: Пыть-Ях | I8: отгружено | J8: 04.09.2023* | K8: Вольво М577 МР 96 | Q8: 1440 | S8: 90000 | T8: =S8*(F8/1000) -> 129600
B9: Спец№10 | C9: САФ-Сервис | D9: ЭКСТРАМУЛ-2000 - 190 кг п/эт | E9: 290823 | F9: 6840 | G9: 36 | H9: Пермь | I9: отгружено | J9: 45173 | K9: Volvo М552КК 29 | L9: 89118744900 | M9: Суров Сергей Владимирович | Q9: 6840 | R9: + | S9: 129700 | T9: =S9*(F9/1000) -> 887148
B10: Спец№10 | C10: САФ-Сервис | D10: ЭКСТРАМУЛ-2000 - 190 кг п/эт | E10: 300823 | F10: 8550 | G10: 45 | H10: Пермь | I10: отгружено | J10: 45173 | K10: Volvo М552КК 29 | Q10: 8550 | R10: + | S10: 129700 | T10: =S10*(F10/1000) -> 1108935
B11: Спец№10 | C11: САФ-Сервис | D11: ЭКСТРАМУЛ-2000 - 190 кг п/эт | E11: 310823 | F11: 1330 | G11: 7 | H11: Пермь | I11: отгружено | J11: 45173 | K11: Volvo М552КК 29 | Q11: 1330 | R11: + | S11: 129700 | T11: =S11*(F11/1000) -> 172501
B12: Спец№68 | C12: СБМ | D12: СБМСУЛЬФ | E12: 300823 | F12: 20000 | G12: 800 | H12: Пыть-Ях | I12: отгружено | J12: 45173 | K12: Скания В055 ВА 156 | L12: 8 987 348 11 28 | M12: Халяфутдинов Ильдар | O12: 20000 | R12: + | S12: 41000 | T12: =S12*(F12/1000) -> 820000
B13: PO #2023PY155 | C13: Petroyag | D13: ЭКСТРАМУЛ-2000 - 180 кг мет | E13: 280823 | F13: 14400 | G13: 80 | H13: Новороссийск | I13: отгружено | J13: 45173 | K13: MAN Р204НС 67 | L13: 8-915-635-38-67 | M13: Ожиганов Денис | Q13: 14400 | S13: 104000 | T13: =S13*(F13/1000) -> 1497600
B14: Спец№2 | C14: КомплексОйл | D14: ЛИКВИТРОЛ - 200 кг мет | E14: 08/23 | F14: 2400 | G14: 12 | H14: Архангельск | I14: отгружено | J14: 45174 | Q14: 2400 | S14: 167000 | T14: =S14*(F14/1000) -> 400800
B15: PO #2023PY155 | C15: Petroyag | D15: ВЕЛЛТРИТ - 180 кг мет | E15: 280823 | F15: 14400 | G15: 80 | H15: Новороссийск | I15: отгружено | J15: 45175 | K15: Mercedes-Benz Х 120 МА 60 | L15: 8-911-698-77-78 | M15: Сахиуллин Ринат | Q15: 14400 | S15: 134800 | T15: =S15*(F15/1000) -> 1941120
A16: контейнер | B16: БС-37578 | C16: БурСервис | D16: ADAPTA II (Ликвитрол) - 25 кг канистра | E16: 240823 | F16: 12000 | G16: 480 | H16: Пурпе | I16: отгружено | J16: 45177 | N16: RZDU0105382 | Q16: 12000 | S16: 165000 | T16: =S16*(F16/1000) -> 1980000
A17: контейнер | B17: БС-36789 | C17: БурСервис | D17: EZ MUL NTR (Экстрамул-2000) - 190 кг мет | E17: 270823 | F17: 5130 | G17: 27 | H17: Пурпе | I17: отгружено | J17: 45177 | N17: RZDU0706336 | Q17: 5130 | S17: 115000 | T17: =S17*(F17/1000) -> 589950
A18: контейнер | B18: БС-36789 | C18: БурСервис | D18: EZ MUL NTR (Экстрамул-2000) - 190 кг мет | E18: 280823 | F18: 8550 | G18: 45 | H18: Пурпе | I18: отгружено | J18: 45177 | N18: RZDU0706336 | Q18: 8550 | S18: 115000 | T18: =S18*(F18/1000) -> 983250
A19: контейнер | B19: БС-36789 | C19: БурСервис | D19: EZ MUL NTR (Экстрамул-2000) - 190 кг мет | E19: 290823 | F19: 1520 | G19: 8 | H19: Пурпе | I19: отгружено | J19: 45177 | N19: RZDU0706336 | Q19: 1520 | S19: 115000 | T19: =S19*(F19/1000) -> 174800
B20: БС-38613 | C20: БурСервис | D20: BaraFLC (0) | E20: 040923 | F20: 15876 | G20: 700 | H20: Усинск | I20: отгружено | J20: 45177 | N20: RZDU0657756 | O20: 15876 | S20: 49500 | T20: =S20*(F20/1000) -> 785862
B21: Спец№16 | C21: СтаркОйл | D21: ТЕРРАПАН ж - 200 кг мет | E21: 030923 | F21: 2400 | G21: 12 | H21: самовывоз | I21: отгружено | J21: 45177 | K21: Газон Х 956 КВ 152 | L21: 8-919-853-59-64 | M21: Малютин Алексей | Q21: 2400 | S21: 110000 | T21: =S21*(F21/1000) -> 264000
B22: Спец№16 | C22: СтаркОйл | D22: Оптитрол Ж - 200 кг п/эт | E22: 020923 | F22: 3200 | G22: 16 | H22: самовывоз | I22: отгружено | J22: 45177 | Q22: 3200 | S22: 68000 | T22: =S22*(F22/1000) -> 217600
B23: Спец№2 | C23: Мад Сервис | D23: КЛСП | E23: 050323 | F23: 5000 | G23: 250 | H23: Самара | I23: отгружено | J23: 45177 | K23: Газон С395НХ 797 | L23: 8-996-307-74-40 | M23: Сергиенко Артём | P23: 5000 | S23: 83800 | T23: =S23*(F23/1000) -> 419000
B24: Спец№1 | C24: Мад Сервис | D24: Сульфированный асфальт | E24: 01/2023 | F24: 8000 | G24: 320 | H24: Нижневартовск | I24: отгружено | J24: 45180 | K24: Скания Н604 ХО 159 | L24: 8 982 235 70 80 | M24: Миньковский Андрей | O24: 8000 | S24: 41000 | T24: =S24*(F24/1000) -> 328000
B25: Спец№1 | C25: Мад Сервис | D25: СУПЕРСЛАЙДЕР ГОЛД - 180 кг мет | E25: 12/22 | F25: 10080 | G25: 56 | H25: Нижневартовск | I25: отгружено | J25: 45180 | K25: Скания Н604 ХО 159 | Q25: 10080 | S25: 110000 | T25: =S25*(F25/1000) -> 1108800
B26: Спец№7 | C26: KazPetroDrilling | D26: Оптитрол Ж - 200 кг п/эт | E26: 130723 | F26: 800 | G26: 4 | H26: Жанаозен | I26: отгружено | J26: 45180 | K26: Даф У594 ВА 790 | L26: 8 920 632 65 77 | M26: Сальников Андрей | Q26: 800 | S26: 70668 | T26: =S26*(F26/1000) -> 56534.4
B27: Спец№7 | C27: KazPetroDrilling | D27: Оптитрол Ж - 200 кг п/эт | E27: 140723 | F27: 7200 | G27: 36 | H27: Жанаозен | I27: отгружено | J27: 45180 | K27: Даф У594 ВА 790 | Q27: 7200 | S27: 70668 | T27: =S27*(F27/1000) -> 508809.6
B28: Спец№7 | C28: KazPetroDrilling | D28: Оптитрол Ж - 200 кг п/эт | E28: 090823 | F28: 4200 | G28: 21 | H28: Жанаозен | I28: отгружено | J28: 45180 | K28: Даф У594 ВА 790 | Q28: 4200 | S28: 70668 | T28: =S28*(F28/1000) -> 296805.6
B29: Спец№7 | C29: KazPetroDrilling | D29: Оптитрол Ж - 200 кг п/эт | E29: 010923 | F29: 4800 | G29: 24 | H29: Жанаозен | I29: отгружено | J29: 45180 | K29: Даф У594 ВА 790 | Q29: 4800 | S29: 70668 | T29: =S29*(F29/1000) -> 339206.4
B30: Спец№7 | C30: KazPetroDrilling | D30: Оптитрол Ж - 200 кг п/эт | E30: 020923 | F30: 600 | G30: 3 | H30: Жанаозен | I30: отгружено | J30: 45180 | K30: Даф У594 ВА 790 | Q30: 600 | S30: 70668 | T30: =S30*(F30/1000) -> 42400.8
B31: Спец№10 | C31: САФ-Сервис | D31: ЭКСТРАМУЛ-2000 - 190 кг п/эт | E31: 310823 | F31: 6840 | G31: 36 | H31: Пермь | I31: отгружено | J31: 45180 | K31: Вольво К777 ОО 29 | L31: 8 960 015 44 01 | M31: Жилин Андрей | Q31: 6840 | R31: + | S31: 129700 | T31: =S31*(F31/1000) -> 887148
B32: Спец№10 | C32: САФ-Сервис | D32: ЭКСТРАМУЛ-2000 - 190 кг п/эт | E32: 010923 | F32: 8360 | G32: 44 | H32: Пермь | I32: отгружено | J32: 45180 | K32: Вольво К777 ОО 29 | Q32: 8360 | R32: + | S32: 129700 | T32: =S32*(F32/1000) -> 1084292
B33: Спец№10 | C33: САФ-Сервис | D33: ЭКСТРАМУЛ-2000 - 190 кг п/эт | E33: 020923 | F33: 1520 | G33: 8 | H33: Пермь | I33: отгружено | J33: 45180 | K33: Вольво К777 ОО 29 | Q33: 1520 | R33: + | S33: 129700 | T33: =S33*(F33/1000) -> 197144
B34: Спец№1 | C34: BioEnergy | D34: ЭКСТРАМУЛ-2000 - 900 кг еврокуб | E34: 110823 | F34: 16200 | G34: 18 | H34: Самовывоз | I34: отгружено | J34: 45180 | K34: СКАНИЯ М 870 КУ 198 | L34: 8911-676-38-81 | M34: Осокин Дмитрий | Q34: 16200 | S34: 115000 | T34: =S34*(F34/1000) -> 1863000
B35: Спец№68 | C35: СБМ | D35: СБМСУЛЬФ | E35: 310823 | F35: 20000 | G35: 800 | H35: Пыть-Ях | I35: отгружено | J35: 45181 | K35: Вольво Т954 ВВ 790 | L35: 8 920 922 35 55 | M35: Архипов Сергей | O35: 20000 | R35: + | S35: 41000 | T35: =S35*(F35/1000) -> 820000
B36: Спец№10 | C36: МКО | D36: BLACKTROL ж - 200 кг мет | E36: 160823 | F36: 2400 | G36: 12 | H36: самовывоз | I36: отгружено | J36: 45181 | K36: Вольво Х425 ММ 37 | M36: Слепцов Денис | Q36: 2400 | S36: 89900 | T36: =S36*(F36/1000) -> 215760
B37: Спец№10 | C37: МКО | D37: BLACKTROL ж - 200 кг мет | E37: 070923 | F37: 8000 | G37: 40 | H37: самовывоз | I37: отгружено | J37: 45181 | K37: Вольво Х425 ММ 37 | Q37: 8000 | S37: 89900 | T37: =S37*(F37/1000) -> 719200
B38: Спец№10 | C38: МКО | D38: BLACKTROL ж - 200 кг мет | E38: 080923 | F38: 7200 | G38: 36 | H38: самовывоз | I38: отгружено | J38: 45181 | K38: Вольво Х425 ММ 37 | Q38: 7200 | S38: 89900 | T38: =S38*(F38/1000) -> 647280
B39: Счёт №351 | C39: Морские платформы | D39: Оптитрол Ж - 200 кг п/эт | E39: 130723 | F39: 200 | G39: 1 | H39: самовывоз | I39: отгружено | J39: 45182 | K39: Деловые линии | Q39: 200 | S39: 67000 | T39: =S39*(F39/1000) -> 13400
B40: Счёт №351 | C40: Морские платформы | D40: BLACKTROL ж - 200 кг мет | E40: 160823 | F40: 200 | G40: 1 | H40: самовывоз | I40: отгружено | J40: 45182 | K40: Деловые линии | Q40: 200 | S40: 85000 | T40: =S40*(F40/1000) -> 17000
...

Sheet август 2023
B1: ОТГРУЗКИ ПРОДУКЦИИ | C1: 45139
A2: заметки | B2: НОМЕР ЗАКАЗА | C2: КЛИЕНТ | D2: ПРОДУКТ | E2: ПАРТИЯ | F2: КОЛИЧЕСТВО | H2: ПУНКТ НАЗНАЧЕНИЯ | I2: СТАТУС | J2: ДАТА ОТГРУЗКИ | K2: АВТОДОСТАВКА | N2: ЖД ДОСТАВКА | O2: ИТОГО ОТГРУЖЕНО | R2: АКТЫ
F3: КГ | G3: мешков/бочек | K3: № АВТО | L3: ТЕЛ. ВОДИТЕЛЯ | M3: ВОДИТЕЛЬ | N3: № КОНТЕЙНЕРА | O3: ЧП | P3: ИНАЯ | Q3: Жидкий | S3: Цена со склада за 1 тонну | T3: Итого
B4: Спец№60 | C4: СБМ | D4: СБМОЙЛРЕО В (Реомод ж) - 180 кг мет | E4: 260723 | F4: 720 | G4: 4 | H4: Пыть-Ях | I4: отгружено | J4: 45139 | K4: Вольво С931 ЕМ 51 | L4: 8 921 297 46 13 | M4: Киреев Сергей | Q4: 720 | R4: + | S4: 320000 | T4: =S4*(F4/1000) -> 230400
B5: Спец№60 | C5: СБМ | D5: СБМОЙЛРЕО В (Реомод ж) - 180 кг мет | E5: 270723 | F5: 8460 | G5: 47 | H5: Пыть-Ях | I5: отгружено | J5: 45139 | K5: Вольво С931 ЕМ 51 | Q5: 8460 | R5: + | S5: 320000 | T5: =S5*(F5/1000) -> 2707200
B6: Спец№60 | C6: СБМ | D6: СБМОЙЛРЕО В (Реомод ж) - 180 кг мет | E6: 280723 | F6: 6660 | G6: 37 | H6: Пыть-Ях | I6: отгружено | J6: 45139 | K6: Вольво С931 ЕМ 51 | Q6: 6660 | R6: + | S6: 320000 | T6: =S6*(F6/1000) -> 2131200
B7: Спец№61 | C7: СБМ | D7: СБМСУЛЬФ | E7: 210723 | F7: 20000 | G7: 800 | H7: Пыть-Ях | I7: отгружено | J7: 45140 | K7: Мерседес С094 УХ 72 | L7: 8 912 995 38 89 | M7: Новоселов Виктор | O7: 20000 | R7: + | S7: 41000 | T7: =S7*(F7/1000) -> 820000
B8: Спец№61 | C8: СБМ | D8: СБМСУЛЬФ | E8: 250723 | F8: 20000 | G8: 800 | H8: Пыть-Ях | I8: отгружено | J8: 45140 | K8: Камаз Н017 ТК 799 | L8: 8 910 209 89 12 | M8: Зиборов Иван | O8: 20000 | R8: + | S8: 41000 | T8: =S8*(F8/1000) -> 820000
C9: Уренгойский речной порт | D9: BUR-RMOD L (Реомод ж) - 190 кг п/эт | E9: 070623 | F9: 190 | G9: 1 | H9: Коротчаево | I9: отгружено | J9: 45140 | K9: Деловые линии | Q9: 190 | S9: 320000 | T9: =S9*(F9/1000) -> 60800
A10: политрол | B10: Счёт№271 | C10: Геохим | D10: ПОЛИТРОЛ - 200 кг мет | E10: 260723 | F10: 1000 | G10: 5 | H10: самовывоз | I10: отгружено | J10: 45140 | K10: Газель О873 МН 29 | L10: 8 921 476 83 86 | M10: Ярков Андрей | Q10: 1000 | S10: 149000 | T10: =S10*(F10/1000) -> 149000
A11: отгрузка с Усть-Кут | B11: Спец№16 | C11: ИНКО-Сервис | D11: СУПЕРСЛАЙДЕР ГОЛД - 180 кг мет | E11: 220122 | F11: 4320 | G11: 24 | H11: Самара | I11: отгружено | J11: *03.08.2023 | Q11: 4320 | R11: + | S11: 80000 | T11: =S11*(F11/1000) -> 345600
A12: отгрузка с Усть-Кут | B12: Спец№16 | C12: ИНКО-Сервис | D12: СУПЕРСЛАЙДЕР ГОЛД - 180 кг мет | E12: 270122 | F12: 11520 | G12: 64 | H12: Самара | I12: отгружено | J12: *03.08.2023 | Q12: 11520 | R12: + | S12: 80000 | T12: =S12*(F12/1000) -> 921600
B13: Спец№61 | C13: СБМ | D13: СБМСУЛЬФ | E13: 260723 | F13: 6000 | G13: 240 | H13: Пыть-Ях | I13: отгружено | J13: 45141 | K13: Ситрак В985 ТС 43 | L13: 8 922 942 40 75 | M13: Павлов Сергей | O13: 6000 | R13: + | S13: 41000 | T13: =S13*(F13/1000) -> 246000
B14: Спец№54 | C14: СБМ | D14: СБМСУЛЬФ | E14: 270723 | F14: 4000 | G14: 160 | H14: Пыть-Ях | I14: отгружено | J14: 45141 | K14: Ситрак В985 ТС 43 | O14: 4000 | R14: + | S14: 41000 | T14: =S14*(F14/1000) -> 164000
B15: Спец№59 | C15: СБМ | D15: СБМОЙЛРЕО В (Реомод ж) - 180 кг мет | E15: 280723 | F15: 1620 | G15: 9 | H15: Пыть-Ях | I15: отгружено | J15: 45141 | K15: Ситрак В985 ТС 43 | Q15: 1620 | R15: + | S15: 320000 | T15: =S15*(F15/1000) -> 518400
B16: Спец№59 | C16: СБМ | D16: СБМОЙЛРЕО В (Реомод ж) - 180 кг мет | E16: 010823 | F16: 5580 | G16: 31 | H16: Пыть-Ях | I16: отгружено | J16: 45141 | K16: Ситрак В985 ТС 43 | Q16: 5580 | R16: + | S16: 320000 | T16: =S16*(F16/1000) -> 1785600
B17: Спец№131 | C17: АКРОС | D17: Drilling Lube - 200 кг п/эт | E17: 310723 | F17: 8800 | G17: 44 | H17: Мурманск | I17: отгружено | J17: 45142 | K17: Вольво А954 ОА 134 | L17: 8 903 478 31 40 | M17: Мошков Василий | Q17: 8800 | S17: 369000 | T17: =S17*(F17/1000) -> 3247200
B18: Спец№131 | C18: АКРОС | D18: Drilling Lube - 200 кг п/эт | E18: 010823 | F18: 8800 | G18: 44 | H18: Мурманск | I18: отгружено | J18: 45142 | K18: Вольво А954 ОА 134 | Q18: 8800 | S18: 369000 | T18: =S18*(F18/1000) -> 3247200
B19: Счёт№260 | C19: ХГРП | D19: BLACKTROL ж - 30 кг канистра | E19: 310723 | F19: 2000 | G19: 67 | H19: Чита | I19: отгружено | J19: 45142 | K19: Деловые линии | Q19: 2000 | S19: 89900 | T19: =S19*(F19/1000) -> 179800
B20: Спец№7 | C20: ЭРИЕЛЛ | D20: BLACKTROL ж - 200 кг мет | E20: 220623 | F20: 4000 | G20: 20 | H20: самовывоз | I20: отгружено | J20: 45145 | K20: Ман 80W532TA | M20: Азимов Лазизбек | Q20: 4000 | S20: 90000 | T20: =S20*(F20/1000) -> 360000
B21: Спец№7 | C21: ЭРИЕЛЛ | D21: BLACKTROL ж - 200 кг мет | E21: 260623 | F21: 800 | G21: 4 | H21: самовывоз | I21: отгружено | J21: 45145 | K21: Ман 80W532TA | Q21: 800 | S21: 90000 | T21: =S21*(F21/1000) -> 72000
B22: Спец№7 | C22: ЭРИЕЛЛ | D22: BLACKTROL ж - 200 кг мет | E22: 100723 | F22: 8000 | G22: 40 | H22: самовывоз | I22: отгружено | J22: 45145 | K22: Ман 80W532TA | Q22: 8000 | S22: 90000 | T22: =S22*(F22/1000) -> 720000
B23: Спец№7 | C23: ЭРИЕЛЛ | D23: BLACKTROL ж - 200 кг мет | E23: 170723 | F23: 4800 | G23: 24 | H23: самовывоз | I23: отгружено | J23: 45145 | K23: Ман 80W532TA | Q23: 4800 | S23: 90000 | T23: =S23*(F23/1000) -> 432000
B24: Спец№7 | C24: ЭРИЕЛЛ | D24: BLACKTROL ж - 200 кг мет | E24: 100723 | F24: 400 | G24: 2 | H24: самовывоз | I24: отгружено | J24: 45145 | K24: Ман 80142TBA | M24: Одилов Сардорбек | Q24: 400 | S24: 90000 | T24: =S24*(F24/1000) -> 36000
B25: Спец№7 | C25: ЭРИЕЛЛ | D25: BLACKTROL ж - 200 кг мет | E25: 170723 | F25: 4200 | G25: 21 | H25: самовывоз | I25: отгружено | J25: 45145 | K25: Ман 80142TBA | Q25: 4200 | S25: 90000 | T25: =S25*(F25/1000) -> 378000
B26: Спец№7 | C26: ЭРИЕЛЛ | D26: BLACKTROL ж - 200 кг мет | E26: 180723 | F26: 9000 | G26: 45 | H26: самовывоз | I26: отгружено | J26: 45145 | K26: Ман 80142TBA | Q26: 9000 | S26: 90000 | T26: =S26*(F26/1000) -> 810000
B27: Спец№7 | C27: ЭРИЕЛЛ | D27: BLACKTROL ж - 200 кг мет | E27: 190723 | F27: 4000 | G27: 20 | H27: самовывоз | I27: отгружено | J27: 45145 | K27: Ман 80142TBA | Q27: 4000 | S27: 90000 | T27: =S27*(F27/1000) -> 360000
B28: Спец№7 | C28: ЭРИЕЛЛ | D28: BLACKTROL ж - 200 кг мет | E28: 190723 | F28: 5000 | G28: 25 | H28: самовывоз | I28: отгружено | J28: 45145 | K28: Ман 80J592VA | M28: Махмудов Максуджон | Q28: 5000 | S28: 90000 | T28: =S28*(F28/1000) -> 450000
B29: Спец№7 | C29: ЭРИЕЛЛ | D29: BLACKTROL ж - 200 кг мет | E29: 200723 | F29: 8800 | G29: 44 | H29: самовывоз | I29: отгружено | J29: 45145 | K29: Ман 80J592VA | Q29: 8800 | S29: 90000 | T29: =S29*(F29/1000) -> 792000
B30: Спец№7 | C30: ЭРИЕЛЛ | D30: BLACKTROL ж - 200 кг мет | E30: 210723 | F30: 3800 | G30: 19 | H30: самовывоз | I30: отгружено | J30: 45145 | K30: Ман 80J592VA | Q30: 3800 | S30: 90000 | T30: =S30*(F30/1000) -> 342000
B31: Спец№7К | C31: ОМАС | D31: ТЕРРАПАН | E31: 280723 | F31: 20000 | G31: 800 | H31: Нижневартовск | I31: отгружено | J31: 45147 | K31: Скания М173 ВА 159 | L31: 8 982 480 25 26 | M31: Пепеляев Михаил | P31: 20000 | S31: 249000 | T31: =S31*(F31/1000) -> 4980000
B32: Спец№3 | C32: Соларкем | D32: Сульфированный асфальт | E32: 080823 | F32: 3000 | G32: 120 | H32: самовывоз | I32: отгружено | J32: 45147 | K32: Газ К472 МК 45 | L32: 8 919 575 44 37 | M32: Лапин Алексей | O32: 3000 | S32: 42000 | T32: =S32*(F32/1000) -> 126000
B33: Спец№8К | C33: ОМАС | D33: Сульфированный асфальт | E33: 01/2023 | F33: 20000 | G33: 800 | H33: Нижневартовск | I33: отгружено | J33: 45147 | K33: Даф А032 НА 45 | L33: 8 919 588 65 79 | M33: Колупаев Дмитрий | O33: 20000 | S33: 42000 | T33: =S33*(F33/1000) -> 840000
B34: Спец№131 | C34: АКРОС | D34: Drilling Lube - 200 кг п/эт | E34: 020823 | F34: 8800 | G34: 44 | H34: Мурманск | I34: отгружено | J34: 45148 | K34: Вольво М128 УТ 10 | L34: 8 911 414 67 87 | M34: Беззубков Антон | Q34: 8800 | S34: 369000 | T34: =S34*(F34/1000) -> 3247200
B35: Спец№131 | C35: АКРОС | D35: Drilling Lube - 200 кг п/эт | E35: 030823 | F35: 8800 | G35: 44 | H35: Мурманск | I35: отгружено | J35: 45148 | K35: Вольво М128 УТ 10 | Q35: 8800 | S35: 369000 | T35: =S35*(F35/1000) -> 3247200
B36: Спец№8К | C36: ОМАС | D36: ТЕРРАПАН | E36: 020823 | F36: 20000 | G36: 800 | H36: Нижневартовск | I36: отгружено | J36: 45149 | K36: Даф К008 МА 29 | L36: 8 911 682 59 92 | M36: Белоцерковский Алексей | P36: 20000 | S36: 249000 | T36: =S36*(F36/1000) -> 4980000
A37: контейнер | B37: БС-36243 | C37: БурСервис | D37: BaraFLC (0) | E37: 080623 | F37: 15876 | G37: 700 | H37: Усинск | I37: отгружено | J37: 45149 | O37: 15876 | S37: 49500 | T37: =S37*(F37/1000) -> 785862
A38: контейнер | B38: БС-36243 | C38: БурСервис | D38: BaraFLC (0) | E38: 070823 | F38: 15876 | G38: 700 | H38: Усинск | I38: отгружено | J38: 45149 | O38: 15876 | S38: 49500 | T38: =S38*(F38/1000) -> 785862
B39: Спец№134 | C39: Акрос | D39: MEX GL-LUBE (СС Голд) - 200 кг п/эт | E39: 070823 | F39: 8800 | G39: 44 | H39: Мегион | I39: отгружено | J39: 45152 | K39: Скания Т059 АК 59 | L39: 8 999 861 45 97 | M39: Чугунов Владимир | Q39: 8800 | S39: 110000 | T39: =S39*(F39/1000) -> 968000
B40: Спец№134 | C40: Акрос | D40: MEX GL-LUBE (СС Голд) - 200 кг п/эт | E40: 080823 | F40: 8800 | G40: 44 | H40: Мегион | I40: отгружено | J40: 45152 | K40: Скания Т059 АК 59 | Q40: 8800 | S40: 110000 | T40: =S40*(F40/1000) -> 968000
...

Sheet июль 2023
B1: ОТГРУЗКИ ПРОДУКЦИИ | C1: 45108
A2: заметки | B2: НОМЕР ЗАКАЗА | C2: КЛИЕНТ | D2: ПРОДУКТ | E2: ПАРТИЯ | F2: КОЛИЧЕСТВО | H2: ПУНКТ НАЗНАЧЕНИЯ | I2: СТАТУС | J2: ДАТА ОТГРУЗКИ | K2: АВТОДОСТАВКА | N2: ЖД ДОСТАВКА | O2: ИТОГО ОТГРУЖЕНО | R2: АКТЫ
F3: КГ | G3: мешков/бочек | K3: № АВТО | L3: ТЕЛ. ВОДИТЕЛЯ | M3: ВОДИТЕЛЬ | N3: № КОНТЕЙНЕРА | O3: ЧП | P3: ИНАЯ | Q3: Жидкий | S3: Цена со склада за 1 тонну | T3: Итого
B4: ИСК19616-08 | C4: ПетроИнжиниринг | D4: EWO WET (Веллтрит) - 200 кг п/эт | E4: 190623 | F4: 17600 | G4: 88 | H4: Коротчаево | I4: отгружено | J4: 45110 | K4: Скания О265 ВО 159 | L4: 8 965 562 73 55 | M4: Бекленев Александр | Q4: 17600 | S4: 152000 | T4: =S4*(F4/1000) -> 2675200
B5: ИСК19741-02 | C5: ПетроИнжиниринг | D5: EWO WET (Веллтрит) - 200 кг п/эт | E5: 200623 | F5: 17600 | G5: 88 | H5: Нефтеюганск | I5: отгружено | J5: 45110 | K5: Камаз В875 ЕМ 702 | L5: 8 917 790 18 81 | M5: Виденеев Сергей | Q5: 17600 | R5: + | S5: 152000 | T5: =S5*(F5/1000) -> 2675200
B6: Спец№2 | C6: Соларкем | D6: Сульфированный асфальт | E6: 290623 | F6: 12000 | G6: 480 | H6: самовывоз | I6: отгружено | J6: 45110 | K6: Вольво О025 НК 29 | L6: 8 911 878 86 34 | M6: Кириленко Михаил | O6: 12000 | S6: 42000 | T6: =S6*(F6/1000) -> 504000
B7: Спец№2 | C7: Соларкем | D7: СУПЕРСЛАЙДЕР СИЛЬВЕР - 200 кг п/эт | E7: 270623 | F7: 6000 | G7: 30 | H7: самовывоз | I7: отгружено | J7: 45110 | K7: Вольво О025 НК 29 | Q7: 6000 | S7: 92500 | T7: =S7*(F7/1000) -> 555000
B8: Спец№16 | C8: ЭкоФлуидз | D8: КЛСП | E8: 050323 | F8: 5000 | G8: 250 | H8: Самара | I8: отгружено | J8: 45110 | K8: ГАЗ Валдай Р705 ХУ 174 | L8: 8 930 681 00 13 | M8: Поляков Андрей | P8: 5000 | S8: 85000 | T8: =S8*(F8/1000) -> 425000
B9: Спец№20 | C9: Энергоресурс | D9: Стабилайт II п/проп 25 кг | E9: 150 | F9: 20000 | G9: 800 | H9: самовывоз | I9: отгружено | J9: 45111 | K9: Мерседес Р996 ОА 198 | M9: Терентьев Сергей | O9: 20000 | S9: 45000 | T9: =F9/1000*S9 -> 900000
B10: БС-32484 | C10: БурСервис | D10: EZ-MUD DP (Поликап) бум 25 кг | E10: 280623 | F10: 20000 | G10: 800 | H10: Пыть-Ях | I10: отгружено | J10: 45111 | K10: Скания А280 ЕМ 156 | L10: 8 987 777 27 94 | M10: Андреев Антон | P10: 20000 | S10: 275000 | T10: =S10*(F10/1000) -> 5500000
B11: Спец№3К | C11: ОМАС | D11: Сульфированный асфальт | E11: 01/2023 | F11: 20000 | G11: 800 | H11: Нижневартовск | I11: отгружено | J11: 45111 | K11: Вольво В109 РО 124 | M11: Бабичев Анатолий | O11: 20000 | R11: + | S11: 42000 | T11: =S11*(F11/1000) -> 840000
B12: ИСК19741-02 | C12: ПетроИнжиниринг | D12: EWO MUL2 - 200 кг п/эт | E12: 150623 | F12: 8800 | G12: 44 | H12: Нефтеюганск | I12: отгружено | J12: 45112 | K12: Даф О922 КМ 29 | L12: 8 911 685 32 02 | M12: Журавлёв Николай | Q12: 8800 | R12: + | S12: 165000 | T12: =S12*(F12/1000) -> 1452000
B13: ИСК19741-02 | C13: ПетроИнжиниринг | D13: EWO MUL2 - 200 кг п/эт | E13: 150623/1 | F13: 1600 | G13: 8 | H13: Нефтеюганск | I13: отгружено | J13: 45112 | K13: Даф О922 КМ 29 | Q13: 1600 | R13: + | S13: 165000 | T13: =S13*(F13/1000) -> 264000
B14: ИСК19741-02 | C14: ПетроИнжиниринг | D14: EWO MUL2 - 200 кг п/эт | E14: 300623 | F14: 7200 | G14: 36 | H14: Нефтеюганск | I14: отгружено | J14: 45112 | K14: Даф О922 КМ 29 | Q14: 7200 | R14: + | S14: 165000 | T14: =S14*(F14/1000) -> 1188000
B15: Спец№15 | C15: ЭкоФлуидз | D15: Сульфированный асфальт | E15: 300623 | F15: 20000 | G15: 800 | H15: Самара | I15: отгружено | J15: 45114 | K15: Ман М472 УУ 35 | L15: 8 911 534 47 41 | M15: Кузичев Сергей | O15: 20000 | R15: + | S15: 41000 | T15: =S15*(F15/1000) -> 820000
B16: Спец№61 | C16: СБМ | D16: СБМСУЛЬФ | E16: 050723 | F16: 20000 | G16: 800 | H16: Пыть-Ях | I16: отгружено | J16: 45117 | K16: Даф М910 РУ 29 | L16: 8 911 685 34 05 | M16: Вишняков Денис | O16: 20000 | R16: + | S16: 41000 | T16: =S16*(F16/1000) -> 820000
B17: Счёт №259 | C17: ИПСтарикова | D17: Оптитрол Ж - 200 кг п/эт | E17: 140323 | F17: 200 | G17: 1 | H17: самовывоз | I17: отгружено | J17: 45117 | K17: Газель Е089 ХК 73 | L17: 8 937 039 54 56 | M17: Карпушин Альберт | Q17: 200 | S17: 68000 | T17: =S17*(F17/1000) -> 13600
B18: Счёт №259 | C18: ИПСтарикова | D18: Оптитрол Ж - 200 кг п/эт | E18: 270323 | F18: 200 | G18: 1 | H18: самовывоз | I18: отгружено | J18: 45117 | K18: Газель Е089 ХК 73 | Q18: 200 | S18: 68000 | T18: =S18*(F18/1000) -> 13600
B19: Счёт №259 | C19: ИПСтарикова | D19: Оптитрол Ж - 200 кг п/эт | E19: 290323 | F19: 200 | G19: 1 | H19: самовывоз | I19: отгружено | J19: 45117 | K19: Газель Е089 ХК 73 | Q19: 200 | S19: 68000 | T19: =S19*(F19/1000) -> 13600
B20: Счёт №259 | C20: ИПСтарикова | D20: Оптитрол Ж - 200 кг п/эт | E20: 260523 | F20: 400 | G20: 2 | H20: самовывоз | I20: отгружено | J20: 45117 | K20: Газель Е089 ХК 73 | Q20: 400 | S20: 68000 | T20: =S20*(F20/1000) -> 27200
B21: Счёт №259 | C21: ИПСтарикова | D21: Оптитрол Ж - 200 кг п/эт | E21: 280623 | F21: 600 | G21: 3 | H21: самовывоз | I21: отгружено | J21: 45117 | K21: Газель Е089 ХК 73 | Q21: 600 | S21: 68000 | T21: =S21*(F21/1000) -> 40800
B22: Спец№61 | C22: СБМ | D22: СБМСУЛЬФ | E22: 060723 | F22: 20000 | G22: 800 | H22: Пыть-Ях | I22: отгружено | J22: 45118 | K22: Вольво О917 МХ 29 | L22: 8 911 567 52 25 | M22: Любимков Алексей | O22: 20000 | R22: + | S22: 41000 | T22: =S22*(F22/1000) -> 820000
B23: Спец№9 | C23: САФ-Сервис | D23: ЭКСТРАМУЛ-2000 - 190 кг п/эт | E23: 070723 | F23: 3420 | G23: 18 | H23: самовывоз | I23: отгружено | J23: 45118 | K23: Маз В420 ОК 43 | L23: 8 912 733 85 67 | M23: Мутных Дмитрий | Q23: 3420 | S23: 129700 | T23: =S23*(F23/1000) -> 443574
B24: Спец№9 | C24: САФ-Сервис | D24: ЭКСТРАМУЛ-2000 - 190 кг п/эт | E24: 100723 | F24: 6460 | G24: 34 | H24: самовывоз | I24: отгружено | J24: 45118 | K24: Маз В420 ОК 43 | Q24: 6460 | S24: 129700 | T24: =S24*(F24/1000) -> 837862
B25: Счёт№240 | C25: БГРП | D25: BLACKTROL ж - 30 кг канистра | E25: 100723 | F25: 510 | G25: 17 | H25: Владивосток | I25: отгружено | J25: 45119 | K25: Деловые Линии | Q25: 510 | S25: 89000 | T25: =S25*(F25/1000) -> 45390
B26: Счёт№255 | C26: ОйлИнвест | D26: ЭКСТРАМУЛ-2000 - 25 кг канистра | E26: 100723 | F26: 25 | G26: 1 | H26: Екатеринбуг | I26: отгружено | J26: 45119 | K26: Деловые Линии | Q26: 25 | S26: 125000 | T26: =S26*(F26/1000) -> 3125
A27: контейнер | B27: БС-30377 | C27: БурСервис | D27: EZ MUL NTR (Экстрамул-2000) - 190 кг мет | E27: 300523 | F27: 3420 | G27: 18 | H27: Лена | I27: отгружено | J27: 45120 | N27: RZDU0201529 | Q27: 3420 | S27: 115000 | T27: =S27*(F27/1000) -> 393300
A28: контейнер | B28: БС-30377 | C28: БурСервис | D28: EZ MUL NTR (Экстрамул-2000) - 190 кг мет | E28: 070623 | F28: 3040 | G28: 16 | H28: Лена | I28: отгружено | J28: 45120 | N28: RZDU0201529 | Q28: 3040 | S28: 115000 | T28: =S28*(F28/1000) -> 349600
A29: контейнер | B29: БС-30377 | C29: БурСервис | D29: EZ MUL NTR (Экстрамул-2000) - 190 кг мет | E29: 080623 | F29: 8550 | G29: 45 | H29: Лена | I29: отгружено | J29: 45120 | N29: RZDU0201529 | Q29: 8550 | S29: 115000 | T29: =S29*(F29/1000) -> 983250
A30: контейнер | B30: БС-30377 | C30: БурСервис | D30: EZ MUL NTR (Экстрамул-2000) - 190 кг мет | E30: 090623 | F30: 190 | G30: 1 | H30: Лена | I30: отгружено | J30: 45120 | N30: RZDU0201529 | Q30: 190 | S30: 115000 | T30: =S30*(F30/1000) -> 21850
A31: контейнер | B31: БС-30377 | C31: БурСервис | D31: EZ MUL NTR (Экстрамул-2000) - 190 кг мет | E31: 090623 | F31: 8360 | G31: 44 | H31: Лена | I31: отгружено | J31: 45120 | N31: TKRU3174232 | Q31: 8360 | S31: 115000 | T31: =S31*(F31/1000) -> 961400
A32: контейнер | B32: БС-30377 | C32: БурСервис | D32: EZ MUL NTR (Экстрамул-2000) - 190 кг мет | E32: 190623 | F32: 950 | G32: 5 | H32: Лена | I32: отгружено | J32: 45120 | N32: TKRU3174232 | Q32: 950 | S32: 115000 | T32: =S32*(F32/1000) -> 109250
A33: контейнер | B33: БС-30377 | C33: БурСервис | D33: EZ MUL NTR (Экстрамул-2000) - 190 кг мет | E33: 200623 | F33: 5890 | G33: 31 | H33: Лена | I33: отгружено | J33: 45120 | N33: TKRU3174232 | Q33: 5890 | S33: 115000 | T33: =S33*(F33/1000) -> 677350
A34: контейнер | B34: БС-30377 | C34: БурСервис | D34: EZ MUL NTR (Экстрамул-2000) - 190 кг мет | E34: 200623 | F34: 2850 | G34: 15 | H34: Лена | I34: отгружено | J34: 45120 | N34: TKRU3243821 | Q34: 2850 | S34: 115000 | T34: =S34*(F34/1000) -> 327750
A35: контейнер | B35: БС-30377 | C35: БурСервис | D35: EZ MUL NTR (Экстрамул-2000) - 190 кг мет | E35: 260623 | F35: 1140 | G35: 6 | H35: Лена | I35: отгружено | J35: 45120 | N35: TKRU3243821 | Q35: 1140 | S35: 115000 | T35: =S35*(F35/1000) -> 131100
A36: контейнер | B36: БС-30377 | C36: БурСервис | D36: EZ MUL NTR (Экстрамул-2000) - 190 кг мет | E36: 270623 | F36: 8550 | G36: 45 | H36: Лена | I36: отгружено | J36: 45120 | N36: TKRU3243821 | Q36: 8550 | S36: 115000 | T36: =S36*(F36/1000) -> 983250
A37: контейнер | B37: БС-30377 | C37: БурСервис | D37: EZ MUL NTR (Экстрамул-2000) - 190 кг мет | E37: 280623 | F37: 2660 | G37: 14 | H37: Лена | I37: отгружено | J37: 45120 | N37: TKRU3243821 | Q37: 2660 | S37: 115000 | T37: =S37*(F37/1000) -> 305900
A38: контейнер | B38: БС-30377 | C38: БурСервис | D38: EZ MUL NTR (Экстрамул-2000) - 190 кг мет | E38: 280623 | F38: 5510 | G38: 29 | H38: Лена | I38: отгружено | J38: 45120 | N38: TKRU3357629 | Q38: 5510 | S38: 115000 | T38: =S38*(F38/1000) -> 633650
... A40: контейнер | B40: БС-30377 | C40: БурСервис | D40: EZ MUL NTR (Экстрамул-2000) - 190 кг мет | E40: 300623 | F40: 1140 | G40: 6 | H40: Лена | I40: отгружено | J40: 45120 | N40: TKRU3357629 | Q40: 1140 | S40: 115000 | T40: =S40*(F40/1000) -> 131100
B41: Спец№21 | C41: Энергоресурс | D41: BLACKTROL ж - 200 кг мет | E41: 220623 | F41: 600 | G41: 3 | H41: самовывоз | I41: отгружено | J41: 45120 | K41: Вольво Р150 АС 178 | M41: Андреев Александр | Q41: 600 | S41: 89900 | T41: =S41*(F41/1000) -> 53940
...

Sheet июнь 2023
B1: ОТГРУЗКИ ПРОДУКЦИИ | C1: 45078
A2: заметки | B2: НОМЕР ЗАКАЗА | C2: КЛИЕНТ | D2: ПРОДУКТ | E2: ПАРТИЯ | F2: КОЛИЧЕСТВО | H2: ПУНКТ НАЗНАЧЕНИЯ | I2: СТАТУС | J2: ДАТА ОТГРУЗКИ | K2: АВТОДОСТАВКА | N2: ЖД ДОСТАВКА | O2: ИТОГО ОТГРУЖЕНО | R2: АКТЫ
F3: КГ | G3: мешков/бочек | K3: № АВТО | L3: ТЕЛ. ВОДИТЕЛЯ | M3: ВОДИТЕЛЬ | N3: № КОНТЕЙНЕРА | O3: ЧП | P3: ИНАЯ | Q3: Жидкий | S3: Цена со склада за 1 тонну | T3: Итого
B4: БС-28213 | C4: БурСервис | D4: BaraFLC | E4: 230523 | F4: 19845 | G4: 875 | H4: Новый Уренгой | I4: отгружено | J4: 45078 | K4: Скания К548 ВА 159 | L4: 8 922 386 99 34 | M4: Гомзяков Михаил | O4: 19845 | R4: + | S4: 49500 | T4: =S4*(F4/1000) -> 982327.5
B5: 42569 | C5: ТКШ | D5: R2D2 | E5: 100523 | F5: 1600 | G5: 80 | H5: Новый Уренгой | I5: отгружено | J5: 45078 | K5: Скания М173 ВА 159 | L5: 8 982 480 25 26 | M5: Пепеляев Михаил | P5: 1600 | R5: + | S5: 83000 | T5: =S5*(F5/1000) -> 132800
B6: БС-28209 | C6: БурСервис | D6: ADAPTA II (Ликвитрол) - 25 кг канистра | E6: 160523 | F6: 12000 | G6: 480 | H6: Новый Уренгой | I6: отгружено | J6: 45078 | K6: Скания М173 ВА 159 | L6: 8 982 480 25 26 | M6: Пепеляев Михаил | Q6: 12000 | R6: + | S6: 165000 | T6: =S6*(F6/1000) -> 1980000
B7: Спец№9 | C7: ERIELL | D7: ТЕРРАПАН | E7: 240523 | F7: 20000 | G7: 800 | H7: самовывоз | I7: отгружено | J7: 45078 | K7: Ман 50116СВА | M7: Комалов Шерали | P7: 20000 | S7: 242000 | T7: =S7*(F7/1000) -> 4840000
B8: БС-12837 | C8: БурСервис | D8: EZ MUL NTR (Экстрамул-2000) - 190 кг мет | E8: 260523 | F8: 1520 | G8: 8 | H8: Пурпе | I8: отгружено | J8: 45078 | K8: Рено С705 РО 76 | L8: 8 910 817 94 14 | M8: Пикалев Анатолий | Q8: 1520 | R8: + | S8: 115000 | T8: =S8*(F8/1000) -> 174800
B9: БС-12837 | C9: БурСервис | D9: EZ MUL NTR (Экстрамул-2000) - 190 кг мет | E9: 290523 | F9: 8550 | G9: 45 | H9: Пурпе | I9: отгружено | J9: 45078 | K9: Рено С705 РО 76 | Q9: 8550 | R9: + | S9: 115000 | T9: =S9*(F9/1000) -> 983250
B10: БС-12837 | C10: БурСервис | D10: EZ MUL NTR (Экстрамул-2000) - 190 кг мет | E10: 300523 | F10: 5130 | G10: 27 | H10: Пурпе | I10: отгружено | J10: 45078 | K10: Рено С705 РО 76 | Q10: 5130 | R10: + | S10: 115000 | T10: =S10*(F10/1000) -> 589950
B11: БС-27258 | C11: БурСервис | D11: EZ MUL NTR (Экстрамул-2000) - 190 кг мет | E11: 250523 | F11: 3610 | G11: 19 | H11: Пурпе | I11: отгружено | J11: 45079 | K11: Скания М565 СА 159 | L11: 8 950 811 89 02 | M11: Роготнев Владимир | Q11: 3610 | R11: + | S11: 115000 | T11: =S11*(F11/1000) -> 415150
