Workbook

Sheet декабрь 2025
B1: ОТГРУЗКИ ПРОДУКЦИИ | C1: 45992
A2: заметки | B2: НОМЕР ЗАКАЗА | C2: КЛИЕНТ | D2: ПРОДУКТ | E2: ПАРТИЯ | F2: КОЛИЧЕСТВО | H2: ПУНКТ НАЗНАЧЕНИЯ | I2: СТАТУС | J2: ДАТА ОТГРУЗКИ | K2: АВТОДОСТАВКА | N2: ЖД ДОСТАВКА | O2: ИТОГО ОТГРУЖЕНО | R2: АКТЫ | S2: Цена со склада за 1 тонну
F3: КГ | G3: мешков/бочек | K3: № АВТО | L3: ТЕЛ. ВОДИТЕЛЯ | M3: ВОДИТЕЛЬ | N3: № КОНТЕЙНЕРА/ВАГОНА | O3: ЧП | P3: ИНАЯ | Q3: Жидкий | T3: Итого
A4: авто(Ванюхин) | B4: Спец№24 (2-6) | C4: КазПетроДриллинг | D4: Оптитрол Ж - 200 кг п/эт | E4: 221025 | F4: 800 | G4: 4 | H4: Жанаозен | I4: отгружено | J4: 45992 | K4: DАF Е375АМ198 | L4: 89270908660/87779998937 | M4: Каражан Арман | Q4: 800 | R4: + | S4: 82000 | T4: =S4*F4/1000 -> 65600
A5: авто(Ванюхин) | B5: Спец№24 (2-6) | C5: КазПетроДриллинг | D5: Оптитрол Ж - 200 кг п/эт | E5: 201125 | F5: 6400 | G5: 32 | H5: Жанаозен | I5: отгружено | J5: 45992 | K5: DАF Е375АМ198 | L5: 89270908660/87779998937 | M5: Каражан Арман | Q5: 6400 | R5: + | S5: 82000 | T5: =S5*F5/1000 -> 524800
A6: авто(Ванюхин) | B6: Спец№24 (2-6) | C6: КазПетроДриллинг | D6: Оптитрол Ж - 200 кг п/эт | E6: 211125 | F6: 10400 | G6: 52 | H6: Жанаозен | I6: отгружено | J6: 45992 | K6: DАF Е375АМ198 | L6: 89270908660/87779998937 | M6: Каражан Арман | Q6: 10400 | R6: + | S6: 82000 | T6: =S6*F6/1000 -> 852800
A7: авто(Самовывоз) | B7: Спец№1 | C7: Прогресс-2 | D7: BLACKTROL ж - 200 кг п/эт | E7: 071025 | F7: 1600 | G7: 8 | H7: САМОВЫВОЗ | I7: отгружено | J7: 45992 | K7: ГАЗ К627МВ763 | L7: 890223544561 | M7: Симдянов Павел | Q7: 1600 | R7: + | S7: 111000 | T7: =S7*F7/1000 -> 177600
A8: авто(Бакин) | B8: Спец№97К(4-9) | C8: ОМАС | D8: ТЕРРАПАН - бум 25,0 кг | E8: 10/2025 | F8: 20000 | G8: 800 | H8: НЖВ | I8: отгружено | J8: 45993 | K8: Вольво Р034СВ29 | L8: 89212974613 | M8: Киреев Сергей | P8: 20000 | R8: + | S8: 250000 | T8: =S8*F8/1000 -> 5000000
A9: авто(Ариал) | B9: Спец№49(2-4) | C9: Буринтех | D9: СУЛЬФОБИТ - бум 25,0 кг | E9: 090625 | F9: 20000 | G9: 800 | H9: Пыть-Ях | I9: отгружено | J9: 45993 | K9: Мерседес Е516СМ174 | L9: 89823053258 | M9: Марков Вячеслав | O9: 20000 | R9: + | S9: 41500 | T9: =S9*F9/1000 -> 830000
A10: авто(Ариал) | B10: Спец№49(2-4) | C10: Буринтех | D10: СУЛЬФОБИТ - бум 25,0 кг | E10: 050625 | F10: 1000 | G10: 40 | H10: Пыть-Ях | I10: отгружено | J10: 45993 | K10: Мерседес Е516СМ174 | L10: 89823053258 | M10: Марков Вячеслав | O10: 1000 | R10: + | S10: 41500 | T10: =S10*F10/1000 -> 41500
A11: авто(Инкам) | B11: Спец№97К(5-9) | C11: ОМАС | D11: Сульф асф - бум 25,0 кг | E11: 03/2025 | F11: 18000 | G11: 720 | H11: НЖВ | I11: отгружено | J11: 45996 | K11: DAF К008МА29 | L11: 89116825992 | M11: Белоцерковский Алексей | O11: 18000 | R11: + | S11: 44500 | T11: =S11*F11/1000 -> 801000
A12: авто(Инкам) | B12: Спец№97К(5-9) | C12: ОМАС | D12: ТЕРРАПАН - бум 25,0 кг | E12: 10/2025 | F12: 2000 | G12: 80 | H12: НЖВ | I12: отгружено | J12: 45996 | K12: DAF К008МА29 | L12: 89116825992 | M12: Белоцерковский Алексей | P12: 2000 | R12: + | S12: 250000 | T12: =S12*F12/1000 -> 500000
A13: ДЛ | B13: Счет№369 | C13: БГРП | D13: СУПЕРСЛАЙДЕР ПЛАТИНУМ - 200 кг п/эт | E13: 251125 | F13: 600 | G13: 3 | H13: самовывоз на Рубцовск | I13: отгружено | J13: 45996 | K13: Деловые линии | L13: №00250063878 | Q13: 600 | R13: + | S13: 235000 | T13: =S13*F13/1000 -> 141000
A14: авто(Бакин) | B14: Спец№97К(6-9) | C14: ОМАС | D14: ТЕРРАПАН - бум 25,0 кг | E14: 10/2025 | F14: 18000 | G14: 720 | H14: НЖВ | I14: отгружено | J14: 45999 | K14: Вольво О856УЕ29 | L14: 89216004800 | M14: Рядовкин Евгений | P14: 18000 | R14: + | S14: 250000 | T14: =S14*F14/1000 -> 4500000
A15: авто(Бакин) | B15: Спец№97К(6-9) | C15: ОМАС | D15: Сульф асф - бум 25,0 кг | E15: 03/2025 | F15: 2000 | G15: 80 | H15: НЖВ | I15: отгружено | J15: 45999 | K15: Вольво О856УЕ29 | L15: 89216004800 | M15: Рядовкин Евгений | O15: 2000 | R15: + | S15: 44500 | T15: =S15*F15/1000 -> 89000
A16: авто(Ариал) | B16: Спец№31(1-4) | C16: МАДСЕРВИС | D16: Сульф асф - бум 25,0 кг | E16: 050424 | F16: 12000 | G16: 480 | H16: Бузулук | I16: отгружено | J16: 46000 | K16: РЕНО Н451МС196 | L16: 89923370709 | M16: Дудин Андрей | O16: 12000 | R16: + | S16: 44500 | T16: =S16*F16/1000 -> 534000
A17: авто(Ариал) | B17: Спец№31(1-4) | C17: МАДСЕРВИС | D17: ПОЛИКАП - бум 25,0 кг | E17: 020725 | F17: 2000 | G17: 80 | H17: Бузулук | I17: отгружено | J17: 46000 | K17: РЕНО Н451МС196 | L17: 89923370709 | M17: Дудин Андрей | P17: 2000 | R17: + | S17: 250000 | T17: =S17*F17/1000 -> 500000
A18: авто(Ариал) | B18: Спец№31(1-4) | C18: МАДСЕРВИС | D18: СУПЕРСЛАЙДЕР ГОЛД - 200 кг п/эт | E18: 180424 | F18: 6400 | G18: 32 | H18: Бузулук | I18: отгружено | J18: 46000 | K18: РЕНО Н451МС196 | L18: 89923370709 | M18: Дудин Андрей | Q18: 6400 | R18: + | S18: 105000 | T18: =S18*F18/1000 -> 672000
A19: авто(Ариал) | B19: 01/50/14/09/1264 (1) | C19: Сургутнефтегаз | D19: Оптитрол Ж - 200 кг п/эт | E19: 200925 | F19: 3600 | G19: 18 | H19: Сургут. Белый Яр | I19: отгружено | J19: 46000 | K19: Ситрак У190МУ48 | L19: 89042871081 | M19: Кононыхин Эдуард | Q19: 3600 | R19: + | S19: 85500 | T19: =S19*F19/1000 -> 307800
A20: авто(Ариал) | B20: 01/50/14/09/1264 (1) | C20: Сургутнефтегаз | D20: Оптитрол Ж - 200 кг п/эт | E20: 011025 | F20: 6800 | G20: 34 | H20: Сургут. Белый Яр | I20: отгружено | J20: 46000 | K20: Ситрак У190МУ48 | L20: 89042871081 | M20: Кононыхин Эдуард | Q20: 6800 | R20: + | S20: 85500 | T20: =S20*F20/1000 -> 581400
A21: авто(Ариал) | B21: 01/50/14/09/1264 (1) | C21: Сургутнефтегаз | D21: Оптитрол Ж - 200 кг п/эт | E21: 141125 | F21: 7200 | G21: 36 | H21: Сургут. Белый Яр | I21: отгружено | J21: 46000 | K21: Ситрак У190МУ48 | L21: 89042871081 | M21: Кононыхин Эдуард | Q21: 7200 | R21: + | S21: 85500 | T21: =S21*F21/1000 -> 615600
A22: авто(Рич Трак) | B22: 01/50/14/09/1264 (2) | C22: Сургутнефтегаз | D22: Оптитрол Ж - 200 кг п/эт | E22: 281025 | F22: 6800 | G22: 34 | H22: Сургут. Белый Яр | I22: отгружено | J22: 46001 | K22: ФАВ В066ХЕ122 | L22: 89823630520 | M22: Пенский Дмитрий | Q22: 6800 | R22: + | S22: 85500 | T22: =S22*F22/1000 -> 581400
A23: авто(Рич Трак) | B23: 01/50/14/09/1264 (2) | C23: Сургутнефтегаз | D23: Оптитрол Ж - 200 кг п/эт | E23: 291025 | F23: 7000 | G23: 35 | H23: Сургут. Белый Яр | I23: отгружено | J23: 46001 | K23: ФАВ В066ХЕ122 | L23: 89823630520 | M23: Пенский Дмитрий | Q23: 7000 | R23: + | S23: 85500 | T23: =S23*F23/1000 -> 598500
A24: авто(Рич Трак) | B24: 01/50/14/09/1264 (2) | C24: Сургутнефтегаз | D24: Оптитрол Ж - 200 кг п/эт | E24: 311025 | F24: 3800 | G24: 19 | H24: Сургут. Белый Яр | I24: отгружено | J24: 46001 | K24: ФАВ В066ХЕ122 | L24: 89823630520 | M24: Пенский Дмитрий | Q24: 3800 | R24: + | S24: 85500 | T24: =S24*F24/1000 -> 324900
A25: авто(Рич Трак) | B25: 01/50/14/09/1264 (3) | C25: Сургутнефтегаз | D25: BLACKTROL ж - 200 кг п/эт | E25: 020925 | F25: 8800 | G25: 44 | H25: Сургут. Белый Яр | I25: отгружено | J25: 46001 | K25: СКАНИЯ Х311КУ55 | L25: 89131417754 | M25: Елпашов Ярослав | Q25: 8800 | R25: + | S25: 94500 | T25: =S25*F25/1000 -> 831600
A26: авто(Рич Трак) | B26: 01/50/14/09/1264 (3) | C26: Сургутнефтегаз | D26: BLACKTROL ж - 200 кг п/эт | E26: 040925 | F26: 8800 | G26: 44 | H26: Сургут. Белый Яр | I26: отгружено | J26: 46001 | K26: СКАНИЯ Х311КУ55 | L26: 89131417754 | M26: Елпашов Ярослав | Q26: 8800 | R26: + | S26: 94500 | T26: =S26*F26/1000 -> 831600
A27: авто(Агро) | B27: 01/50/14/09/1264 (4) | C27: Сургутнефтегаз | D27: Оптитрол Ж - 200 кг п/эт | E27: 050925 | F27: 7200 | G27: 36 | H27: Сургут. Белый Яр | I27: отгружено | J27: 46001 | K27: VOLVO С 497ОС193 | L27: 89182638560 | M27: Шаханин Александр | Q27: 7200 | R27: + | S27: 85500 | T27: =S27*F27/1000 -> 615600
A28: авто(Агро) | B28: 01/50/14/09/1264 (4) | C28: Сургутнефтегаз | D28: Оптитрол Ж - 200 кг п/эт | E28: 050925/1 | F28: 6800 | G28: 34 | H28: Сургут. Белый Яр | I28: отгружено | J28: 46001 | K28: VOLVO С 497ОС193 | L28: 89182638560 | M28: Шаханин Александр | Q28: 6800 | R28: + | S28: 85500 | T28: =S28*F28/1000 -> 581400
A29: авто(Агро) | B29: 01/50/14/09/1264 (4) | C29: Сургутнефтегаз | D29: Оптитрол Ж - 200 кг п/эт | E29: 200925 | F29: 3600 | G29: 18 | H29: Сургут. Белый Яр | I29: отгружено | J29: 46001 | K29: VOLVO С 497ОС193 | L29: 89182638560 | M29: Шаханин Александр | Q29: 3600 | R29: + | S29: 85500 | T29: =S29*F29/1000 -> 307800
... A31: авто(Ариал) | B31: 01/50/14/09/1264 (5) | C31: Сургутнефтегаз | D31: BLACKTROL ж - 200 кг п/эт | E31: 071125 | F31: 8800 | G31: 44 | H31: Сургут. Белый Яр | I31: отгружено | J31: 46001 | K31: Вольво М958МВ29 | L31: 89991688169 | M31: Манаков Юрий | Q31: 8800 | R31: + | S31: 94500 | T31: =S31*F31/1000 -> 831600
A32: авто(Агро) | B32: Спец№31(2-4) | C32: МАДСЕРВИС | D32: Сульф асф - бум 25,0 кг | E32: 050424 | F32: 20000 | G32: 800 | H32: Бузулук | I32: отгружено | J32: 46002 | K32: Ивеко А479ТУ43 | L32: 89229265251 | M32: Парфенов Василий | O32: 20000 | R32: + | S32: 44500 | T32: =S32*F32/1000 -> 890000
A33: авто (Рич Трак) | B33: Спец№155 | C33: Акрос | D33: BLACKTROL ж - 215,5 кг п/эт | E33: 101225 | F33: 18964 | G33: 88 | H33: Ноябрьск | I33: отгружено | J33: 46003 | K33: Скания В913ХВ35 | L33: 89115127033 | M33: Соколов Михаил | Q33: 18964 | R33: + | S33: 93000 | T33: =S33*F33/1000 -> 1763652
A34: авто() | B34: Спец№97К(7-9) | C34: ОМАС | D34: Сульф асф - бум 25,0 кг | E34: 03/2025 | F34: 20000 | G34: 800 | H34: НЖВ | I34: отгружено | J34: 46003 | K34: SHACMAN М274ВЕ702 | L34: 89051805168 | M34: Абдрашитов Роберт | O34: 20000 | R34: + | S34: 44500 | T34: =S34*F34/1000 -> 890000
A35: кнт | B35: БС-122779 | C35: БурСервис | D35: DRIL-N-SLIDE (СС Платинум) - 175 кг п/эт | E35: 041225 | F35: 7000 | G35: 40 | H35: Пурпе | I35: отгружено | J35: 46006 | K35: Камаз Е999СА29 | L35: 89115583359 | M35: Вайгант Сергей | N35: RZDU0728417 | Q35: 7000 | R35: + | S35: 255000 | T35: =S35*F35/1000 -> 1785000
A36: кнт | B36: БС-122779 | C36: БурСервис | D36: DRIL-N-SLIDE (СС Платинум) - 175 кг п/эт | E36: 051225 | F36: 7000 | G36: 40 | H36: Пурпе | I36: отгружено | J36: 46006 | K36: Камаз Е999СА29 | L36: 89115583359 | M36: Вайгант Сергей | N36: RZDU0728417 | Q36: 7000 | R36: + | S36: 255000 | T36: =S36*F36/1000 -> 1785000
A37: авто(Семенов) | B37: Спец№97К(8-9) | C37: ОМАС | D37: ТЕРРАПАН - бум 25,0 кг | E37: 10/2025 | F37: 20000 | G37: 800 | H37: НЖВ | I37: отгружено | J37: 46007 | K37: ДАФ У377МХ45 | L37: 89195966929 | M37: Ильин Андрей | P37: 20000 | R37: + | S37: 250000 | T37: =S37*F37/1000 -> 5000000
A38: авто(Агро) | B38: Спец№97К(9-9) | C38: ОМАС | D38: Сульф асф - бум 25,0 кг | E38: 03/2025 | F38: 18000 | G38: 720 | H38: НЖВ | I38: отгружено | J38: 46007 | K38: МЕРСЕДЕС У555ВО56 | L38: 89877892282 | M38: Садыков Михаил | O38: 18000 | R38: + | S38: 44500 | T38: =S38*F38/1000 -> 801000
A39: авто(Агро) | B39: Спец№97К(9-9) | C39: ОМАС | D39: ТЕРРАПАН - бум 25,0 кг | E39: 10/2025 | F39: 2000 | G39: 80 | H39: НЖВ | I39: отгружено | J39: 46007 | K39: МЕРСЕДЕС У555ВО56 | L39: 89877892282 | M39: Садыков Михаил | P39: 2000 | R39: + | S39: 250000 | T39: =S39*F39/1000 -> 500000
A40: авто(Ариал) | B40: 01/50/14/09/1264 (6) | C40: Сургутнефтегаз | D40: Оптитрол Ж - 200 кг п/эт | E40: 311025 | F40: 3200 | G40: 16 | H40: Сургут. Белый Яр | I40: отгружено | J40: 46007 | K40: ВОЛЬВО О951РК72 | L40: 89966862434 | M40: Добрыдин Станислав | Q40: 3200 | R40: + | S40: 85500 | T40: =S40*F40/1000 -> 273600
A41: авто(Ариал) | B41: 01/50/14/09/1264 (6) | C41: Сургутнефтегаз | D41: Оптитрол Ж - 200 кг п/эт | E41: 101225 | F41: 6400 | G41: 32 | H41: Сургут. Белый Яр | I41: отгружено | J41: 46007 | K41: ВОЛЬВО О951РК72 | L41: 89966862434 | M41: Добрыдин Станислав | Q41: 6400 | R41: + | S41: 85500 | T41: =S41*F41/1000 -> 547200
...

Sheet ноябрь 2025
B1: ОТГРУЗКИ ПРОДУКЦИИ | C1: 45962
A2: заметки | B2: НОМЕР ЗАКАЗА | C2: КЛИЕНТ | D2: ПРОДУКТ | E2: ПАРТИЯ | F2: КОЛИЧЕСТВО | H2: ПУНКТ НАЗНАЧЕНИЯ | I2: СТАТУС | J2: ДАТА ОТГРУЗКИ | K2: АВТОДОСТАВКА | N2: ЖД ДОСТАВКА | O2: ИТОГО ОТГРУЖЕНО | R2: АКТЫ | S2: Цена со склада за 1 тонну
F3: КГ | G3: мешков/бочек | K3: № АВТО | L3: ТЕЛ. ВОДИТЕЛЯ | M3: ВОДИТЕЛЬ | N3: № КОНТЕЙНЕРА/ВАГОНА | O3: ЧП | P3: ИНАЯ | Q3: Жидкий | T3: Итого
A5: авто(Агро) | B5: Спец№30 | C5: МАДСЕРВИС | D5: Сульф асф - бум 25,0 кг | E5: 050424 | F5: 6000 | G5: 240 | H5: Уфа | I5: отгружено | J5: 45962 | K5: Ивеко К209РО702 | L5: 89174032153 | M5: Сафкин Денис | O5: 6000 | R5: + | S5: 44500 | T5: =S5*F5/1000 -> 267000
A6: авто(Агро) | B6: Спец№30 | C6: МАДСЕРВИС | D6: СТАБИЛАЙТ РУО - бум 25,0 кг | E6: 281025 | F6: 2000 | G6: 80 | H6: Уфа | I6: отгружено | J6: 45962 | K6: Ивеко К209РО702 | L6: 89174032153 | M6: Сафкин Денис | P6: 2000 | R6: + | S6: 70000 | T6: =S6*F6/1000 -> 140000
A7: авто(Агро) | B7: Спец№30 | C7: МАДСЕРВИС | D7: ТЕРМАВИС РУО - бум 20,0 кг | E7: 301025 | F7: 3000 | G7: 150 | H7: Уфа | I7: отгружено | J7: 45962 | K7: Ивеко К209РО702 | L7: 89174032153 | M7: Сафкин Денис | P7: 3000 | R7: + | S7: 270000 | T7: =S7*F7/1000 -> 810000
A8: авто(Агро) | B8: Спец№30 | C8: МАДСЕРВИС | D8: РЕОМОД ж - 180 кг п/эт | E8: 311025 | F8: 2160 | G8: 12 | H8: Уфа | I8: отгружено | J8: 45962 | K8: Ивеко К209РО702 | L8: 89174032153 | M8: Сафкин Денис | Q8: 2160 | R8: + | S8: 310000 | T8: =S8*F8/1000 -> 669600
A9: авто(Агро) | B9: Спец№30 | C9: МАДСЕРВИС | D9: ЭКСТРАМУЛ-2000 - 200 кг п/эт | E9: 291025 | F9: 6400 | G9: 32 | H9: Уфа | I9: отгружено | J9: 45962 | K9: Ивеко К209РО702 | L9: 89174032153 | M9: Сафкин Денис | Q9: 6400 | R9: + | S9: 135000 | T9: =S9*F9/1000 -> 864000
A10: авто (Бакин) | B10: Спец№94К | C10: ОМАС | D10: Сульф асф - бум 25,0 кг | E10: 03/2025 | F10: 4000 | G10: 160 | H10: Нижневартовск | I10: отгружено | J10: 45966 | K10: Вольво О856УЕ29 | L10: 89216004800 | M10: Рядовкин Евгений | O10: 4000 | R10: + | S10: 44500 | T10: =S10*F10/1000 -> 178000
A11: авто (Бакин) | B11: Спец№94К | C11: ОМАС | D11: СУПЕРСЛАЙДЕР ГОЛД - 200 кг п/эт | E11: 230425 | F11: 16000 | G11: 80 | H11: Нижневартовск | I11: отгружено | J11: 45966 | K11: Вольво О856УЕ29 | L11: 89216004800 | M11: Рядовкин Евгений | Q11: 16000 | R11: + | S11: 105000 | T11: =S11*F11/1000 -> 1680000
A12: авто(Агро) | B12: Спец№152(7-7) | C12: Акрос | D12: Drilling Lube (СС РУО) - 200 кг п/эт | E12: 241025 | F12: 17600 | G12: 88 | H12: Мурманск | I12: отгружено | J12: 45966 | K12: Камаз К033ТУ34 | L12: 89814308537/89315037120 | M12: Напалков Сергей | Q12: 17600 | R12: + | S12: 369000 | T12: =S12*F12/1000 -> 6494400
A13: авто(Ванюхин) | B13: Спец№22 (2-2) | C13: КазПетроДриллинг | D13: Оптитрол Ж - 200 кг п/эт | E13: 080825 | F13: 3200 | G13: 16 | H13: Жанаозен | I13: отгружено | J13: 45971 | K13: Volvo Т681МР67 | L13: 89608185086/1777918885 | M13: Ащегулов Семён | Q13: 3200 | R13: + | S13: 82000 | T13: =S13*F13/1000 -> 262400
A14: авто(Ванюхин) | B14: Спец№22 (2-2) | C14: КазПетроДриллинг | D14: Оптитрол Ж - 200 кг п/эт | E14: 120825 | F14: 6400 | G14: 32 | H14: Жанаозен | I14: отгружено | J14: 45971 | K14: Volvo Т681МР67 | L14: 89608185086/1777918885 | M14: Ащегулов Семён | Q14: 6400 | R14: + | S14: 82000 | T14: =S14*F14/1000 -> 524800
A15: авто(Ванюхин) | B15: Спец№22 (2-2) | C15: КазПетроДриллинг | D15: Оптитрол Ж - 200 кг п/эт | E15: 130825 | F15: 6800 | G15: 34 | H15: Жанаозен | I15: отгружено | J15: 45971 | K15: Volvo Т681МР67 | L15: 89608185086/1777918885 | M15: Ащегулов Семён | Q15: 6800 | R15: + | S15: 82000 | T15: =S15*F15/1000 -> 557600
A16: авто(Ванюхин) | B16: Спец№22 (2-2) | C16: КазПетроДриллинг | D16: Оптитрол Ж - 200 кг п/эт | E16: 140825 | F16: 400 | G16: 2 | H16: Жанаозен | I16: отгружено | J16: 45971 | K16: Volvo Т681МР67 | L16: 89608185086/1777918885 | M16: Ащегулов Семён | Q16: 400 | R16: + | S16: 82000 | T16: =S16*F16/1000 -> 32800
A17: авто(Ванюхин) | B17: Спец№22 (2-2) | C17: КазПетроДриллинг | D17: Оптитрол Ж - 200 кг п/эт | E17: 150825 | F17: 600 | G17: 3 | H17: Жанаозен | I17: отгружено | J17: 45971 | K17: Volvo Т681МР67 | L17: 89608185086/1777918885 | M17: Ащегулов Семён | Q17: 600 | R17: + | S17: 82000 | T17: =S17*F17/1000 -> 49200
A18: авто(Ванюхин) | B18: Спец№22 (2-2) | C18: КазПетроДриллинг | D18: Оптитрол Ж - 200 кг п/эт | E18: 190825 | F18: 200 | G18: 1 | H18: Жанаозен | I18: отгружено | J18: 45971 | K18: Volvo Т681МР67 | L18: 89608185086/1777918885 | M18: Ащегулов Семён | Q18: 200 | R18: + | S18: 82000 | T18: =S18*F18/1000 -> 16400
A19: авто(Инкам) | B19: Спец№95К | C19: ОМАС | D19: Сульф асф - бум 25,0 кг | E19: 03/2025 | F19: 20000 | G19: 800 | H19: Пыть-Ях | I19: отгружено | J19: 45971 | K19: DAF О539ОН29 | L19: 89216700606 | M19: Хрущ Александр | O19: 20000 | R19: + | S19: 44500 | T19: =S19*F19/1000 -> 890000
A20: авто(ГК Урал) | B20: Спец№95К | C20: ОМАС | D20: СУПЕРСЛАЙДЕР ГОЛД - 200 кг п/эт | E20: 230425 | F20: 17600 | G20: 88 | H20: Пыть-Ях | I20: отгружено | J20: 45974 | K20: Вольво М441ВК96 | L20: 89995402889 | M20: Краснощеков Сергей | Q20: 17600 | R20: + | S20: 105000 | T20: =S20*F20/1000 -> 1848000
A21: авто(ГК Урал) | B21: Спец№96К (1-2) | C21: ОМАС | D21: Сульф асф - бум 25,0 кг | E21: 03/2025 | F21: 20000 | G21: 800 | H21: Пыть-Ях | I21: отгружено | J21: 45975 | K21: Вольво У251МУ72 | L21: 89199519633 | M21: Григорьев Евгений | O21: 20000 | R21: + | S21: 44500 | T21: =S21*F21/1000 -> 890000
A22: авто(Вельшеда) | B22: Спец№29 | C22: МАДСЕРВИС | D22: Сульф асф - бум 25,0 кг | E22: 050424 | F22: 13000 | G22: 520 | H22: Нижневартовск | I22: отгружено | J22: 45974 | K22: Мерседес Е283РТ797 | L22: 89206754537 | M22: Хохлев Владимир | O22: 13000 | R22: + | S22: 44500 | T22: =S22*F22/1000 -> 578500
A23: авто(Вельшеда) | B23: Спец№29 | C23: МАДСЕРВИС | D23: ТЕРРАПАН - бум 25,0 кг | E23: 200825 | F23: 7000 | G23: 280 | H23: Нижневартовск | I23: отгружено | J23: 45974 | K23: Мерседес Е283РТ797 | L23: 89206754537 | M23: Хохлев Владимир | P23: 7000 | R23: + | S23: 250000 | T23: =S23*F23/1000 -> 1750000
A24: авто(Инкам) | B24: Спец№96К (2-2) | C24: ОМАС | D24: Сульф асф - бум 25,0 кг | E24: 03/2025 | F24: 20000 | G24: 800 | H24: Пыть-Ях | I24: отгружено | J24: 45975 | K24: DAF К008МА29 | L24: 89116825992 | M24: Белоцерковский Алексей | O24: 20000 | R24: + | S24: 44500 | T24: =S24*F24/1000 -> 890000
A25: Деловые Линии | B25: Счет №357 | C25: Парм-Гинс | D25: ТЕРМАВИС РУО - бум 22,7 кг | E25: 150625 | F25: 22.7 | G25: 1 | H25: Волгоград | I25: отгружено | J25: 45981 | K25: Деловые Линии | L25: Наклд. №00250060962 | P25: 22.7 | R25: + | S25: 316000.08 | T25: =S25*F25/1000 -> 7173.2018
A26: авто(Ванюхин) | B26: Спец№24 (1-6) | C26: КазПетроДриллинг | D26: Оптитрол Ж - 200 кг п/эт | E26: 190825 | F26: 4000 | G26: 20 | H26: Жанаозен | I26: отгружено | J26: 45982 | K26: Mercedes Р039ВВ250 | L26: 89773804045 | M26: Котов Денис | Q26: 4000 | R26: + | S26: 82000 | T26: =S26*F26/1000 -> 328000
A27: авто(Ванюхин) | B27: Спец№24 (1-6) | C27: КазПетроДриллинг | D27: Оптитрол Ж - 200 кг п/эт | E27: 211025 | F27: 7200 | G27: 36 | H27: Жанаозен | I27: отгружено | J27: 45982 | K27: Mercedes Р039ВВ250 | L27: 89773804045 | M27: Котов Денис | Q27: 7200 | R27: + | S27: 82000 | T27: =S27*F27/1000 -> 590400
A28: авто(Ванюхин) | B28: Спец№24 (1-6) | C28: КазПетроДриллинг | D28: Оптитрол Ж - 200 кг п/эт | E28: 221025 | F28: 6400 | G28: 32 | H28: Жанаозен | I28: отгружено | J28: 45982 | K28: Mercedes Р039ВВ250 | L28: 89773804045 | M28: Котов Денис | Q28: 6400 | R28: + | S28: 82000 | T28: =S28*F28/1000 -> 524800
A29: авто | B29: Спец№35 | C29: Энергоресурс | D29: BLACKTROL ж - 200 кг п/эт | E29: 220425 | F29: 3200 | G29: 16 | H29: Пермь | I29: отгружено | J29: 45982 | K29: С956НУ716 | L29: 89312303316 | M29: Галеев Ильгиз | Q29: 3200 | R29: + | S29: 89900 | T29: =S29*F29/1000 -> 287680
A30: авто | B30: Спец№35 | C30: Энергоресурс | D30: BLACKTROL ж - 210 кг п/эт | E30: 210125 | F30: 3360 | G30: 16 | H30: Пермь | I30: отгружено | J30: 45982 | K30: С956НУ716 | L30: 89312303316 | M30: Галеев Ильгиз | Q30: 3360 | R30: + | S30: 89900 | T30: =S30*F30/1000 -> 302064
A31: авто(Коровин) | B31: Спец№97К(1-9) | C31: ОМАС | D31: Сульф асф - бум 25,0 кг | E31: 03/2025 | F31: 20000 | G31: 800 | H31: НЖВ | I31: отгружено | J31: 45986 | K31: ДАФ У377МХ45 | L31: 89195966929 | M31: Ильин Андрей | O31: 20000 | R31: + | S31: 44500 | T31: =S31*F31/1000 -> 890000
A32: авто(Инкам) | B32: Спец№97К(2-9) | C32: ОМАС | D32: Сульф асф - бум 25,0 кг | E32: 03/2025 | F32: 20000 | G32: 800 | H32: НЖВ | I32: отгружено | J32: 45986 | K32: DAF О539ОН29 | L32: 89216700606 | M32: Хрущ Александр | O32: 20000 | R32: + | S32: 44500 | T32: =S32*F32/1000 -> 890000
A33: авто(КЛОТО) | B33: Спец№97К(3-9) | C33: ОМАС | D33: СУПЕРСЛАЙДЕР ГОЛД - 200 кг п/эт | E33: 230425 | F33: 17600 | G33: 88 | H33: НЖВ | I33: отгружено | J33: 45989 | K33: Mercedes О515ОУ29 | L33: 89115800204 | M33: Борисов Дмитрий | Q33: 17600 | R33: + | S33: 105000 | T33: =S33*F33/1000 -> 1848000
T34: =SUM(T5:T33) -> 25060817
A35: Итого заказов на: | B35: =SUM($F$5:$F$34)/1000 -> 254.1427 | C35: т
A36: Итого отгружено: | B36: =$B$37+$B$38+$B$39 -> 254.1427 | C36: т | F36: образцы заказаны
A37: из них ЧП: | B37: =SUM(O5:O34)/1000 -> 123 | C37: т | F37: завел в отчет по отгрузкам
A38: из них ИНАЯ: | B38: =SUM(P5:P34)/1000 -> 12.0227 | C38: т | F38: отправил ПК
A39: из них на жидкий: | B39: =SUM(Q5:Q34)/1000 -> 119.12 | C39: т | F39: Надо заполнить
A40: Осталось отгрузить | B40: =$B$35-$B$36 -> 0 | C40: т | F40: Не выполнено

Sheet октябрь 2025
B1: ОТГРУЗКИ ПРОДУКЦИИ | C1: 45931
A2: заметки | B2: НОМЕР ЗАКАЗА | C2: КЛИЕНТ | D2: ПРОДУКТ | E2: ПАРТИЯ | F2: КОЛИЧЕСТВО | H2: ПУНКТ НАЗНАЧЕНИЯ | I2: СТАТУС | J2: ДАТА ОТГРУЗКИ | K2: АВТОДОСТАВКА | N2: ЖД ДОСТАВКА | O2: ИТОГО ОТГРУЖЕНО | R2: АКТЫ | S2: Цена со склада за 1 тонну
F3: КГ | G3: мешков/бочек | K3: № АВТО | L3: ТЕЛ. ВОДИТЕЛЯ | M3: ВОДИТЕЛЬ | N3: № КОНТЕЙНЕРА/ВАГОНА | O3: ЧП | P3: ИНАЯ | Q3: Жидкий | T3: Итого
A5: авто(АКС) | B5: Спец№25(1-3) | C5: МАДСЕРВИС | D5: Сульф асф - бум 25,0 кг | E5: 050424 | F5: 20000 | G5: 800 | H5: Нижневартовск | I5: отгружен | J5: 45931 | K5: Даф Х 901 КС 72 | L5: 89829645340 | M5: Солянников Дмитрий | O5: 20000 | R5: + | S5: 44500 | T5: =S5*(F5/1000) -> 890000
A6: Самовывоз | B6: Спец 2 | C6: FWL | D6: ЭКСТРАМУЛ-2000 - 180 кг мет | E6: 180925 | F6: =G6*180 -> 3600 | G6: 20 | H6: Самовывоз | I6: отгружен | J6: 45931 | K6: Renault М571СУ 35 | L6: 89062807497 | M6: Доля Виталий Владимирович | Q6: 3600 | R6: + | S6: 127500 | T6: =S6*(F6/1000) -> 459000
A7: Самовывоз | B7: Спец 2 | C7: FWL | D7: ЭКСТРАМУЛ-2000 - 180 кг мет | E7: 220925 | F7: =G7*180 -> 10800 | G7: 60 | H7: Самовывоз | I7: отгружен | J7: 45931 | K7: Renault М571СУ 35 | L7: 89062807497 | M7: Доля Виталий Владимирович | Q7: 10800 | R7: + | S7: 127500 | T7: =S7*(F7/1000) -> 1377000
A8: Самовывоз | B8: Спец 2 | C8: FWL | D8: ВЕЛЛТРИТ - 180 кг мет | E8: 170925 | F8: =G8*180 -> 14400 | G8: 80 | H8: Самовывоз | I8: отгружен | J8: 45931 | K8: DAF М048КХ67 | L8: 89092943651 | M8: Ясинский Владимир | Q8: 14400 | R8: + | S8: 146500 | T8: =S8*(F8/1000) -> 2109600
A9: ВЕЛЬШЕДА | B9: RSH7.MDS.R-25-0800-008928 | C9: ТКШ | D9: АДВАНТА п - бум 14,0 кг | E9: 300925 | F9: 14000 | G9: 1000 | H9: Холмск | I9: отгружен | J9: 45933 | K9: Scania Н 244 УР29 | L9: 89648370244 | M9: Голуб Игорь Анатольевич | P9: =F9 -> 14000 | R9: + | S9: 317000 | T9: =S9*(F9/1000) -> 4438000
A10: Самовывоз | B10: Спец 2 | C10: FWL | D10: ЭКСТРАМУЛ-2000 - 180 кг мет | E10: 220925 | F10: =G10*180 -> 7200 | G10: 40 | H10: Самовывоз | I10: отгружен | J10: 45933 | K10: VOLVO Р450НК 27 | L10: 89098291001 | M10: Кутепов Евгений Александрович | Q10: =F10 -> 7200 | R10: + | S10: 127500 | T10: =S10*(F10/1000) -> 918000
A11: Самовывоз | B11: Спец 2 | C11: FWL | D11: ЭКСТРАМУЛ-2000 - 180 кг мет | E11: 240925 | F11: =G11*180 -> 7200 | G11: 40 | H11: Самовывоз | I11: отгружен | J11: 45933 | K11: VOLVO Р450НК 27 | L11: 89098291001 | M11: Кутепов Евгений Александрович | Q11: =F11 -> 7200 | R11: + | S11: 127500 | T11: =S11*(F11/1000) -> 918000
A12: авто(Авто 45) | B12: Спец№89К | C12: Омас | D12: Сульф асф - п/проп обезл 25,0 кг | E12: 03/2025 | F12: 20000 | G12: 800 | H12: Пыть-Ях | I12: отгружен | J12: 45933 | K12: DAF К298МО45 | L12: 89080063420 | M12: Антонов Евгений Васильевич | O12: =F12 -> 20000 | R12: + | S12: 44500 | T12: =S12*(F12/1000) -> 890000
A13: авто(Авто 45) | B13: Спец№27(1-2) | C13: МАДСЕРВИС | D13: Сульф асф - бум 25,0 кг | E13: 050425 | F13: 4000 | G13: 160 | H13: Нижневартовск | I13: отгружен | J13: 45933 | K13: DAF Р575МС45 | L13: 89125770562 | M13: Осипов Дмитрий Петрович | O13: =F13 -> 4000 | R13: + | S13: 44500 | T13: =S13*(F13/1000) -> 178000
A14: авто(Авто 45) | B14: Спец№27(1-2) | C14: МАДСЕРВИС | D14: ТЕРРАПАН - бум 25,0 кг | E14: 200825 | F14: 15000 | G14: 600 | H14: Нижневартовск | I14: отгружен | J14: 45933 | K14: DAF Р575МС45 | L14: 89125770562 | M14: Осипов Дмитрий Петрович | P14: =F14 -> 15000 | R14: + | S14: 250000 | T14: =S14*(F14/1000) -> 3750000
A15: авто(Авто 45) | B15: Спец№27(1-2) | C15: МАДСЕРВИС | D15: СУПЕРСЛАЙДЕР ГОЛД - 200 кг п/эт | E15: 180424 | F15: 1600 | G15: 8 | H15: Нижневартовск | I15: отгружен | J15: 45933 | K15: DAF Р575МС45 | L15: 89125770562 | M15: Осипов Дмитрий Петрович | Q15: =F15 -> 1600 | R15: + | S15: 105000 | T15: =S15*(F15/1000) -> 168000
A16: Клото | B16: Спец№3 | C16: АВК | D16: Сода кальцинированная | F16: 20000 | G16: 20 | H16: Архангельск | I16: отгружен | J16: 45933 | K16: Mercedes-Benz О515ОУ29 | L16: 89115800204 | M16: Борисов Дмитрий Сергеевич | P16: 20000 | R16: + | S16: 39000 | T16: =S16*(F16/1000) -> 780000
A17: Самовывоз | B17: Спец 2 | C17: FWL | D17: ВЕЛЛТРИТ - 180 кг мет | E17: 190925 | F17: =G17*180 -> 14400 | G17: 80 | H17: Самовывоз | I17: отгружен | J17: 45936 | K17: SCANIA М165ТА 159 | L17: 89128871037 | M17: Глазырин Виктор Геннадьевич | Q17: 14400 | R17: + | S17: 146500 | T17: =S17*(F17/1000) -> 2109600
A18: авто(Авто 45) | B18: Спец№25(2-3) | C18: МАДСЕРВИС | D18: Сульф асф - бум 25,0 кг | E18: 050424 | F18: 20000 | G18: 800 | H18: Нижневартовск | I18: отгружен | J18: 45936 | K18: DAF А032НА45 | L18: 89822215272 | M18: Бывальцев Денис Михайлович | O18: =F18 -> 20000 | R18: + | S18: 44500 | T18: =S18*(F18/1000) -> 890000
A19: авто(ИП Семенова) | B19: Спец№25(3-3) | C19: МАДСЕРВИС | D19: Сульф асф - бум 25,0 кг | E19: 050424 | F19: 20000 | G19: 800 | H19: Нижневартовск | I19: отгружен | J19: 45936 | K19: DAF В 426 МХ 45 | L19: 89125754867 | M19: Анфалов Сергей Аркадьевич | O19: =F19 -> 20000 | R19: + | S19: 44500 | T19: =S19*(F19/1000) -> 890000
A20: авто(Бакин) | B20: Спец№27 (2-2) | C20: МАДСЕРВИС | D20: Сульф асф - бум 25,0 кг | E20: 050424 | F20: 20000 | G20: 800 | H20: Нижневартовск | I20: отгружен | J20: 45937 | K20: Вольво О 618 СМ 29 | L20: 89115713730 | M20: Фокин Дмитрий Викторович | O20: =F20 -> 20000 | R20: + | S20: 44500 | T20: =S20*(F20/1000) -> 890000
A21: Авто (Клото) | B21: Спец№93К(1-6) | C21: ОМАС | D21: Сульф асф - бум 25,0 кг | E21: 03/2025 | F21: 20000 | G21: 800 | H21: Пыть-Ях | I21: Отгружен | J21: 45937 | K21: Mercedes-Benz О515ОУ29 | L21: 89115800204 | M21: Борисов Дмитрий Сергеевич | O21: =F21 -> 20000 | R21: + | S21: 44500 | T21: =S21*(F21/1000) -> 890000
A22: Самовывоз | B22: Спец 2 | C22: FWL | D22: ЭКСТРАМУЛ-2000 - 180 кг мет | E22: 240925 | F22: =G22*180 -> 10800 | G22: 60 | H22: Самовывоз | I22: отгружен | J22: 45937 | K22: VOLVO У911ОР 48 | L22: 89086044720 | M22: Помольцев Александр Викторович | Q22: 10800 | R22: + | S22: 127500 | T22: =S22*(F22/1000) -> 1377000
A23: Самовывоз | B23: Спец 2 | C23: FWL | D23: ЭКСТРАМУЛ-2000 - 180 кг мет | E23: 250925 | F23: =G23*180 -> 3600 | G23: 20 | H23: Самовывоз | I23: отгружен | J23: 45937 | K23: VOLVO У911ОР 48 | L23: 89086044720 | M23: Помольцев Александр Викторович | Q23: 3600 | R23: + | S23: 127500 | T23: =S23*(F23/1000) -> 459000
A24: Самовывоз | B24: Спец 2 | C24: FWL | D24: ЭКСТРАМУЛ-2000 - 180 кг мет | E24: 250925 | F24: =G24*180 -> 10800 | G24: 60 | H24: Самовывоз | I24: отгружен | J24: 45937 | K24: КАМАЗ А815ОТ 193 | L24: 89189908365 | M24: Дудник Кирилл Николаевич | Q24: =F24 -> 10800 | R24: + | S24: 127500 | T24: =S24*(F24/1000) -> 1377000
A25: Самовывоз | B25: Спец 2 | C25: FWL | D25: ВЕЛЛТРИТ - 180 кг мет | E25: 190925 | F25: =G25*180 -> 3600 | G25: 20 | H25: Самовывоз | I25: отгружен | J25: 45937 | K25: КАМАЗ А815ОТ 193 | L25: 89189908365 | M25: Дудник Кирилл Николаевич | Q25: =F25 -> 3600 | R25: + | S25: 146500 | T25: =S25*(F25/1000) -> 527400
A26: авто(Бакин) | B26: Спец№154 (1-2) | C26: Акрос | D26: BLACKTROL ж - 215,5 кг п/эт | E26: 071025 | F26: 18964 | G26: 88 | H26: Ноябрьск | I26: отгружен | J26: 45938 | K26: Вольво Р 034 СВ 29 | L26: 89212974613 | M26: Киреев Сергей Владимирович | Q26: =F26 -> 18964 | R26: + | S26: 93000 | T26: =S26*(F26/1000) -> 1763652
A27: авто (АГРО) | B27: Спец№1 | C27: Волганефтетранс | D27: BLACKTROL ж - 200 кг п/эт | E27: 071025 | F27: 2400 | G27: 12 | H27: Саратов | I27: отгружен | J27: 45938 | K27: газель Х 170 ТА 72 | L27: 89003337955 | M27: Демендеев Руслан Николаевич | Q27: =F27 -> 2400 | R27: + | S27: 111000 | T27: =S27*F27/1000 -> 266400
A28: авто (АГРО) | B28: БС-116085 | C28: БурСервис | D28: DRIL-N-SLIDE (СС Платинум) - 175 кг п/эт | E28: 071025 | F28: =44*175 -> 7700 | G28: 44 | H28: Пурпе | I28: отгружен | J28: 45939 | K28: Ивеко С 669 УК 56 | L28: 89878985273 | M28: Яновский Сергей Александрович | Q28: =F28 -> 7700 | R28: + | S28: 255000 | T28: =S28*F28/1000 -> 1963500
A29: авто (АГРО) | B29: БС-116085 | C29: БурСервис | D29: DRIL-N-SLIDE (СС Платинум) - 175 кг п/эт | E29: 081025 | F29: 7700 | G29: 44 | H29: Пурпе | I29: отгружен | J29: 45939 | K29: Ивеко С 669 УК 56 | L29: 89878985273 | M29: Яновский Сергей Александрович | Q29: =F29 -> 7700 | R29: + | S29: 255000 | T29: =S29*F29/1000 -> 1963500
A30: авто (АРИАЛ) | B30: Спец№93К(2-6) | C30: ОМАС | D30: ТЕРРАПАН - бум 25,0 кг | E30: 10/2025 | F30: 10000 | G30: 400 | H30: Пыть-Ях | I30: отгружен | J30: 45940 | K30: ДАФ К562УА-32 | L30: 89051761114 | M30: Антошин Андрей Иванович | P30: =F30 -> 10000 | R30: + | S30: 250000 | T30: =S30*F30/1000 -> 2500000
A31: авто (АРИАЛ) | B31: Спец№93К(2-6) | C31: ОМАС | D31: Сульф асф - бум 25,0 кг | E31: 03/2025 | F31: 10000 | G31: 400 | H31: Пыть-Ях | I31: отгружен | J31: 45940 | K31: ДАФ К562УА-32 | L31: 89051761114 | M31: Антошин Андрей Иванович | O31: =F31 -> 10000 | R31: + | S31: 44500 | T31: =S31*F31/1000 -> 445000
A32: авто (АГРО) | B32: Спец№91К | C32: ОМАС | D32: Сульф асф - бум 25,0 кг | E32: 03/2025 | F32: 15000 | G32: 600 | H32: Нижневартовск | I32: отгружен | J32: 45940 | K32: КАМАЗ Х293 РХ 790 | L32: 89325440767 | M32: Сабитов Ильдар Энварьевич | O32: =F32 -> 15000 | R32: + | S32: 44500 | T32: =S32*F32/1000 -> 667500
A33: авто (АГРО) | B33: Спец№91К | C33: ОМАС | D33: СУПЕРСЛАЙДЕР ГОЛД - 200 кг п/эт | E33: 230425 | F33: 5600 | G33: 28 | H33: Нижневартовск | I33: отгружен | J33: 45940 | K33: КАМАЗ Х293 РХ 790 | L33: 89325440767 | M33: Сабитов Ильдар Энварьевич | Q33: =F33 -> 5600 | R33: + | S33: 105000 | T33: =S33*F33/1000 -> 588000
A34: кнт(Самовывоз) | B34: БС-114257(1-2) | C34: БурСервис | D34: BURFLC - бум 25,0 кг | E34: 290925/1 | F34: 4375 | G34: 175 | H34: Пурпе | I34: отгружен | J34: 45943 | N34: TKRU3181340 | O34: 4375 | R34: + | S34: 41000 | T34: =S34*F34/1000 -> 179375
A35: кнт(Самовывоз) | B35: БС-114257(1-2) | C35: БурСервис | D35: BURFLC - бум 25,0 кг | E35: 290925/2 | F35: 4375 | G35: 175 | H35: Пурпе | I35: отгружен | J35: 45943 | N35: TKRU3181340 | O35: 4375 | R35: + | S35: 41000 | T35: =S35*F35/1000 -> 179375
A36: кнт(Самовывоз) | B36: БС-114257(1-2) | C36: БурСервис | D36: BURFLC - бум 25,0 кг | E36: 290925/3 | F36: 4375 | G36: 175 | H36: Пурпе | I36: отгружен | J36: 45943 | N36: TKRU3181340 | O36: 4375 | R36: + | S36: 41000 | T36: =S36*F36/1000 -> 179375
A37: кнт(Самовывоз) | B37: БС-114257(1-2) | C37: БурСервис | D37: BURFLC - бум 25,0 кг | E37: 290925/4 | F37: 4375 | G37: 175 | H37: Пурпе | I37: отгружен | J37: 45943 | N37: TKRU3181340 | O37: 4375 | R37: + | S37: 41000 | T37: =S37*F37/1000 -> 179375
A38: кнт(Самовывоз) | B38: БС-114257(2-2) | C38: БурСервис | D38: BURFLC - бум 25,0 кг | E38: 300925/1 | F38: 4375 | G38: 175 | H38: Пурпе | I38: отгружен | J38: 45943 | N38: TKRU3219907 | O38: 4375 | R38: + | S38: 41000 | T38: =S38*F38/1000 -> 179375
A39: кнт(Самовывоз) | B39: БС-114257(2-2) | C39: БурСервис | D39: BURFLC - бум 25,0 кг | E39: 300925/2 | F39: 4375 | G39: 175 | H39: Пурпе | I39: отгружен | J39: 45943 | N39: TKRU3219907 | O39: 4375 | R39: + | S39: 41000 | T39: =S39*F39/1000 -> 179375
A40: кнт(Самовывоз) | B40: БС-114257(2-2) | C40: БурСервис | D40: BURFLC - бум 25,0 кг | E40: 300925/3 | F40: 4375 | G40: 175 | H40: Пурпе | I40: отгружен | J40: 45943 | N40: TKRU3219907 | O40: 4375 | R40: + | S40: 41000 | T40: =S40*F40/1000 -> 179375
A41: кнт(Самовывоз) | B41: БС-114257(2-2) | C41: БурСервис | D41: BURFLC - бум 25,0 кг | E41: 300925/4 | F41: 4375 | G41: 175 | H41: Пурпе | I41: отгружен | J41: 45943 | N41: TKRU3219907 | O41: 4375 | R41: + | S41: 41000 | T41: =S41*F41/1000 -> 179375
...

Sheet сентябрь 2025
B1: ОТГРУЗКИ ПРОДУКЦИИ | C1: 45901
A2: заметки | B2: НОМЕР ЗАКАЗА | C2: КЛИЕНТ | D2: ПРОДУКТ | E2: ПАРТИЯ | F2: КОЛИЧЕСТВО | H2: ПУНКТ НАЗНАЧЕНИЯ | I2: СТАТУС | J2: ДАТА ОТГРУЗКИ | K2: АВТОДОСТАВКА | N2: ЖД ДОСТАВКА | O2: ИТОГО ОТГРУЖЕНО | R2: АКТЫ | S2: Цена со склада за 1 тонну
F3: КГ | G3: мешков/бочек | K3: № АВТО | L3: ТЕЛ. ВОДИТЕЛЯ | M3: ВОДИТЕЛЬ | N3: № КОНТЕЙНЕРА/ВАГОНА | O3: ЧП | P3: ИНАЯ | Q3: Жидкий | T3: Итого
A5: авто(АГЛ) | B5: БС-111582(3-5) | C5: БурСервис | D5: BURFLC - бум 25,0 кг | E5: 140825/2 | F5: 1750 | G5: 70 | H5: Пыть-Ях | I5: отгружен | J5: 45901 | K5: Вольво Р 034 СВ 29 | L5: 89212974613 | M5: Киреев Сергей | O5: 1750 | R5: + | S5: 41000 | T5: =S5*(F5/1000) -> 71750
A6: авто(АГЛ) | B6: БС-111582(3-5) | C6: БурСервис | D6: BURFLC - бум 25,0 кг | E6: 140825/3 | F6: 4375 | G6: 175 | H6: Пыть-Ях | I6: отгружен | J6: 45901 | K6: Вольво Р 034 СВ 29 | L6: 89212974613 | M6: Киреев Сергей | O6: 4375 | R6: + | S6: 41000 | T6: =S6*(F6/1000) -> 179375
A7: авто(АГЛ) | B7: БС-111582(3-5) | C7: БурСервис | D7: BURFLC - бум 25,0 кг | E7: 140825/4 | F7: 4375 | G7: 175 | H7: Пыть-Ях | I7: отгружен | J7: 45901 | K7: Вольво Р 034 СВ 29 | L7: 89212974613 | M7: Киреев Сергей | O7: 4375 | R7: + | S7: 41000 | T7: =S7*(F7/1000) -> 179375
A8: авто(АГЛ) | B8: БС-111582(3-5) | C8: БурСервис | D8: BURFLC - бум 25,0 кг | E8: 150825/1 | F8: 4375 | G8: 175 | H8: Пыть-Ях | I8: отгружен | J8: 45901 | K8: Вольво Р 034 СВ 29 | L8: 89212974613 | M8: Киреев Сергей | O8: 4375 | R8: + | S8: 41000 | T8: =S8*(F8/1000) -> 179375
A9: авто(АГЛ) | B9: БС-111582(3-5) | C9: БурСервис | D9: BURFLC - бум 25,0 кг | E9: 150825/2 | F9: 4375 | G9: 175 | H9: Пыть-Ях | I9: отгружен | J9: 45901 | K9: Вольво Р 034 СВ 29 | L9: 89212974613 | M9: Киреев Сергей | O9: 4375 | R9: + | S9: 41000 | T9: =S9*(F9/1000) -> 179375
A10: авто(АГЛ) | B10: БС-111582(3-5) | C10: БурСервис | D10: BURFLC - бум 25,0 кг | E10: 150825/3 | F10: 1750 | G10: 70 | H10: Пыть-Ях | I10: отгружен | J10: 45901 | K10: Вольво Р 034 СВ 29 | L10: 89212974613 | M10: Киреев Сергей | O10: 1750 | R10: + | S10: 41000 | T10: =S10*(F10/1000) -> 71750
A11: авто(Ариал) | B11: Спец№152(3-7) | C11: Акрос | D11: Drilling Lube (СС РУО) - 200 кг п/эт | E11: 260825 | F11: 17600 | G11: 88 | H11: Мурманск | I11: отгружен | J11: 45901 | K11: ВОЛЬВО Х 933 КО 52 | L11: 89200569667 | M11: Воинов Леонид | Q11: 17600 | R11: + | S11: 369000 | T11: =S11*(F11/1000) -> 6494400
A12: авто(Ариал) | B12: Спец№152(4-7) | C12: Акрос | D12: Drilling Lube (СС РУО) - 200 кг п/эт | E12: 280825 | F12: 17600 | G12: 88 | H12: Мурманск | I12: отгружен | J12: 45902 | K12: МАН М 884 ОЕ 35 | L12: 89211459714 | M12: Лучкин Евгений | Q12: 17600 | R12: + | S12: 369000 | T12: =S12*(F12/1000) -> 6494400
A13: авто(Агро) | B13: БС-111582(4-5) | C13: БурСервис | D13: BURFLC - бум 25,0 кг | E13: 150825/3 | F13: 2625 | G13: 105 | H13: Пыть-Ях | I13: отгружен | J13: 45902 | K13: Камаз В 139 РХ 790 | L13: 89162954327 | M13: Матушкин Анатолий | O13: 2625 | R13: + | S13: 41000 | T13: =S13*(F13/1000) -> 107625
A14: авто(Агро) | B14: БС-111582(4-5) | C14: БурСервис | D14: BURFLC - бум 25,0 кг | E14: 150825/4 | F14: 4375 | G14: 175 | H14: Пыть-Ях | I14: отгружен | J14: 45902 | K14: Камаз В 139 РХ 790 | L14: 89162954327 | M14: Матушкин Анатолий | O14: 4375 | R14: + | S14: 41000 | T14: =S14*(F14/1000) -> 179375
A15: авто(Агро) | B15: БС-111582(4-5) | C15: БурСервис | D15: BURFLC - бум 25,0 кг | E15: 160825/1 | F15: 4375 | G15: 175 | H15: Пыть-Ях | I15: отгружен | J15: 45902 | K15: Камаз В 139 РХ 790 | L15: 89162954327 | M15: Матушкин Анатолий | O15: 4375 | R15: + | S15: 41000 | T15: =S15*(F15/1000) -> 179375
A16: авто(Агро) | B16: БС-111582(4-5) | C16: БурСервис | D16: BURFLC - бум 25,0 кг | E16: 160825/2 | F16: 4375 | G16: 175 | H16: Пыть-Ях | I16: отгружен | J16: 45902 | K16: Камаз В 139 РХ 790 | L16: 89162954327 | M16: Матушкин Анатолий | O16: 4375 | R16: + | S16: 41000 | T16: =S16*(F16/1000) -> 179375
A17: авто(Агро) | B17: БС-111582(4-5) | C17: БурСервис | D17: BURFLC - бум 25,0 кг | E17: 160825/3 | F17: 4375 | G17: 175 | H17: Пыть-Ях | I17: отгружен | J17: 45902 | K17: Камаз В 139 РХ 790 | L17: 89162954327 | M17: Матушкин Анатолий | O17: 4375 | R17: + | S17: 41000 | T17: =S17*(F17/1000) -> 179375
A18: авто(Агро) | B18: БС-111582(4-5) | C18: БурСервис | D18: BURFLC - бум 25,0 кг | E18: 160825/4 | F18: 875 | G18: 35 | H18: Пыть-Ях | I18: отгружен | J18: 45902 | K18: Камаз В 139 РХ 790 | L18: 89162954327 | M18: Матушкин Анатолий | O18: 875 | R18: + | S18: 41000 | T18: =S18*(F18/1000) -> 35875
A19: авто(Авто 45) | B19: Спец№153 | C19: Акрос | D19: BLACKTROL ж - 215,5 кг п/эт | E19: 200825 | F19: 18964 | G19: 88 | H19: Ноябрьск | I19: отгружен | J19: 45902 | K19: DAF К 298 МО 45 | L19: 89080063420 | M19: Антонов Евгений | Q19: 18964 | R19: + | S19: 89000 | T19: =S19*(F19/1000) -> 1687796
A20: авто(Ариал) | B20: БС-111582(5-5) | C20: БурСервис | D20: EZ-MUD DP (Поликап) - бум 25,0 кг | E20: 020925 | F20: 17500 | G20: 700 | H20: Пыть-Ях | I20: отгружен | J20: 45905 | K20: МАЗ М 508 ОХ 196 | L20: 89220214604 | M20: Быков Алексей | P20: 17500 | R20: + | S20: 265000 | T20: =S20*(F20/1000) -> 4637500
A21: авто(Ариал) | B21: БС-111582(5-5) | C21: БурСервис | D21: BURFLC - бум 25,0 кг | E21: 160825/4 | F21: 3500 | G21: 140 | H21: Пыть-Ях | I21: отгружен | J21: 45905 | K21: МАЗ М 508 ОХ 196 | L21: 89220214604 | M21: Быков Алексей | O21: 3500 | R21: + | S21: 41000 | T21: =S21*(F21/1000) -> 143500
A22: авто(Ариал) | B22: Спец№85К(1-2) | C22: Омас | D22: СУПЕРСЛАЙДЕР ГОЛД - 200 кг п/эт | E22: 230425 | F22: 4000 | G22: 20 | H22: Пыть-Ях | I22: отгружен | J22: 45905 | K22: ДАФ Т 428 УК 750 | L22: 89123368550 | M22: Пушкарев Виктор | Q22: 4000 | R22: + | S22: 105000 | T22: =S22*(F22/1000) -> 420000
A23: авто(Ариал) | B23: Спец№85К(1-2) | C23: Омас | D23: ТЕРРАПАН - бум 25,0 кг | E23: 12/2024 | F23: 8000 | G23: 320 | H23: Пыть-Ях | I23: отгружен | J23: 45905 | K23: ДАФ Т 428 УК 750 | L23: 89123368550 | M23: Пушкарев Виктор | P23: 8000 | R23: + | S23: 250000 | T23: =S23*(F23/1000) -> 2000000
A24: авто(Ариал) | B24: Спец№85К(1-2) | C24: Омас | D24: Сульф асф - п/проп обезл 25,0 кг | E24: 03/2025 | F24: 8000 | G24: 320 | H24: Пыть-Ях | I24: отгружен | J24: 45905 | K24: ДАФ Т 428 УК 750 | L24: 89123368550 | M24: Пушкарев Виктор | O24: 8000 | R24: + | S24: 43500 | T24: =S24*(F24/1000) -> 348000
A25: авто(Агро) | B25: Спец№78К (3-3) | C25: Омас | D25: Сульф асф - п/проп обезл 25,0 кг | E25: 03/2025 | F25: 20000 | G25: 800 | H25: Пыть-Ях | I25: отгружен | J25: 45908 | K25: МАЗ Н 99 5ЕО 72 | L25: 89220464746 | M25: Кузнецов Андрей | O25: 20000 | R25: + | S25: 43500 | T25: =S25*(F25/1000) -> 870000
A26: авто(Ариал) | B26: Спец№82К(1-3) | C26: Омас | D26: Сульф асф - п/проп обезл 25,0 кг | E26: 03/2025 | F26: 20000 | G26: 800 | H26: Пыть-Ях | I26: отгружен | J26: 45908 | K26: Скания В 050 КА 156 | L26: 89198650586 | M26: Шатун Евгений | O26: 20000 | R26: + | S26: 43500 | T26: =S26*(F26/1000) -> 870000
A27: авто(Агро) | B27: Спец№86К | C27: Омас | D27: СУПЕРСЛАЙДЕР ГОЛД - 200 кг п/эт | E27: 230425 | F27: 12000 | G27: 60 | H27: Бузулук | I27: отгружен | J27: 45908 | K27: FOTON AUMAN М 149 ХТ 702 | L27: 89374798860 | M27: Биккинин Эльвир | Q27: 12000 | R27: + | S27: 105000 | T27: =S27*(F27/1000) -> 1260000
A28: авто(Агро) | B28: Спец№86К | C28: Омас | D28: КЛСП - бум 20,0 кг | E28: 150425 | F28: 8000 | G28: 400 | H28: Бузулук | I28: отгружен | J28: 45908 | K28: FOTON AUMAN М 149 ХТ 702 | L28: 89374798860 | M28: Биккинин Эльвир | P28: 8000 | R28: + | S28: 87000 | T28: =S28*(F28/1000) -> 696000
A29: авто(Бакин) | B29: Спец№82К(2-3) | C29: Омас | D29: Сульф асф - п/проп обезл 25,0 кг | E29: 03/2025 | F29: 20000 | G29: 800 | H29: Пыть-Ях | I29: отгружен | J29: 45909 | K29: Вольво О 618 СМ 29 | L29: 89115713730 | M29: Фокин Дмитрий | O29: 20000 | R29: + | S29: 43500 | T29: =S29*(F29/1000) -> 870000
A30: авто(Инкам) | B30: Спец№82К(3-3) | C30: Омас | D30: Сульф асф - п/проп обезл 25,0 кг | E30: 03/2025 | F30: 20000 | G30: 800 | H30: Пыть-Ях | I30: отгружен | J30: 45909 | K30: DAF О539ОН29/DAF К008МА29 | L30: 89216700606/89116825992 | M30: Хрущ/Белоцерковский | O30: 20000 | R30: + | S30: 43500 | T30: =S30*(F30/1000) -> 870000
A31: авто(Агро) | B31: Спец№87К | C31: Омас | D31: Сульф асф - п/проп обезл 25,0 кг | E31: 03/2025 | F31: 11000 | G31: 440 | H31: Нижевартовск | I31: отгружен | J31: 45909 | K31: KENWORTH У 181 ЕЕ 142 | L31: 89234704019 | M31: Заика Николай | O31: 11000 | R31: + | S31: 43500 | T31: =S31*(F31/1000) -> 478500
A32: авто(Агро) | B32: Спец№87К | C32: Омас | D32: СУПЕРСЛАЙДЕР ГОЛД - 200 кг п/эт | E32: 230425 | F32: 8000 | G32: 40 | H32: Нижевартовск | I32: отгружен | J32: 45909 | K32: KENWORTH У 181 ЕЕ 142 | L32: 89234704019 | M32: Заика Николай | Q32: 8000 | R32: + | S32: 105000 | T32: =S32*(F32/1000) -> 840000
A33: кнт | B33: Спец№5(1-3) | C33: ИНК-Сервис | D33: Стабилайт II - бум марк 25,0 кг | E33: 270825 | F33: 17500 | G33: 700 | H33: Усть-Кут | I33: отгружен | J33: 45909 | M33: ЗПУ Клещ 60СЦ номер В5654303 | N33: GQRU3142153 | O33: 17500 | R33: + | S33: 39000 | T33: =S33*(F33/1000) -> 682500
A34: кнт | B34: Спец№5(2-3) | C34: ИНК-Сервис | D34: Стабилайт II - бум марк 25,0 кг | E34: 280825 | F34: 17500 | G34: 700 | H34: Усть-Кут | I34: отгружен | J34: 45909 | M34: ЗПУ Клещ 60СЦ номер В5654304 | N34: TKRU3034457 | O34: 17500 | R34: + | S34: 39000 | T34: =S34*(F34/1000) -> 682500
A35: кнт(БС) | B35: БС-111914 | C35: БурСервис | D35: TORQ TRIM II PLUS (СС Голд) - 185 кг п/эт | E35: 010925 | F35: 14800 | G35: 80 | H35: Пурпе | I35: отгружен | J35: 45910 | K35: Ман О 531 НТ 29 | L35: 89212430941 | M35: Пепельницын Алексей | N35: TKRU3127539 | Q35: 14800 | R35: + | S35: 125000 | T35: =S35*(F35/1000) -> 1850000
A36: авто(Ариал) | B36: Спец№85К(2-2) | C36: Омас | D36: ТЕРРАПАН - бум 25,0 кг | E36: 12/2024 | F36: 8000 | G36: 320 | H36: Пыть-Ях | I36: отгружен | J36: 45911 | K36: Камаз В 102 РХ 790 | L36: 89226266773 | M36: Севергин Александр | P36: 8000 | R36: + | S36: 250000 | T36: =S36*(F36/1000) -> 2000000
A37: авто(Ариал) | B37: Спец№85К(2-2) | C37: Омас | D37: Сульф асф - п/проп обезл 25,0 кг | E37: 03/2025 | F37: 2000 | G37: 80 | H37: Пыть-Ях | I37: отгружен | J37: 45911 | K37: Камаз В 102 РХ 790 | L37: 89226266773 | M37: Севергин Александр | O37: 2000 | R37: + | S37: 43500 | T37: =S37*(F37/1000) -> 87000
A38: авто(Ариал) | B38: Спец№88К | C38: Омас | D38: ТЕРРАПАН - бум 25,0 кг | E38: 12/2024 | F38: 10000 | G38: 400 | H38: Пыть-Ях | I38: отгружен | J38: 45911 | K38: Камаз В 102 РХ 790 | L38: 89226266773 | M38: Севергин Александр | P38: 10000 | R38: + | S38: 250000 | T38: =S38*(F38/1000) -> 2500000
A39: авто(Бакин) | B39: Спец№53(1-5) | C39: Инко-Сервис | D39: Сульф асф - бум 25,0 кг | E39: 20250829 | F39: 21000 | G39: 840 | H39: Демьянка | I39: отгружен | J39: 45912 | K39: Вольво О 856 УЕ 29 | L39: 89216004800 | M39: Рядовкин Евгений | O39: 21000 | R39: + | S39: 45000 | T39: =S39*(F39/1000) -> 945000
A40: авто(Ариал) | B40: Спец№53(2-5) | C40: Инко-Сервис | D40: Сульф асф - бум 25,0 кг | E40: 20250829 | F40: 21000 | G40: 840 | H40: Демьянка | I40: отгружен | J40: 45912 | K40: Скания У 580 ВР 48 | L40: 89802610619/89802643561 | M40: Малютин Виктор | O40: 21000 | R40: + | S40: 45000 | T40: =S40*(F40/1000) -> 945000
A41: авто(Клото) | B41: Спец№53(3-5) | C41: Инко-Сервис | D41: Сульф асф - бум 25,0 кг | E41: 20250829 | F41: 21000 | G41: 840 | H41: Демьянка | I41: отгружен | J41: 45915 | K41: Mercedes О 515 ОУ 29 | L41: 89539399073/89115800204 | M41: Борисов Дмитрий | O41: 21000 | R41: + | S41: 45000 | T41: =S41*(F41/1000) -> 945000
...

Sheet август 2025
B1: ОТГРУЗКИ ПРОДУКЦИИ | C1: 45870
A2: заметки | B2: НОМЕР ЗАКАЗА | C2: КЛИЕНТ | D2: ПРОДУКТ | E2: ПАРТИЯ | F2: КОЛИЧЕСТВО | H2: ПУНКТ НАЗНАЧЕНИЯ | I2: СТАТУС | J2: ДАТА ОТГРУЗКИ | K2: АВТОДОСТАВКА | N2: ЖД ДОСТАВКА | O2: ИТОГО ОТГРУЖЕНО | R2: АКТЫ | S2: Цена со склада за 1 тонну
F3: КГ | G3: мешков/бочек | K3: № АВТО | L3: ТЕЛ. ВОДИТЕЛЯ | M3: ВОДИТЕЛЬ | N3: № КОНТЕЙНЕРА/ВАГОНА | O3: ЧП | P3: ИНАЯ | Q3: Жидкий | T3: Итого
A5: авто(Ванюхин) | B5: Спец№20(1-2) | C5: КазПетроДриллинг | D5: Стабилайт II - бум 25,0 кг | E5: 120625 | F5: 20000 | G5: 800 | H5: Жанаозен | I5: отгружен | J5: 45870 | K5: Volvo Т 681 MP 67 | L5: 89608185086/87777918885 | M5: Ащегулов Семён | O5: 20000 | R5: + | S5: 45000 | T5: =S5*(F5/1000) -> 900000
A6: авто(Ариал) | B6: БС-101657(6-8) | C6: БурСервис | D6: BURFLC - бум 25,0 кг | E6: 270525 | F6: 20125 | G6: 805 | H6: Пыть-Ях | I6: отгружен | J6: 45870 | K6: МАЗ Н 995 ЕО 72 | L6: 89220464746 | M6: Кузнецов Андрей | O6: 20125 | R6: + | S6: 41000 | T6: =S6*(F6/1000) -> 825125
A7: авто(Инкам) | B7: БС-101657(7-8) | C7: БурСервис | D7: BURFLC - бум 25,0 кг | E7: 290525 | F7: 20125 | G7: 805 | H7: Пыть-Ях | I7: отгружен | J7: 45870 | K7: DAF К 008 МА 29 | L7: 89116825992 | M7: Белоцерковский Алексей | O7: 20125 | R7: + | S7: 41000 | T7: =S7*(F7/1000) -> 825125
A8: авто(Агро) | B8: Спец№51 | C8: Инко-Сервис | D8: Стабилайт II - бум марк 25,0 кг | E8: 220725 | F8: 20000 | G8: 800 | H8: Новосемейкино | I8: отгружен | J8: 45870 | K8: FAW У 769 ЕА 152 | L8: 89601818667 | M8: Курапов Дмитрий | O8: 20000 | R8: + | S8: 45000 | T8: =S8*(F8/1000) -> 900000
A9: авто(Авто 45) | B9: БС-102928(2-3) | C9: БурСервис | D9: BURFLC - бум 25,0 кг | E9: 020625 | F9: 20125 | G9: 805 | H9: Пыть-Ях | I9: отгружен | J9: 45873 | K9: КАМАЗ О 773 НМ 45 | L9: 89195697888 | M9: Шмаков Александр | O9: 20125 | R9: + | S9: 41000 | T9: =S9*(F9/1000) -> 825125
A10: авто(ИП Семенова) | B10: БС-102928(3-3) | C10: БурСервис | D10: BURFLC - бум 25,0 кг | E10: 050625 | F10: 20125 | G10: 805 | H10: Пыть-Ях | I10: отгружен | J10: 45873 | K10: DAF У 377 МХ 45 | L10: 89195966929 | M10: Ильин Андрей | O10: 20125 | R10: + | S10: 41000 | T10: =S10*(F10/1000) -> 825125
A11: авто(Ванюхин) | B11: Спец№20(2-2) | C11: КазПетроДриллинг | D11: Стабилайт II - бум 25,0 кг | E11: 190625 | F11: 20000 | G11: 800 | H11: Жанаозен | I11: отгружен | J11: 45874 | K11: DAF У 690 РК 790 | L11: 89273817812/87773777323 | M11: Портнов Дмитрий | O11: 20000 | R11: + | S11: 45000 | T11: =S11*(F11/1000) -> 900000
A12: кнт | B12: БС-108150(1-3) | C12: БурСервис | D12: BURFLC - бум 25,0 кг | E12: 010825/1 | F12: 4375 | G12: 175 | H12: Пурпе | I12: отгружен | J12: 45876 | N12: TKRU3440733 | O12: 4375 | R12: + | S12: 41000 | T12: =S12*(F12/1000) -> 179375
A13: кнт | B13: БС-108150(1-3) | C13: БурСервис | D13: BURFLC - бум 25,0 кг | E13: 010825/2 | F13: 4375 | G13: 175 | H13: Пурпе | I13: отгружен | J13: 45876 | N13: TKRU3440733 | O13: 4375 | R13: + | S13: 41000 | T13: =S13*(F13/1000) -> 179375
A14: кнт | B14: БС-108150(1-3) | C14: БурСервис | D14: BURFLC - бум 25,0 кг | E14: 010825/3 | F14: 4375 | G14: 175 | H14: Пурпе | I14: отгружен | J14: 45876 | N14: TKRU3440733 | O14: 4375 | R14: + | S14: 41000 | T14: =S14*(F14/1000) -> 179375
A15: кнт | B15: БС-108150(1-3) | C15: БурСервис | D15: BURFLC - бум 25,0 кг | E15: 010825/4 | F15: 4375 | G15: 175 | H15: Пурпе | I15: отгружен | J15: 45876 | N15: TKRU3440733 | O15: 4375 | R15: + | S15: 41000 | T15: =S15*(F15/1000) -> 179375
A16: кнт | B16: БС-108150(2-3) | C16: БурСервис | D16: BURFLC - бум 25,0 кг | E16: 020825/1 | F16: 4375 | G16: 175 | H16: Пурпе | I16: отгружен | J16: 45876 | N16: TKRU3056836 | O16: 4375 | R16: + | S16: 41000 | T16: =S16*(F16/1000) -> 179375
A17: кнт | B17: БС-108150(2-3) | C17: БурСервис | D17: BURFLC - бум 25,0 кг | E17: 020825/2 | F17: 4375 | G17: 175 | H17: Пурпе | I17: отгружен | J17: 45876 | N17: TKRU3056836 | O17: 4375 | R17: + | S17: 41000 | T17: =S17*(F17/1000) -> 179375
A18: кнт | B18: БС-108150(2-3) | C18: БурСервис | D18: BURFLC - бум 25,0 кг | E18: 020825/3 | F18: 4375 | G18: 175 | H18: Пурпе | I18: отгружен | J18: 45876 | N18: TKRU3056836 | O18: 4375 | R18: + | S18: 41000 | T18: =S18*(F18/1000) -> 179375
A19: кнт | B19: БС-108150(2-3) | C19: БурСервис | D19: BURFLC - бум 25,0 кг | E19: 020825/4 | F19: 4375 | G19: 175 | H19: Пурпе | I19: отгружен | J19: 45876 | N19: TKRU3056836 | O19: 4375 | R19: + | S19: 41000 | T19: =S19*(F19/1000) -> 179375
A20: авто(Ванюхин) | B20: Спец№21(2-2) | C20: КазПетроДриллинг | D20: Оптитрол Ж - 200 кг п/эт | E20: 270626 | F20: 17600 | G20: 88 | H20: Жанаозен | I20: отгружен | J20: 45880 | K20: DAF Е 375 AM 198 | L20: 89270908660/87779998937 | M20: Каражан Арман | Q20: 17600 | R20: + | S20: 81500 | T20: =S20*(F20/1000) -> 1434400
A21: авто(Ванюхин) | B21: Спец№21(1-2) | C21: КазПетроДриллинг | D21: Оптитрол Ж - 200 кг п/эт | E21: 200525 | F21: 17600 | G21: 88 | H21: Жанаозен | I21: отгружен | J21: 45880 | K21: DAF У 594 ВА 790 | L21: 89277644533/87789283367 | M21: Суетин Дмитрий | Q21: 17600 | R21: + | S21: 81500 | T21: =S21*(F21/1000) -> 1434400
A22: Самовывоз | B22: Спец№3 | C22: Комар эпокси | D22: СУПЕРСЛАЙДЕР ГОЛД - 200 кг п/эт | E22: 080825 | F22: 6000 | G22: 30 | H22: Самовывоз | I22: отгружен | J22: 45881 | K22: Джак К 194 HM 136 | L22: 89771324621 | M22: Мейзер Игорь | Q22: 6000 | R22: + | S22: 170000 | T22: =S22*(F22/1000) -> 1020000
A23: кнт | B23: БС-109055 | C23: БурСервис | D23: RADIAGREEN RA - 950 кг еврокуб | E23: ОЕ50411003 | F23: 9500 | G23: 10 | H23: Корсаков | I23: отгружен | J23: 45883 | K23: КУРС ЕВРО НА 15.08 93,0588 | N23: GESU1286125 | Q23: 9500 | R23: + | S23: 790348.39 | T23: =S23*(F23/1000) -> 7508309.7
A24: кнт | B24: БС-109055 | C24: БурСервис | D24: RADIAGREEN RA - 950 кг еврокуб | E24: ОЕ50411003 | F24: 9500 | G24: 10 | H24: Корсаков | I24: отгружен | J24: 45883 | K24: КУРС ЕВРО НА 15.08 93,0588 | N24: TCKU3763060 | Q24: 9500 | R24: + | S24: 790348.39 | T24: =S24*(F24/1000) -> 7508309.7
A25: атво(Бакин) | B25: Спец№34 | C25: Энергоресурс | D25: BLACKTROL ж - 200 кг п/эт | E25: 220425 | F25: 6400 | G25: 32 | H25: Пермь | I25: отгружен | J25: 45887 | K25: Вольво О 618 СМ 29 | L25: 89115713730 | M25: Фокин Дмитрий | Q25: =F25 -> 6400 | R25: + | S25: 89900 | T25: =S25*(F25/1000) -> 575360
A26: атво(Бакин) | B26: Спец№34 | C26: Энергоресурс | D26: Стабилайт II - п/проп обезл 22,7 кг | E26: б/п | F26: 13620 | G26: 600 | H26: Пермь | I26: отгружен | J26: 45887 | K26: Вольво О 618 СМ 29 | L26: 89115713730 | M26: Фокин Дмитрий | O26: =F26 -> 13620 | R26: + | S26: 45800 | T26: =S26*(F26/1000) -> 623796
A27: авто(Агро) | B27: Спец№152(1-7) | C27: Акрос | D27: Drilling Lube (СС РУО) - 200 кг п/эт | E27: 120825 | F27: 17600 | G27: 88 | H27: Мурманск | I27: отгружен | J27: 45888 | K27: Ситрак У 674 КУ 716 | L27: 89375266623 | M27: Салимзянов Радик Зифирович | Q27: 17600 | R27: + | S27: 369000 | T27: =S27*(F27/1000) -> 6494400
A28: авто(Ариал) | B28: Спец№152(2-7) | C28: Акрос | D28: Drilling Lube (СС РУО) - 200 кг п/эт | E28: 140825 | F28: 17600 | G28: 88 | H28: Мурманск | I28: отгружен | J28: 45889 | K28: Ситрак Р 751 ЕН 32 | L28: 89532884114, 89506984652 | M28: Павлюченков Геннадий | Q28: 17600 | R28: + | S28: 369000 | T28: =S28*(F28/1000) -> 6494400
A29: авто(Инкам) | B29: БС-111582(1-5) | C29: БурСервис | D29: BURFLC - бум 25,0 кг | E29: 120825/1 | F29: 4375 | G29: 175 | H29: Пыть-Ях | I29: отгружен | J29: 45889 | K29: DAF К 008 МА 29 | L29: 89116825992 | M29: Белоцерковский Алексей | O29: 4375 | R29: + | S29: 41000 | T29: =S29*(F29/1000) -> 179375
A30: авто(Инкам) | B30: БС-111582(1-5) | C30: БурСервис | D30: BURFLC - бум 25,0 кг | E30: 120825/2 | F30: 4375 | G30: 175 | H30: Пыть-Ях | I30: отгружен | J30: 45889 | K30: DAF К 008 МА 29 | L30: 89116825992 | M30: Белоцерковский Алексей | O30: 4375 | R30: + | S30: 41000 | T30: =S30*(F30/1000) -> 179375
A31: авто(Инкам) | B31: БС-111582(1-5) | C31: БурСервис | D31: BURFLC - бум 25,0 кг | E31: 120825/3 | F31: 4375 | G31: 175 | H31: Пыть-Ях | I31: отгружен | J31: 45889 | K31: DAF К 008 МА 29 | L31: 89116825992 | M31: Белоцерковский Алексей | O31: 4375 | R31: + | S31: 41000 | T31: =S31*(F31/1000) -> 179375
A32: авто(Инкам) | B32: БС-111582(1-5) | C32: БурСервис | D32: BURFLC - бум 25,0 кг | E32: 120825/4 | F32: 4375 | G32: 175 | H32: Пыть-Ях | I32: отгружен | J32: 45889 | K32: DAF К 008 МА 29 | L32: 89116825992 | M32: Белоцерковский Алексей | O32: 4375 | R32: + | S32: 41000 | T32: =S32*(F32/1000) -> 179375
A33: авто(Инкам) | B33: БС-111582(1-5) | C33: БурСервис | D33: BURFLC - бум 25,0 кг | E33: 130825/1 | F33: 3500 | G33: 140 | H33: Пыть-Ях | I33: отгружен | J33: 45889 | K33: DAF К 008 МА 29 | L33: 89116825992 | M33: Белоцерковский Алексей | O33: 3500 | R33: + | S33: 41000 | T33: =S33*(F33/1000) -> 143500
A34: авто(Агро) | B34: Спец№52(1-2) | C34: Инко-Сервис | D34: Сульф асф - бум 25,0 кг | E34: 20250808 | F34: 20000 | G34: 800 | H34: Демьянка | I34: отгружен | J34: 45889 | K34: DAF М982АА15 | L34: 89824419561 | M34: Вильгельм Павел | O34: 20000 | R34: + | S34: 45000 | T34: =S34*(F34/1000) -> 900000
A35: авто(Агро) | B35: Спец№52(2-2) | C35: Инко-Сервис | D35: Сульф асф - бум 25,0 кг | E35: 20250808 | F35: 20000 | G35: 800 | H35: Демьянка | I35: отгружен | J35: 45889 | K35: РЕНО Н 451 МС 196 | L35: 89995590766 | M35: Михайлов Денис | O35: 20000 | R35: + | S35: 45000 | T35: =S35*(F35/1000) -> 900000
A36: авто(Авто 45) | B36: Спец№22 | C36: МАДСЕРВИС | D36: Сульф асф - бум 25,0 кг | E36: 050424 | F36: 20000 | G36: 800 | H36: Нижневартовск | I36: отгружен | J36: 45890 | K36: КАМАЗ О773НМ 45 | L36: 89125770562 | M36: Осипов Дмитрий | O36: 20000 | R36: + | S36: 43500 | T36: =S36*(F36/1000) -> 870000
A37: кнт | B37: БС-110580 | C37: БурСервис | D37: EZ-MUD DP (Поликап) - бум 25,0 кг | E37: 080825 | F37: 8750 | G37: 350 | H37: Пурпе | I37: отгружен | J37: 45890 | N37: TKRU3399732 | O37: 8750 | R37: + | S37: 265000 | T37: =S37*(F37/1000) -> 2318750
A38: кнт | B38: БС-108150(3-3) | C38: БурСервис | D38: BURFLC - бум 25,0 кг | E38: 030825/3 | F38: 4375 | G38: 175 | H38: Пурпе | I38: отгружен | J38: 45890 | N38: TKRU3399732 | O38: 4375 | R38: + | S38: 41000 | T38: =S38*(F38/1000) -> 179375
A39: кнт | B39: БС-108150(3-3) | C39: БурСервис | D39: BURFLC - бум 25,0 кг | E39: 030825/4 | F39: 4375 | G39: 175 | H39: Пурпе | I39: отгружен | J39: 45890 | N39: TKRU3399732 | O39: 4375 | R39: + | S39: 41000 | T39: =S39*(F39/1000) -> 179375
A40: кнт | B40: БС-110580 | C40: БурСервис | D40: EZ-MUD DP (Поликап) - бум 25,0 кг | E40: 080825 | F40: 8750 | G40: 350 | H40: Пурпе | I40: отгружен | J40: 45890 | N40: TKRU3407503 | O40: 8750 | R40: + | S40: 265000 | T40: =S40*(F40/1000) -> 2318750
A41: кнт | B41: БС-108150(3-3) | C41: БурСервис | D41: BURFLC - бум 25,0 кг | E41: 030825/1 | F41: 4375 | G41: 175 | H41: Пурпе | I41: отгружен | J41: 45890 | N41: TKRU3407503 | O41: 4375 | R41: + | S41: 41000 | T41: =S41*(F41/1000) -> 179375
...

Sheet июль 2025
B1: ОТГРУЗКИ ПРОДУКЦИИ | C1: 45839
A2: заметки | B2: НОМЕР ЗАКАЗА | C2: КЛИЕНТ | D2: ПРОДУКТ | E2: ПАРТИЯ | F2: КОЛИЧЕСТВО | H2: ПУНКТ НАЗНАЧЕНИЯ | I2: СТАТУС | J2: ДАТА ОТГРУЗКИ | K2: АВТОДОСТАВКА | N2: ЖД ДОСТАВКА | O2: ИТОГО ОТГРУЖЕНО | R2: АКТЫ | S2: Цена со склада за 1 тонну
F3: КГ | G3: мешков/бочек | K3: № АВТО | L3: ТЕЛ. ВОДИТЕЛЯ | M3: ВОДИТЕЛЬ | N3: № КОНТЕЙНЕРА/ВАГОНА | O3: ЧП | P3: ИНАЯ | Q3: Жидкий | T3: Итого
A5: авто(авто 45) | B5: Спец№151 | C5: Акрос | D5: BLACKTROL ж - 215,5 кг п/эт | E5: 260625 | F5: 18964 | G5: 88 | H5: Ноябрьск | I5: отгружен | J5: 45847 | K5: А/М КАМАЗ Х268 НМ 45 | L5: 89822215272 | M5: Бывальцев Денис Михайлович | Q5: =F5 -> 18964 | R5: + | S5: 89000 | T5: =S5*(F5/1000) -> 1687796
A6: авто(Ариал Транс) | B6: Спец№50 | C6: Инко-Сервис | D6: ВЕЛЛТРИТ - 200 кг п/эт | E6: 20250625 | F6: 3200 | G6: 16 | H6: Волгоград | I6: отгружен | J6: 45848 | K6: SCANIA С742АН550 | L6: 79170959670 | M6: Чукалин Сергей Георгиевич | Q6: =F6 -> 3200 | R6: + | S6: 167500 | T6: =S6*(F6/1000) -> 536000
A7: авто(Ариал Транс) | B7: Спец№50 | C7: Инко-Сервис | D7: ЭКСТРАМУЛ-2000 - 200 кг п/эт | E7: 20250627 | F7: 14400 | G7: 72 | H7: Волгоград | I7: отгружен | J7: 45848 | K7: SCANIA С742АН550 | L7: 79170959670 | M7: Чукалин Сергей Георгиевич | Q7: =F7 -> 14400 | R7: + | S7: 128000 | T7: =S7*(F7/1000) -> 1843200
A8: авто(Бакин) | B8: Спец№81К | C8: Омас | D8: Сульф асф - п/проп обезл 25,0 кг | E8: 03/2025 | F8: 10000 | G8: 400 | H8: Нижневартовск | I8: отгружен | J8: 45849 | K8: Вольво О 618 СМ 29 | L8: 89115713730 | M8: Фокин Дмитрий Викторович | O8: =F8 -> 10000 | R8: + | S8: 43500 | T8: =S8*(F8/1000) -> 435000
A9: авто(Бакин) | B9: Спец№81К | C9: Омас | D9: ТЕРРАПАН - бум 25,0 кг | E9: 12/2024 | F9: 10000 | G9: 400 | H9: Нижневартовск | I9: отгружен | J9: 45849 | K9: Вольво О 618 СМ 29 | L9: 89115713730 | M9: Фокин Дмитрий Викторович | P9: =F9 -> 10000 | R9: + | S9: 250000 | T9: =S9*(F9/1000) -> 2500000
A10: деловые линии | B10: Счет №226 | C10: ОХОТСКАЯ ГГК | D10: ШЕЙЛ-ИКС п - бум 25,0 кг | E10: 100725 | F10: 500 | G10: 20 | H10: Хабаровск | I10: отгружен | J10: 45852 | K10: 55334659 | M10: Деловые линии | Q10: =F10 -> 500 | R10: + | S10: 110000 | T10: =S10*(F10/1000) -> 55000
A11: деловые линии | B11: Счет №226 | C11: ОХОТСКАЯ ГГК | D11: BLACKTROL ж - 200 кг мет | E11: 090725 | F11: 600 | G11: 3 | H11: Хабаровск | I11: отгружен | J11: 45852 | K11: 55334659 | M11: Деловые линии | Q11: =F11 -> 600 | R11: + | S11: 89000 | T11: =S11*(F11/1000) -> 53400
A12: Самовывоз | B12: Счет №235 | C12: Прогресс-2 | D12: BLACKTROL ж - 200 кг п/эт | E12: 150725 | F12: 800 | G12: 4 | H12: Отгружено | I12: отгружен | J12: 45860 | K12: Газ М 326 ХА 164 | L12: 89966264435 | M12: Айнахов Евгений | Q12: 800 | R12: + | S12: 111000 | T12: =S12*(F12/1000) -> 88800
A13: авто(Борисов) | B13: Спец№84К | C13: Омас | D13: СУПЕРСЛАЙДЕР ГОЛД - 200 кг п/эт | E13: 230425 | F13: 5600 | G13: 28 | H13: Нижневартовск | I13: отгружен | J13: 45863 | K13: Mercedes О 515 ОУ 29 | L13: 89539399073/89115800204 | M13: Борисов Дмитрий | Q13: 5600 | R13: + | S13: 105000 | T13: =S13*(F13/1000) -> 588000
A14: авто(Борисов) | B14: Спец№84К | C14: Омас | D14: ТЕРРАПАН - бум 25,0 кг | E14: 12/2024 | F14: 14000 | G14: 560 | H14: Нижневартовск | I14: отгружен | J14: 45863 | K14: Mercedes О 515 ОУ 29 | L14: 89539399073/89115800204 | M14: Борисов Дмитрий | P14: 14000 | R14: + | S14: 250000 | T14: =S14*(F14/1000) -> 3500000
A15: авто(Бакин) | B15: Спец№1-СТ | C15: ССК-Технологии | D15: Стабилайт II - п/проп обезл 25,0 кг | E15: 210725 | F15: 20000 | G15: 800 | H15: Демьянка | I15: отгружен | J15: 45866 | K15: Вольво Р 034 СВ 29 | L15: 89212974613 | M15: Киреев Сергей | O15: 20000 | R15: + | S15: 43000 | T15: =S15*(F15/1000) -> 860000
A16: авто(Ванюхин) | B16: Спец№18(2-2) | C16: КазПетроДриллинг | D16: Стабилайт II - бум 25,0 кг | E16: 130525 | F16: 20000 | G16: 800 | H16: Жанаозен | I16: отгружен | J16: 45866 | K16: Mersedes О 119 КУ 790 | L16: 89608340879/87476119403 | M16: Дегтярев Андрей | O16: 20000 | R16: + | S16: 45000 | T16: =S16*(F16/1000) -> 900000
A17: авто(Бакин) | B17: БС-102928(1-3) | C17: БурСервис | D17: BURFLC - бум 25,0 кг | E17: 040625 | F17: 20125 | G17: 805 | H17: Пыть-Ях | I17: отгружен | J17: 45869 | K17: Вольво О 618 СМ 29 | L17: 89115713730 | M17: Фокин Дмитрий | O17: 20125 | R17: + | S17: 41000 | T17: =S17*(F17/1000) -> 825125
