Workbook

Sheet декабрь 2024
B1: ОТГРУЗКИ ПРОДУКЦИИ | C1: 45627
A2: заметки | B2: НОМЕР ЗАКАЗА | C2: КЛИЕНТ | D2: ПРОДУКТ | E2: ПАРТИЯ | F2: КОЛИЧЕСТВО | H2: ПУНКТ НАЗНАЧЕНИЯ | I2: СТАТУС | J2: ДАТА ОТГРУЗКИ | K2: АВТОДОСТАВКА | N2: ЖД ДОСТАВКА | O2: ИТОГО ОТГРУЖЕНО | R2: АКТЫ
F3: КГ | G3: мешков/бочек | K3: № АВТО | L3: ТЕЛ. ВОДИТЕЛЯ | M3: ВОДИТЕЛЬ | N3: № КОНТЕЙНЕРА | O3: ЧП | P3: ИНАЯ | Q3: Жидкий | S3: Цена со склада за 1 тонну | T3: Итого
A5: авто(Агро) | B5: Спец№34 | C5: Буринтех | D5: СУЛЬФОБИТ - бум 25,0 кг | E5: 261124 | F5: 20000 | G5: 800 | H5: Пыть-Ях | I5: отгружено | J5: 45631 | K5: Даф К 358 ВО 53 | L5: 89116036602 | M5: Баринов Владимир | O5: 20000 | R5: + | S5: 41500 | T5: =S5*(F5/1000) -> 830000
A6: авто(Бакин) | B6: спец№38 | C6: ИНКО-Сервис | D6: Сульф асф - бум 25,0 кг | E6: 20241202 | F6: 9000 | G6: 360 | H6: Волгоград | I6: отгружено | J6: 45632 | K6: Вольво С 931 ЕМ 51 | L6: 89212974613 | M6: Киреев Сергей | O6: 9000 | R6: + | S6: 41000 | T6: =S6*(F6/1000) -> 369000
A7: авто(Бакин) | B7: спец№15 | C7: СПС | D7: МАКС-ФЛЕКС - 200 кг мет | E7: 041224 | F7: 10400 | G7: 52 | H7: Волжский | I7: отгружено | J7: 45632 | K7: Вольво С 931 ЕМ 51 | L7: 89212974613 | M7: Киреев Сергей | Q7: 10400 | R7: + | S7: 197000 | T7: =S7*(F7/1000) -> 2048800
A8: автоАриал+Ванюхин) | B8: Спец№15 | C8: КазПетроДриллинг | D8: СУПЕРСЛАЙДЕР ГОЛД - 200 кг п/эт | E8: 051224 | F8: 3200 | G8: 16 | H8: Клото-Пушкино | I8: отгружено | J8: 45632 | K8: Газель У 491 ВС 76 | L8: 89676763153 | M8: Никитин Игорь | Q8: 3200 | R8: + | S8: 130000 | T8: =S8*(F8/1000) -> 416000
A9: автоАриал+Ванюхин) | B9: Ариал+Ванюхин | C9: КазПетроДриллинг | D9: СУПЕРСЛАЙДЕР ГОЛД - 200 кг п/эт | E9: 051224 | H9: Пушкино-Атырау | I9: отгружено | J9: 45635 | K9: Mercedes-Benz О119 КУ 790 | L9: 79608340879/87476119403 | M9: Дегтярев Андрей | O9: 0 | P9: 0 | Q9: 0 | R9: + | T9: =S9*(F9/1000) -> 0
A10: авто(ГК Урал) | B10: Спец№25 | C10: ЭКО ФЛУИДЗ | D10: Сульф асф - бум 25,0 кг | E10: 050424 | F10: 18000 | G10: 720 | H10: Нижневартовсск | I10: отгружено | J10: 45632 | K10: РЕНО Р 085 ЕХ 154 | L10: 89132514085 | M10: Баянов Николай | O10: 18000 | R10: + | S10: 43500 | T10: =S10*(F10/1000) -> 783000
A11: авто(ГК Урал) | B11: Спец№25 | C11: ЭКО ФЛУИДЗ | D11: СУПЕРСЛАЙДЕР ГОЛД - 200 кг п/эт | E11: 180424 | F11: 2400 | G11: 12 | H11: Нижневартовсск | I11: отгружено | J11: 45632 | K11: РЕНО Р 085 ЕХ 154 | L11: 89132514085 | M11: Баянов Николай | Q11: 2400 | R11: + | S11: 105000 | T11: =S11*(F11/1000) -> 252000
A12: авто(ГК Урал) | B12: Спец№37 (3-5) | C12: Химпром | D12: ТЕРРАПАН - бум 25,0 кг | E12: 329/10 | F12: 5000 | G12: 200 | H12: Краснокамск | I12: отгружено | J12: 45632 | K12: Камаз Н 212 ТВ 35 | L12: 89115193078 | M12: Добрынин Александр | N12: 5824,5825,5966,5967,5968 | P12: 5000 | R12: + | S12: 250000 | T12: =S12*(F12/1000) -> 1250000
A13: авто(ГК Урал) | B13: Спец№37 (3-5) | C13: Химпром | D13: ТЕРРАПАН - бум 25,0 кг | E13: 329/11 | F13: 5000 | G13: 200 | H13: Краснокамск | I13: отгружено | J13: 45632 | K13: Камаз Н 212 ТВ 35 | L13: 89115193078 | M13: Добрынин Александр | N13: 5969,5970,5971,5972,5973 | P13: 5000 | R13: + | S13: 250000 | T13: =S13*(F13/1000) -> 1250000
A14: авто(ГК Урал) | B14: Спец№37 (3-5) | C14: Химпром | D14: ТЕРРАПАН - бум 25,0 кг | E14: 329/12 | F14: 5000 | G14: 200 | H14: Краснокамск | I14: отгружено | J14: 45632 | K14: Камаз Н 212 ТВ 35 | L14: 89115193078 | M14: Добрынин Александр | N14: 5974,5975,5976,5977,5978 | P14: 5000 | R14: + | S14: 250000 | T14: =S14*(F14/1000) -> 1250000
A15: авто(ГК Урал) | B15: Спец№37 (3-5) | C15: Химпром | D15: ТЕРРАПАН - бум 25,0 кг | E15: 329/13 | F15: 1000 | G15: 40 | H15: Краснокамск | I15: отгружено | J15: 45632 | K15: Камаз Н 212 ТВ 35 | L15: 89115193078 | M15: Добрынин Александр | N15: 5979 | P15: 1000 | R15: + | S15: 250000 | T15: =S15*(F15/1000) -> 250000
A16: авто(ГК Урал) | B16: Спец№37 (3-5) | C16: Химпром | D16: ТЕРРАПАН - бум 25,0 кг | E16: 329/25 | F16: 1000 | G16: 40 | H16: Краснокамск | I16: отгружено | J16: 45632 | K16: Камаз Н 212 ТВ 35 | L16: 89115193078 | M16: Добрынин Александр | N16: 5693 | P16: 1000 | R16: + | S16: 250000 | T16: =S16*(F16/1000) -> 250000
A17: авто(ГК Урал) | B17: Спец№37 (3-5) | C17: Химпром | D17: ТЕРРАПАН - бум 25,0 кг | E17: 329/26 | F17: 2000 | G17: 80 | H17: Краснокамск | I17: отгружено | J17: 45632 | K17: Камаз Н 212 ТВ 35 | L17: 89115193078 | M17: Добрынин Александр | N17: 5711, 5712 | P17: 2000 | R17: + | S17: 250000 | T17: =S17*(F17/1000) -> 500000
A18: авто(ГК Урал) | B18: Спец№37 (3-5) | C18: Химпром | D18: ТЕРРАПАН - бум 25,0 кг | E18: 329/27 | F18: 1000 | G18: 40 | H18: Краснокамск | I18: отгружено | J18: 45632 | K18: Камаз Н 212 ТВ 35 | L18: 89115193078 | M18: Добрынин Александр | N18: 5798 | P18: 1000 | R18: + | S18: 250000 | T18: =S18*(F18/1000) -> 250000
A19: авто(КЛОТО) | B19: Спец№57К | C19: Омас | D19: Сульф асф - п/проп обезл 25,0 кг | E19: 04/2024 | F19: 20000 | G19: 800 | H19: Бузулук | I19: отгружено | J19: 45632 | K19: Mercedes-Benz О 515 ОУ 29 | L19: 8 953 939 90 73 | M19: Борисов Дмитрий | O19: 20000 | R19: + | S19: 43500 | T19: =S19*(F19/1000) -> 870000
A20: конт (самовывоз) | B20: БС-082211(1-3) | C20: БурСервис | D20: BURFLC - бум 25,0 кг | E20: 141124 | F20: 17500 | G20: 700 | H20: Пурпе | I20: отгружено | J20: 45635 | K20: МАН К 733 ТТ 29 | L20: 89815516137 | M20: Чернаков Константин | N20: TKRU3124118 | O20: 17500 | R20: + | S20: 48500 | T20: =S20*(F20/1000) -> 848750
A21: конт (самовывоз) | B21: БС-082211(2-3) | C21: БурСервис | D21: BURFLC - бум 25,0 кг | E21: 161124 | F21: 17500 | G21: 700 | H21: Пурпе | I21: отгружено | J21: 45635 | K21: МАН К 733 ТТ 29 | L21: 89815516137 | M21: Чернаков Константин | N21: TKRU3050910 | O21: 17500 | R21: + | S21: 48500 | T21: =S21*(F21/1000) -> 848750
A22: конт (самовывоз) | B22: БС-082211(3-3) | C22: БурСервис | D22: BURFLC - бум 25,0 кг | E22: 171124 | F22: 17500 | G22: 700 | H22: Пурпе | I22: отгружено | J22: 45635 | K22: Камаз Е 999 СА 29 | L22: 89115583359 | M22: Вайгант Сергей | N22: TKRU3077340 | O22: 17500 | R22: + | S22: 48500 | T22: =S22*(F22/1000) -> 848750
A23: авто(ГК Урал) | B23: Спец№60К | C23: Омас | D23: Сульф асф - п/проп обезл 25,0 кг | E23: 110424 | F23: 20000 | G23: 800 | H23: НЖВ | I23: отгружено | J23: 45635 | K23: Daf М 467 НУ 18 | L23: 89828269847 | M23: Хохряков Сергей | O23: 20000 | R23: + | S23: 43500 | T23: =S23*(F23/1000) -> 870000
A24: авто(Ариал) | B24: Спец№59К | C24: Омас | D24: Сульф асф - п/проп обезл 25,0 кг | E24: 110424 | F24: 14000 | G24: 560 | H24: НЖВ | I24: отгружено | J24: 45636 | K24: FAW О 884 РС 29 | L24: 89021984502 | M24: Бутвин Николай | O24: 14000 | R24: + | S24: 43500 | T24: =S24*(F24/1000) -> 609000
A25: авто(Ариал) | B25: Спец№59К | C25: Омас | D25: СУПЕРСЛАЙДЕР ГОЛД - 200 кг п/эт | E25: 190424 | F25: 5600 | G25: 28 | H25: НЖВ | I25: отгружено | J25: 45636 | K25: FAW О 884 РС 29 | L25: 89021984502 | M25: Бутвин Николай | Q25: 5600 | R25: + | S25: 105000 | T25: =S25*(F25/1000) -> 588000
A26: авто(Агро) | B26: Спец№37 (4-5) | C26: Химпром | D26: ТЕРРАПАН - бум 25,0 кг | E26: 329/13 | F26: 4000 | G26: 160 | H26: Краснокамск | I26: отгружено | J26: 45637 | K26: Шакман Р 313 ВО 154 | L26: 89227142749 | M26: Трубецкой Юрий | N26: 5980,5981,5982,5983 | P26: 4000 | R26: + | S26: 250000 | T26: =S26*(F26/1000) -> 1000000
A27: авто(Агро) | B27: Спец№37 (4-5) | C27: Химпром | D27: ТЕРРАПАН - бум 25,0 кг | E27: 329/14 | F27: 5000 | G27: 200 | H27: Краснокамск | I27: отгружено | J27: 45637 | K27: Шакман Р 313 ВО 154 | L27: 89227142749 | M27: Трубецкой Юрий | N27: 6004,6005,6006,6007,6008 | P27: 5000 | R27: + | S27: 250000 | T27: =S27*(F27/1000) -> 1250000
A28: авто(Агро) | B28: Спец№37 (4-5) | C28: Химпром | D28: ТЕРРАПАН - бум 25,0 кг | E28: 329/15 | F28: 5000 | G28: 200 | H28: Краснокамск | I28: отгружено | J28: 45637 | K28: Шакман Р 313 ВО 154 | L28: 89227142749 | M28: Трубецкой Юрий | N28: 6023,6024,6025,6026,6027 | P28: 5000 | R28: + | S28: 250000 | T28: =S28*(F28/1000) -> 1250000
A29: авто(Агро) | B29: Спец№37 (4-5) | C29: Химпром | D29: ТЕРРАПАН - бум 25,0 кг | E29: 329/16 | F29: 5000 | G29: 200 | H29: Краснокамск | I29: отгружено | J29: 45637 | K29: Шакман Р 313 ВО 154 | L29: 89227142749 | M29: Трубецкой Юрий | N29: 6066,6067,6068,6069,6070 | P29: 5000 | R29: + | S29: 250000 | T29: =S29*(F29/1000) -> 1250000
A30: авто(Агро) | B30: Спец№37 (4-5) | C30: Химпром | D30: ТЕРРАПАН - бум 25,0 кг | E30: 329/17 | F30: 1000 | G30: 40 | H30: Краснокамск | I30: отгружено | J30: 45637 | K30: Шакман Р 313 ВО 154 | L30: 89227142749 | M30: Трубецкой Юрий | N30: 6071 | P30: 1000 | R30: + | S30: 250000 | T30: =S30*(F30/1000) -> 250000
A31: авто(Бакин) | B31: БС-084812(1-2) | C31: БурСервис | D31: BURFLC - бум 25,0 кг | E31: 071224 | F31: 20125 | G31: 805 | H31: Пыть-Ях | I31: отгружено | J31: 45637 | K31: Вольво О 856 УЕ 29 | L31: 89600155752 | M31: Вахтомин Иван | O31: 20125 | R31: + | S31: 48500 | T31: =S31*(F31/1000) -> 976062.5
A32: авто(ГК Урал) | B32: спец№39 | C32: ИНКО-Сервис | D32: ЭКСТРАМУЛ-2000 - 200 кг п/эт | E32: 20241212 | F32: 7200 | G32: 36 | H32: Волгоград | I32: отгружено | J32: 45639 | K32: Вольво О 360 НО 29 | L32: 89214995787 | M32: Попов Вадим | Q32: 7200 | R32: + | S32: 125500 | T32: =S32*(F32/1000) -> 903600
A33: авто(ГК Урал) | B33: спец№16 | C33: СПС | D33: МАКС-ФЛЕКС - 200 кг мет | E33: 041224 | F33: 10400 | G33: 52 | H33: Волжский | I33: отгружено | J33: 45639 | K33: Вольво О 360 НО 29 | L33: 89214995787 | M33: Попов Вадим | Q33: 10400 | R33: + | S33: 197000 | T33: =S33*(F33/1000) -> 2048800
A34: авто | B34: Спец№37 (5-5) | C34: Химпром | D34: ТЕРРАПАН - бум 25,0 кг | E34: 329/17 | F34: 4000 | G34: 160 | H34: Краснокамск | I34: отгружено | J34: 45639 | K34: Скания М 753 РТ 116 | L34: 89225027401 | M34: Емшанов Тимофей | N34: 6072,6073,6074,6075 | P34: 4000 | R34: + | S34: 250000 | T34: =S34*(F34/1000) -> 1000000
A35: авто | B35: Спец№37 (5-5) | C35: Химпром | D35: ТЕРРАПАН - бум 25,0 кг | E35: 329/18 | F35: 5000 | G35: 200 | H35: Краснокамск | I35: отгружено | J35: 45639 | K35: Скания М 753 РТ 116 | L35: 89225027401 | M35: Емшанов Тимофей | N35: 6091,6092,6093,6094,6095 | P35: 5000 | R35: + | S35: 250000 | T35: =S35*(F35/1000) -> 1250000
A36: авто | B36: Спец№37 (5-5) | C36: Химпром | D36: ТЕРРАПАН - бум 25,0 кг | E36: 329/19 | F36: 5000 | G36: 200 | H36: Краснокамск | I36: отгружено | J36: 45639 | K36: Скания М 753 РТ 116 | L36: 89225027401 | M36: Емшанов Тимофей | N36: 6111,6112,6113,6114,6115 | P36: 5000 | R36: + | S36: 250000 | T36: =S36*(F36/1000) -> 1250000
A37: авто | B37: Спец№37 (5-5) | C37: Химпром | D37: ТЕРРАПАН - бум 25,0 кг | E37: 329/20 | F37: 5000 | G37: 200 | H37: Краснокамск | I37: отгружено | J37: 45639 | K37: Скания М 753 РТ 116 | L37: 89225027401 | M37: Емшанов Тимофей | N37: 6126,6127,6128,6129,6130 | P37: 5000 | R37: + | S37: 250000 | T37: =S37*(F37/1000) -> 1250000
A38: авто | B38: Спец№37 (5-5) | C38: Химпром | D38: ТЕРРАПАН - бум 25,0 кг | E38: 329/23 | F38: 1000 | G38: 40 | H38: Краснокамск | I38: отгружено | J38: 45639 | K38: Скания М 753 РТ 116 | L38: 89225027401 | M38: Емшанов Тимофей | N38: 5679 | P38: 1000 | R38: + | S38: 250000 | T38: =S38*(F38/1000) -> 250000
A39: авто(ГК Урал) | B39: БС-087056 | C39: БурСервис | D39: BURFLC - бум 25,0 кг | E39: 241024 | F39: 14875 | G39: 595 | H39: Пыть-Ях | I39: отгружено | J39: 45642 | K39: Daf К 298 МО 45 | L39: 89512771429 | M39: Кутовой Юрий | O39: 14875 | R39: + | S39: 48500 | T39: =S39*(F39/1000) -> 721437.5
A40: авто(ГК Урал) | B40: БС-084595 | C40: БурСервис | D40: TORQ TRIM II PLUS (СС Голд) - 185 кг п/эт | E40: 241024 | F40: 4440 | G40: 24 | H40: Пыть-Ях | I40: отгружено | J40: 45642 | K40: Daf К 298 МО 46 | L40: 89512771429 | M40: Кутовой Юрий | Q40: 4440 | R40: + | S40: 125000 | T40: =S40*(F40/1000) -> 555000
A41: авто(ГК Урал) | B41: Спец№4 | C41: Барус | D41: Стабилайт II - бум 25,0 кг | E41: 091224 | F41: 15000 | G41: 600 | H41: Челябинск | I41: отгружено | J41: 45642 | K41: Ивеко У 848 ЕВ 174 | L41: 89068680005 | M41: Пьячев Владимир | O41: 15000 | R41: + | S41: 45000 | T41: =S41*(F41/1000) -> 675000
...

Sheet ноябрь 2024
B1: ОТГРУЗКИ ПРОДУКЦИИ | C1: 45597
A2: заметки | B2: НОМЕР ЗАКАЗА | C2: КЛИЕНТ | D2: ПРОДУКТ | E2: ПАРТИЯ | F2: КОЛИЧЕСТВО | H2: ПУНКТ НАЗНАЧЕНИЯ | I2: СТАТУС | J2: ДАТА ОТГРУЗКИ | K2: АВТОДОСТАВКА | N2: ЖД ДОСТАВКА | O2: ИТОГО ОТГРУЖЕНО | R2: АКТЫ
F3: КГ | G3: мешков/бочек | K3: № АВТО | L3: ТЕЛ. ВОДИТЕЛЯ | M3: ВОДИТЕЛЬ | N3: № КОНТЕЙНЕРА | O3: ЧП | P3: ИНАЯ | Q3: Жидкий | S3: Цена со склада за 1 тонну | T3: Итого
A5: авто (Ванюхин) | B5: Спец№2 | C5: ОМАС | D5: КЛА-ФРИ - 200 кг п/эт | E5: 111024 | F5: 8800 | G5: 44 | H5: Кульсары | I5: отгружено | J5: 45597 | K5: Вольво Т 681 МР 67 | L5: 89811049534/87478866036 | M5: Бушков Александр | Q5: 8800 | R5: + | S5: 164000 | T5: =S5*(F5/1000) -> 1443200
A6: авто (Ванюхин) | B6: Спец№2 | C6: ОМАС | D6: Сульф асф - п/проп обезл 25,0 кг | E6: 04/2024 | F6: 11000 | G6: 440 | H6: Кульсары | I6: отгружено | J6: 45597 | K6: Вольво Т 681 МР 67 | L6: 89811049534/87478866036 | M6: Бушков Александр | O6: 11000 | R6: + | S6: 43500 | T6: =S6*(F6/1000) -> 478500
A7: конт (самовывоз) | B7: БС-079835 | C7: БурСервис | D7: BURFLC - бум 25,0 кг | E7: 231024 | F7: 17500 | G7: 700 | H7: Пурпе | I7: отгружено | J7: 45602 | K7: МАЗ М 326 ОХ 29 | L7: 89116806638 | M7: Орлов Павел | N7: RZDU0682975 | O7: 17500 | R7: + | S7: 48500 | T7: =S7*(F7/1000) -> 848750
A8: авто(Бакин) | B8: БС-080924(1-2) | C8: БурСервис | D8: BURFLC - бум 25,0 кг | E8: 011124 | F8: 20125 | G8: 805 | H8: Пыть-Ях | I8: отгружено | J8: 45603 | K8: Вольво С 931 ЕМ 51 | L8: 89212974613 | M8: Киреев Сергей | O8: 20125 | R8: + | S8: 48500 | T8: =S8*(F8/1000) -> 976062.5
A9: самовывоз | B9: счет №351 | C9: ООО СГЭС | D9: РЕОМОД п - бум 18,0 кг | E9: 20241004 | F9: 54 | G9: 3 | H9: ПЭК | I9: отгружено | J9: 45603 | K9: Накл. 299950446972 | P9: 54 | R9: + | S9: 210000 | T9: =S9*(F9/1000) -> 11340
A10: конт (Клото) | B10: БС-080783(1-3) | C10: БурСервис | D10: BURFLC - бум 25,0 кг | E10: 291024 | F10: 17500 | G10: 700 | H10: Нягань | I10: отгружено | J10: 45604 | K10: Камаз Е 999 СА 29 | M10: Вайгант Сергей | N10: RZDU0698544 | O10: 17500 | R10: + | S10: 48500 | T10: =S10*(F10/1000) -> 848750
A11: конт (Клото) | B11: БС-080783(2-3) | C11: БурСервис | D11: BURFLC - бум 25,0 кг | E11: 301024 | F11: 17500 | G11: 700 | H11: Нягань | I11: отгружено | J11: 45604 | K11: МАЗ М 326 ОХ 29 | M11: Орлов Павел | N11: ТКRU3174628 | O11: 17500 | R11: + | S11: 48500 | T11: =S11*(F11/1000) -> 848750
A12: конт (Клото) | B12: БС-080783(3-3) | C12: БурСервис | D12: BURFLC - бум 25,0 кг | E12: 311024 | F12: 17500 | G12: 700 | H12: Нягань | I12: отгружено | J12: 45604 | K12: Камаз Е 999 СА 29 | M12: Вайгант Сергей | N12: GQRU3132561 | O12: 17500 | R12: + | S12: 48500 | T12: =S12*(F12/1000) -> 848750
A13: авто(Ариал) | B13: БС-080924(2-2) | C13: БурСервис | D13: BURFLC - бум 25,0 кг | E13: 021124 | F13: 20125 | G13: 805 | H13: Пыть-Ях | I13: отгружено | J13: 45604 | K13: ДАФ А 032 НА 45 | L13: 89195697888 | M13: Шмаков Александр | O13: 20125 | R13: + | S13: 48500 | T13: =S13*(F13/1000) -> 976062.5
A14: авто(Агро) | B14: Счет 383 | C14: СНК | D14: СУПЕРСЛАЙДЕР ГОЛД - 200 кг п/эт | E14: 131124 | F14: 1600 | G14: 8 | H14: Буденновск | I14: отгружено | J14: 45610 | K14: Газ Т 557 КВ 136 | L14: 89304133318 | M14: Коляда Анатолий | Q14: 1600 | R14: + | S14: 130000 | T14: =S14*(F14/1000) -> 208000
A15: авто (самовывоз) | B15: Спец№24 | C15: МКО | D15: BLACKTROL ж - 200 кг п/эт | E15: 050924 | F15: 1600 | G15: 8 | H15: Самовывоз | I15: отгружено | J15: 45614 | K15: SHACMAN Е 904 РО 156 | L15: 89228819733 | M15: Сандак Сергей | Q15: 1600 | R15: + | S15: 95000 | T15: =S15*(F15/1000) -> 152000
A16: авто (самовывоз) | B16: Спец№24 | C16: МКО | D16: BLACKTROL ж - 200 кг п/эт | E16: 260824 | F16: 16000 | G16: 80 | H16: Самовывоз | I16: отгружено | J16: 45614 | K16: SHACMAN Е 904 РО 156 | L16: 89228819733 | M16: Сандак Сергей | Q16: 16000 | R16: + | S16: 95000 | T16: =S16*(F16/1000) -> 1520000
A17: авто (самовывоз) | B17: Спец 5 | C17: BioEnergy | D17: ЭКСТРАМУЛ-2000 - 190 кг мет | E17: 061124 | F17: 15200 | G17: 80 | H17: Самовывоз | I17: отгружено | J17: 45615 | K17: SCANIA М 870 КУ 198 | M17: Осокин Дмитрий Владимирович | Q17: 15200 | R17: + | S17: 125000 | T17: =S17*(F17/1000) -> 1900000
A18: авто | B18: Спец№14(3-5) | C18: КазПетроДриллинг | D18: Оптитрол Ж - 200 кг п/эт | E18: 290824 | F18: 3200 | G18: 16 | H18: Жанаозен | I18: отгружено | J18: 45616 | K18: DAF Р 783 ОР 790 | L18: 89963427701/87772313238 | M18: Шестопалов Александр | Q18: 3200 | R18: + | S18: 69000 | T18: =S18*(F18/1000) -> 220800
A19: авто | B19: Спец№14(3-5) | C19: КазПетроДриллинг | D19: Оптитрол Ж - 200 кг п/эт | E19: 310824 | F19: 7000 | G19: 35 | H19: Жанаозен | I19: отгружено | J19: 45616 | K19: DAF Р 783 ОР 790 | L19: 89963427701/87772313238 | M19: Шестопалов Александр | Q19: 7000 | R19: + | S19: 69000 | T19: =S19*(F19/1000) -> 483000
A20: авто | B20: Спец№14(3-5) | C20: КазПетроДриллинг | D20: Оптитрол Ж - 200 кг п/эт | E20: 010924 | F20: 7200 | G20: 36 | H20: Жанаозен | I20: отгружено | J20: 45616 | K20: DAF Р 783 ОР 790 | L20: 89963427701/87772313238 | M20: Шестопалов Александр | Q20: 7200 | R20: + | S20: 69000 | T20: =S20*(F20/1000) -> 496800
A21: авто | B21: Спец№14(3-5) | C21: КазПетроДриллинг | D21: Оптитрол Ж - 200 кг п/эт | E21: 020924 | F21: 200 | G21: 1 | H21: Жанаозен | I21: отгружено | J21: 45616 | K21: DAF Р 783 ОР 790 | L21: 89963427701/87772313238 | M21: Шестопалов Александр | Q21: 200 | R21: + | S21: 69000 | T21: =S21*(F21/1000) -> 13800
A22: авто | B22: Спец№14(4-5) | C22: КазПетроДриллинг | D22: Оптитрол Ж - 200 кг п/эт | E22: 290824 | F22: 3200 | G22: 16 | H22: Жанаозен | I22: отгружено | J22: 45618 | K22: Вольво Т 681 МР 67 | L22: 89608185086/87777918885 | M22: Ащегулов Семен | Q22: 3200 | R22: + | S22: 69000 | T22: =S22*(F22/1000) -> 220800
A23: авто | B23: Спец№14(4-5) | C23: КазПетроДриллинг | D23: Оптитрол Ж - 200 кг п/эт | E23: 020924 | F23: 6600 | G23: 33 | H23: Жанаозен | I23: отгружено | J23: 45618 | K23: Вольво Т 681 МР 67 | L23: 89608185086/87777918885 | M23: Ащегулов Семен 89608185086/87777918885 Вольво Т 681 МР 67 | Q23: 6600 | R23: + | S23: 69000 | T23: =S23*(F23/1000) -> 455400
A24: авто | B24: Спец№14(4-5) | C24: КазПетроДриллинг | D24: Оптитрол Ж - 200 кг п/эт | E24: 030924 | F24: 7000 | G24: 35 | H24: Жанаозен | I24: отгружено | J24: 45618 | K24: Вольво Т 681 МР 67 | L24: 89608185086/87777918885 | M24: Ащегулов Семен | Q24: 7000 | R24: + | S24: 69000 | T24: =S24*(F24/1000) -> 483000
A25: авто | B25: Спец№14(4-5) | C25: КазПетроДриллинг | D25: Оптитрол Ж - 200 кг п/эт | E25: 040924 | F25: 600 | G25: 3 | H25: Жанаозен | I25: отгружено | J25: 45618 | K25: Вольво Т 681 МР 67 | L25: 89608185086/87777918885 | M25: Ащегулов Семен | Q25: 600 | R25: + | S25: 69000 | T25: =S25*(F25/1000) -> 41400
A26: авто | B26: Спец№14(4-5) | C26: КазПетроДриллинг | D26: Оптитрол Ж - 200 кг п/эт | E26: 050924 | F26: 200 | G26: 1 | H26: Жанаозен | I26: отгружено | J26: 45618 | K26: Вольво Т 681 МР 67 | L26: 89608185086/87777918885 | M26: Ащегулов Семен | Q26: 200 | R26: + | S26: 69000 | T26: =S26*(F26/1000) -> 13800
A27: авто(Гандвик) | B27: Спец№24 | C27: ЭКО ФЛУИДЗ | D27: Сульф асф - бум 25,0 кг | E27: 050424 | F27: 20000 | G27: 800 | H27: Самара | I27: отгружено | J27: 45621 | K27: VOLVO О 917 МХ 29 | L27: 89115675225 | M27: Любимков Алексей | O27: 20000 | R27: + | S27: 43500 | T27: =S27*(F27/1000) -> 870000
A28: авто (самовывоз) | B28: Спец№24 | C28: МКО | D28: BLACKTROL ж - 200 кг п/эт | E28: 040924 | F28: 8800 | G28: 44 | H28: Самовывоз | I28: отгружено | J28: 45621 | K28: Вольво К 120 НК 196 | L28: 89126356925 | M28: Заяц Анатолий | Q28: 8800 | R28: + | S28: 95000 | T28: =S28*(F28/1000) -> 836000
A29: авто (самовывоз) | B29: Спец№24 | C29: МКО | D29: BLACKTROL ж - 200 кг п/эт | E29: 060924 | F29: 8800 | G29: 44 | H29: Самовывоз | I29: отгружено | J29: 45621 | K29: Вольво К 120 НК 196 | L29: 89126356925 | M29: Заяц Анатолий | Q29: 8800 | R29: + | S29: 95000 | T29: =S29*(F29/1000) -> 836000
A30: авто(Агро) | B30: Спец№55К | C30: Омас | D30: ДЖИ-ДРИЛЛ - 200 кг п/эт | E30: 151124 | F30: 8000 | G30: 40 | H30: Бузулук | I30: отгружено | J30: 45623 | K30: Мерседес Е 987 ХН 174 | L30: 89194045061/89514348410 | M30: Шкуратов Дмитрий | Q30: 8000 | R30: + | S30: 99000 | T30: =S30*(F30/1000) -> 792000
A31: авто(Агро) | B31: Спец№55К | C31: Омас | D31: Сульф асф - п/проп обезл 25,0 кг | E31: 04/2024 | F31: 10000 | G31: 400 | H31: Бузулук | I31: отгружено | J31: 45623 | K31: Мерседес Е 987 ХН 174 | L31: 89194045061/89514348410 8-919-404-50-61, 8-951-434-84-10 | M31: Шкуратов Дмитрий | O31: 10000 | R31: + | S31: 43500 | T31: =S31*(F31/1000) -> 435000
A32: авто (Ариал) | B32: Спец№34 | C32: Буринтех | D32: СУЛЬФОБИТ - бум 25,0 кг | E32: 231124 | F32: 18000 | G32: 720 | H32: Пыть-Ях | I32: огружено | J32: 45623 | K32: МАН М 353 ОА 29 | L32: 89021980813 | M32: Талашев Александр | O32: 18000 | R32: + | S32: 41500 | T32: =S32*(F32/1000) -> 747000
A33: авто (Ариал) | B33: Спец№34 | C33: Буринтех | D33: СУЛЬФОБИТ - бум 25,0 кг | E33: 261124 | F33: 2000 | G33: 80 | H33: Пыть-Ях | I33: огружено | J33: 45623 | K33: МАН М 353 ОА 29 | L33: 89021980813 | M33: Талашев Александр | O33: 2000 | R33: + | S33: 41500 | T33: =S33*(F33/1000) -> 83000
A34: авто | B34: Спец№14(5-5) | C34: КазПетроДриллинг | D34: Оптитрол Ж - 200 кг п/эт | E34: 040924 | F34: 6400 | G34: 32 | H34: Жанаозен | I34: отгружено | J34: 45623 | K34: DAF У 594 ВА 790 | L34: 89674825560/87052627456 | M34: Черненков Юрий | Q34: 6400 | R34: + | S34: 69000 | T34: =S34*(F34/1000) -> 441600
A35: авто | B35: Спец№14(5-5) | C35: КазПетроДриллинг | D35: Оптитрол Ж - 200 кг п/эт | E35: 050924 | F35: 7000 | G35: 35 | H35: Жанаозен | I35: отгружено | J35: 45623 | K35: DAF У 594 ВА 790 | L35: 89674825560/87052627456 | M35: Черненков Юрий | Q35: 7000 | R35: + | S35: 69000 | T35: =S35*(F35/1000) -> 483000
A36: авто | B36: Спец№14(5-5) | C36: КазПетроДриллинг | D36: Оптитрол Ж - 200 кг п/эт | E36: 060924 | F36: 200 | G36: 1 | H36: Жанаозен | I36: отгружено | J36: 45623 | K36: DAF У 594 ВА 790 | L36: 89674825560/87052627456 | M36: Черненков Юрий | Q36: 200 | R36: + | S36: 69000 | T36: =S36*(F36/1000) -> 13800
A37: авто | B37: Спец№14(5-5) | C37: КазПетроДриллинг | D37: Оптитрол Ж - 200 кг п/эт | E37: 080924 | F37: 4000 | G37: 20 | H37: Жанаозен | I37: отгружено | J37: 45623 | K37: DAF У 594 ВА 790 | L37: 89674825560/87052627456 | M37: Черненков Юрий | Q37: 4000 | R37: + | S37: 69000 | T37: =S37*(F37/1000) -> 276000
A38: авто(Агро) | B38: Спец№54К | C38: Омас | D38: Сульф асф - п/проп обезл 25,0 кг | E38: 110424 | F38: 10000 | G38: 400 | H38: Нижневартовск | I38: огружено | J38: 45623 | K38: Мерседес Н 324 ЕН 774 | L38: 89124779266 | M38: Меньшенин Владимир | O38: 10000 | R38: + | S38: 43500 | T38: =S38*(F38/1000) -> 435000
A39: авто(Агро) | B39: Спец№54К | C39: Омас | D39: Сульф асф - п/проп марк 25,0 кг | E39: 110424 | F39: 10000 | G39: 400 | H39: Нижневартовск | I39: огружено | J39: 45623 | K39: Мерседес Н 324 ЕН 774 | L39: 89124779266 | M39: Меньшенин Владимир | O39: 10000 | R39: + | S39: 43500 | T39: =S39*(F39/1000) -> 435000
A40: авто(Клото) | B40: Спец№56К | C40: Омас | D40: Сульф асф - п/проп обезл 25,0 кг | E40: 110424 | F40: 20000 | G40: 800 | H40: Уфа | I40: огружено | J40: 45625 | K40: Mercedes-Benz О 515 ОУ 29 | L40: 8 953 939 90 73 | M40: Борисов Дмитрий | O40: 20000 | R40: + | S40: 43500 | T40: =S40*(F40/1000) -> 870000
A41: авто | B41: Спец№37 (1-5) | C41: Химпром | D41: ТЕРРАПАН - бум 25,0 кг | E41: 329/1 | F41: 5000 | G41: 200 | H41: Краснокамск | I41: отгружено | J41: 45625 | K41: Ситрак К175УЕ-33 | L41: 8(906)674-99-74 | M41: Золотой Денис Викторович | N41: полностью | P41: =F41 -> 5000 | R41: + | S41: 250000 | T41: =S41*(F41/1000) -> 1250000
...

Sheet октябрь 2024
B1: ОТГРУЗКИ ПРОДУКЦИИ | C1: 45566
A2: заметки | B2: НОМЕР ЗАКАЗА | C2: КЛИЕНТ | D2: ПРОДУКТ | E2: ПАРТИЯ | F2: КОЛИЧЕСТВО | H2: ПУНКТ НАЗНАЧЕНИЯ | I2: СТАТУС | J2: ДАТА ОТГРУЗКИ | K2: АВТОДОСТАВКА | N2: ЖД ДОСТАВКА | O2: ИТОГО ОТГРУЖЕНО | R2: АКТЫ
F3: КГ | G3: мешков/бочек | K3: № АВТО | L3: ТЕЛ. ВОДИТЕЛЯ | M3: ВОДИТЕЛЬ | N3: № КОНТЕЙНЕРА | O3: ЧП | P3: ИНАЯ | Q3: Жидкий | S3: Цена со склада за 1 тонну | T3: Итого
A5: авто | B5: Спец№12 | C5: ERIELL | D5: LG-DRILL - п/проп 25,0 кг | E5: 280324 | F5: 20000 | G5: 800 | H5: Карши | I5: отгружен | J5: 45566 | K5: VOLVO Т351АО 154 | L5: 8-983-603-12-30 | M5: Романов Василий | O5: 20000 | R5: + | S5: 38000 | T5: =S5*(F5/1000) -> 760000
A6: авто | B6: Спец№12 | C6: ERIELL | D6: LG-DRILL - п/проп 25,0 кг | E6: 120824 | F6: 20000 | G6: 800 | H6: Карши | I6: отгружен | J6: 45566 | K6: SHACMAN У084 ЕМ 31 | L6: 89515616862 | M6: Шеншин Андрей | O6: 20000 | R6: + | S6: 38000 | T6: =S6*(F6/1000) -> 760000
A7: авто (АрхГрузЛогистика) | B7: БС-78420 | C7: БурСервис | D7: TORQ TRIM II PLUS (СС Голд) - 185 кг п/эт | E7: 260924 | F7: 8140 | G7: 44 | H7: Губкинский | I7: отгружен | J7: 45566 | K7: ВОЛЬВО С 931 ЕМ 51 | L7: 8-921-297-46-13 | M7: КИРЕЕВ СЕРГЕЙ ВЛАДИМИРОВИЧ | Q7: 8140 | R7: + | S7: 125000 | T7: =S7*(F7/1000) -> 1017500
A8: авто (АрхГрузЛогистика) | B8: БС-78420 | C8: БурСервис | D8: TORQ TRIM II PLUS (СС Голд) - 185 кг п/эт | E8: 270924 | F8: 8140 | G8: 44 | H8: Губкинский | I8: отгружен | J8: 45566 | K8: ВОЛЬВО С 931 ЕМ 51 | L8: 8-921-297-46-13 | M8: КИРЕЕВ СЕРГЕЙ ВЛАДИМИРОВИЧ | Q8: 8140 | R8: + | S8: 125000 | T8: =S8*(F8/1000) -> 1017500
A9: конт (самовывоз) | B9: БС- 76299(1-2) | C9: БурСервис | D9: BURFLC - бум 25,0 кг | E9: 090924 | F9: 17500 | G9: 700 | H9: Нягань | I9: отгружен | J9: 45566 | N9: TKRU3561289 | O9: 17500 | R9: + | S9: 48500 | T9: =S9*(F9/1000) -> 848750
A10: конт (самовывоз) | B10: БС- 76299(2-2) | C10: БурСервис | D10: BURFLC - бум 25,0 кг | E10: 100924 | F10: 17500 | G10: 700 | H10: Нягань | I10: отгружен | J10: 45566 | N10: TKRU3352170 | O10: 17500 | R10: + | S10: 48500 | T10: =S10*(F10/1000) -> 848750
A11: конт (самовывоз) | B11: БС-77383 | C11: БурСервис | D11: OPTIBUR (Оптитрол ж) - 200 п/эт | E11: 190924 | F11: 13600 | G11: 68 | H11: Пурпе | I11: отгружен | J11: 45568 | N11: TKRU3444180 | Q11: 13600 | R11: + | S11: 77400 | T11: =S11*(F11/1000) -> 1052640
A12: конт (самовывоз) | B12: БС-77383 | C12: БурСервис | D12: OPTIBUR (Оптитрол ж) - 200 п/эт | E12: 150924 | F12: 400 | G12: 2 | H12: Пурпе | I12: отгружен | J12: 45568 | N12: TKRU3444180 | Q12: 400 | R12: + | S12: 77400 | T12: =S12*(F12/1000) -> 30960
A13: конт (самовывоз) | B13: БС-77383 | C13: БурСервис | D13: OPTIBUR (Оптитрол ж) - 200 п/эт | E13: 160924 | F13: 800 | G13: 4 | H13: Пурпе | I13: отгружен | J13: 45568 | N13: TKRU3444180 | Q13: 800 | R13: + | S13: 77400 | T13: =S13*(F13/1000) -> 61920
A14: конт (самовывоз) | B14: БС-77383 | C14: БурСервис | D14: OPTIBUR (Оптитрол ж) - 200 п/эт | E14: 170924 | F14: 1000 | G14: 5 | H14: Пурпе | I14: отгружен | J14: 45568 | N14: TKRU3444180 | Q14: 1000 | R14: + | S14: 77400 | T14: =S14*(F14/1000) -> 77400
A15: конт (самовывоз) | B15: БС-77383 | C15: БурСервис | D15: OPTIBUR (Оптитрол ж) - 200 п/эт | E15: 180924 | F15: 200 | G15: 1 | H15: Пурпе | I15: отгружен | J15: 45568 | N15: TKRU3444180 | Q15: 200 | R15: + | S15: 77400 | T15: =S15*(F15/1000) -> 15480
A16: конт (самовывоз) | B16: БС-77383 | C16: БурСервис | D16: DRIL-N-SLIDE (СС Платинум) - 175 кг п/эт | E16: 240924 | F16: 7000 | G16: 40 | H16: Пурпе | I16: отгружен | J16: 45568 | N16: TKRU3096823 | Q16: 7000 | R16: + | S16: 250000 | T16: =S16*(F16/1000) -> 1750000
A17: конт (самовывоз) | B17: БС-77383 | C17: БурСервис | D17: DRIL-N-SLIDE (СС Платинум) - 175 кг п/эт | E17: 250924 | F17: 7000 | G17: 40 | H17: Пурпе | I17: отгружен | J17: 45568 | N17: TKRU3096823 | Q17: 7000 | R17: + | S17: 250000 | T17: =S17*(F17/1000) -> 1750000
A18: авто (Ариал) | B18: Спец№23 | C18: ЭКО ФЛУИДЗ | D18: Сульф асф - п/проп марк 25,0 кг | E18: 050424 | F18: 13000 | G18: 520 | H18: Нижневартовск | I18: отгружен | J18: 45569 | K18: FAW O884РС29 | L18: 89021984502 | M18: Бутвин Николай Александрович | O18: 13000 | R18: + | S18: 43500 | T18: =S18*(F18/1000) -> 565500
A19: авто (Ариал) | B19: Спец№23 | C19: ЭКО ФЛУИДЗ | D19: СУПЕРСЛАЙДЕР ГОЛД - 200 кг п/эт | E19: 180424 | F19: 6400 | G19: 32 | H19: Нижневартовск | I19: отгружен | J19: 45569 | K19: FAW O884РС29 | L19: 89021984502 | M19: Бутвин Николай Александрович | Q19: 6400 | R19: + | S19: 105000 | T19: =S19*(F19/1000) -> 672000
A20: авто(Ариал) | B20: Спец№36 (1/4) | C20: Химпром | D20: ТЕРРАПАН - бум 25,0 кг | E20: 011024 | F20: 20000 | G20: 800 | H20: Краснокамск | I20: отгружен | J20: 45569 | K20: МАН М353ОА/29 | L20: 8(902)1980813 | M20: Талашев Николай Александрович | P20: 20000 | R20: + | S20: 250000 | T20: =S20*(F20/1000) -> 5000000
A21: авто (Арсэн) | B21: БС-76527 | C21: БурСервис | D21: BURFLC - бум 25,0 кг | E21: 110924 | F21: 20000 | G21: 800 | H21: Пыть-Ях | I21: отгружен | J21: 45572 | K21: DAF О226ЕУ 72 | L21: 79829883775 | M21: Киршин Петр Олегович | O21: 20000 | R21: + | S21: 48500 | T21: =S21*(F21/1000) -> 970000
A22: авто (Арсэн) | B22: БС-76527 | C22: БурСервис | D22: BURFLC - бум 25,0 кг | E22: 260924 | F22: 20000 | G22: 800 | H22: Пыть-Ях | I22: отгружен | J22: 45572 | K22: FAW Т 319 ЕР 196 | L22: 7 902 878-79-67 | M22: Соловьев Владимир Викторович | O22: 20000 | R22: + | S22: 48500 | T22: =S22*(F22/1000) -> 970000
A23: авто | B23: Спец№11 | C23: ERIELL | D23: ТЕРРАПАН - бум 25,0 кг | E23: 041024 | F23: 20000 | G23: 800 | H23: Карши | I23: отгружен | J23: 45574 | K23: Volvo М696УХ29 | L23: 79991688231 | M23: Дружинин Александр | P23: 20000 | R23: + | S23: 245000 | T23: =S23*(F23/1000) -> 4900000
A24: авто (АГРО-ТРАНС) | B24: спец№35 | C24: ИНКО-Сервис | D24: ЭКСТРАМУЛ-2000 - 200 кг п/эт | E24: 20241004 | F24: 12000 | G24: 60 | H24: Волгоград | I24: отгружен | J24: 45574 | K24: DAF Р575МС 45 | L24: 8-908-002-65-90 | M24: Голосков Алексей Анатольевич | Q24: 12000 | R24: + | S24: 123000 | T24: =S24*(F24/1000) -> 1476000
A25: авто (АГРО-ТРАНС) | B25: спец№35 | C25: ИНКО-Сервис | D25: РЕОМОД п - бум 18,0 кг | E25: 20241003 | F25: 2160 | G25: 120 | H25: Волгоград | I25: отгружен | J25: 45574 | K25: DAF Р575МС 45 | L25: 8-908-002-65-90 | M25: Голосков Алексей Анатольевич | P25: 2160 | R25: + | S25: 210000 | T25: =S25*(F25/1000) -> 453600
A26: авто (АГРО-ТРАНС) | B26: спец№35 | C26: ИНКО-Сервис | D26: ВЕЛЛТРИТ - 200 кг п/эт | E26: 20241002 | F26: 3200 | G26: 16 | H26: Волгоград | I26: отгружен | J26: 45574 | K26: DAF Р575МС 45 | L26: 8-908-002-65-90 | M26: Голосков Алексей Анатольевич | Q26: 3200 | R26: + | S26: 165000 | T26: =S26*(F26/1000) -> 528000
A27: авто (АГРО-ТРАНС) | B27: Спец№36 (2/4) | C27: Химпром | D27: ТЕРРАПАН - бум 25,0 кг | E27: 071024 | F27: 20000 | G27: 800 | H27: Краснокамск | I27: отгружен | J27: 45576 | K27: SANY E332ВК156 | L27: 89058150959 | M27: Свечников Павел Александрович | P27: 20000 | R27: + | S27: 250000 | T27: =S27*(F27/1000) -> 5000000
A28: авто (ГК УРАЛ) | B28: БС-078277 (1/3) | C28: БурСервис | D28: BURFLC - бум 25,0 кг | E28: 230924 | F28: =G28*25 -> 17500 | G28: 700 | H28: Пыть Ях | I28: отгружен | J28: 45576 | K28: DAF К 298 МО 45 | L28: 7 (919) 569 - 78 - 88 | M28: Шмаков Александр Николаевич | O28: 17500 | R28: + | S28: 48500 | T28: =S28*(F28/1000) -> 848750
A29: авто (ГК УРАЛ) | B29: БС-078277 (1/3) | C29: БурСервис | D29: BURFLC - бум 25,0 кг | E29: 071024 | F29: =G29*25 -> 2625 | G29: 105 | H29: Пыть Ях | I29: отгружен | J29: 45576 | K29: К 298 МО 45 | L29: 7 (919) 569 - 78 - 88 | M29: Шмаков Александр Николаевич | O29: 2625 | R29: + | S29: 48500 | T29: =S29*(F29/1000) -> 127312.5
A30: авто (АГРО-ТРАНС) | B30: Спец№36 (3/4) | C30: Химпром | D30: ТЕРРАПАН - бум 25,0 кг | E30: 081024 | F30: 20000 | G30: 800 | H30: Краснокамск | I30: отгружен | J30: 45580 | K30: ДАФ С 277 МО 45 | L30: 89195886579 89954480239 | M30: Колупаев Дмитрий Андреевич | P30: 20000 | R30: + | S30: 250000 | T30: =S30*(F30/1000) -> 5000000
A31: конт (самовывоз) | B31: БС-078981 | C31: БурСервис | D31: BURFLC - бум 25,0 кг | E31: 071024 | F31: =G31*25 -> 17500 | G31: 700 | H31: Нягань | I31: отгружен | J31: 45580 | M31: Чернаков Константин | N31: TKRU3212116 | O31: 17500 | R31: + | S31: 48500 | T31: =S31*(F31/1000) -> 848750
A32: авто (АРИАЛ-ТРАНС) | B32: Спец№36 (4/4) | C32: Химпром | D32: ТЕРРАПАН - бум 25,0 кг | E32: 101024 | F32: 20000 | G32: 800 | H32: Краснокамск | I32: отгружен | J32: 45581 | K32: FAW О 884 РС 29 | L32: 89021984502 | M32: Бутвин Николай | P32: 20000 | R32: + | S32: 250000 | T32: =S32*(F32/1000) -> 5000000
A33: авто самовывоз | B33: БС- 67534 (20/74) | C33: БурСервис | D33: RADIAGREEN RA - 950 кг еврокуб | E33: OE40513S01 | F33: =G33*950 -> 15200 | G33: 16 | H33: Холмск | I33: отгружен | J33: 45581 | K33: Вольво М 562 УВ 29 | L33: 89009148991 | M33: Ифтодий Николай | Q33: 15200 | R33: + | S33: 713900 | T33: =S33*(F33/1000) -> 10851280
A34: авто самовывоз | B34: БС- 67534 (20/74) | C34: БурСервис | D34: RADIAGREEN RA - 950 кг еврокуб | E34: OE20627010 | F34: =G34*950 -> 1900 | G34: 2 | H34: Холмск | I34: отгружен | J34: 45581 | K34: Вольво М 562 УВ 29 | L34: 89009148991 | M34: Ифтодий Николай | Q34: 1900 | R34: + | S34: 713900 | T34: =S34*(F34/1000) -> 1356410
A35: авто самовывоз | B35: БС- 67534 (20/74) | C35: БурСервис | D35: RADIAGREEN RA - 950 кг еврокуб | E35: ЕО40904007 | F35: =G35*950 -> 1900 | G35: 2 | H35: Холмск | I35: отгружен | J35: 45581 | K35: Вольво М 562 УВ 29 | L35: 89009148991 | M35: Ифтодий Николай | Q35: 1900 | R35: + | S35: 713900 | T35: =S35*(F35/1000) -> 1356410
A36: самовывоз | B36: БС- 67534 (34/74) | C36: БурСервис | D36: RADIAGREEN RA - 950 кг еврокуб | E36: ЕО40904007 | F36: =G36*950 -> 13300 | G36: 14 | H36: Холмск | I36: отгружен | J36: 45582 | K36: Вольво С 931 ЕМ 51 | L36: 89212974613 | M36: Киреев Сергей | Q36: 13300 | R36: + | S36: 713900 | T36: =S36*(F36/1000) -> 9494870
A37: самовывоз | B37: БС- 69716 | C37: БурСервис | D37: RADIAGREEN RA - 950 кг еврокуб | E37: ЕО40904007 | F37: =G37*950 -> 6650 | G37: 7 | H37: Холмск | I37: отгружен | J37: 45582 | K37: Вольво С 931 ЕМ 51 | L37: 89212974613 | M37: Киреев Сергей | Q37: 6650 | R37: + | S37: 713900 | T37: =S37*(F37/1000) -> 4747435
A38: авто (АГРО) | B38: спец№36 | C38: ИНКО-Сервис | D38: ЭКСТРАМУЛ-2000 - 200 кг п/эт | E38: 20241004 | F38: 13600 | G38: 68 | H38: Волгоград | I38: отгружен | J38: 45582 | K38: DAF Н 964 ТО 68 | L38: 89158742477 | M38: Теляев Николай | Q38: 13600 | R38: + | S38: 125500 | T38: =S38*(F38/1000) -> 1706800
A39: авто (АГРО) | B39: спец№36 | C39: ИНКО-Сервис | D39: ВЕЛЛТРИТ - 200 кг п/эт | E39: 20241002 | F39: 4000 | G39: 20 | H39: Волгоград | I39: отгружен | J39: 45582 | K39: DAF Н 964 ТО 68 | L39: 89158742477 | M39: Теляев Николай | Q39: 4000 | R39: + | S39: 167500 | T39: =S39*(F39/1000) -> 670000
A40: авто (АГРО) | B40: Спец№53К | C40: ОМАС | D40: Сульф асф - п/проп марк 25,0 кг | E40: 110424 | F40: 20000 | G40: 800 | H40: Нижневартовск | I40: отгружен | J40: 45583 | K40: ДАФ Е 074 МЕ 45 | L40: 89048812556 | M40: Матаев Петр | O40: 20000 | R40: + | S40: 43500 | T40: =S40*(F40/1000) -> 870000
A41: авто (АРИАЛ) | B41: БС-078277 (2/3) | C41: БурСервис | D41: BURFLC - бум 25,0 кг | E41: 151024 | F41: =G41*25 -> 20125 | G41: 805 | H41: Пыть Ях | I41: отгружен | J41: 45583 | K41: МАН М 353 ОА 29 | L41: 89021980813 | M41: Талашев Николай | O41: 20125 | R41: + | S41: 48500 | T41: =S41*(F41/1000) -> 976062.5
...

Sheet сентябрь 2024
B1: ОТГРУЗКИ ПРОДУКЦИИ | C1: 45536
A2: заметки | B2: НОМЕР ЗАКАЗА | C2: КЛИЕНТ | D2: ПРОДУКТ | E2: ПАРТИЯ | F2: КОЛИЧЕСТВО | H2: ПУНКТ НАЗНАЧЕНИЯ | I2: СТАТУС | J2: ДАТА ОТГРУЗКИ | K2: АВТОДОСТАВКА | N2: ЖД ДОСТАВКА | O2: ИТОГО ОТГРУЖЕНО | R2: АКТЫ
F3: КГ | G3: мешков/бочек | K3: № АВТО | L3: ТЕЛ. ВОДИТЕЛЯ | M3: ВОДИТЕЛЬ | N3: № КОНТЕЙНЕРА | O3: ЧП | P3: ИНАЯ | Q3: Жидкий | S3: Цена со склада за 1 тонну | T3: Итого
A4: авто(ГК Урал) | B4: БС-75446(2-8) | C4: БурСервис | D4: BURFLC - бум 25,0 кг | E4: 260824 | F4: 750 | G4: 30 | H4: Красноярск | I4: отгружено | J4: 45537 | K4: Ситрак Р 309 ТТ 18 | L4: 89501664888 | M4: Тверитин Сергей | O4: 750 | R4: + | S4: 48500 | T4: =S4*(F4/1000) -> 36375
A5: авто(ГК Урал) | B5: БС-75446(2-8) | C5: БурСервис | D5: BURFLC - бум 25,0 кг | E5: 270824 | F5: 18250 | G5: 730 | H5: Красноярск | I5: отгружено | J5: 45537 | K5: Ситрак Р 309 ТТ 18 | L5: 89501664888 | M5: Тверитин Сергей | O5: 18250 | R5: + | S5: 48500 | T5: =S5*(F5/1000) -> 885125
A6: авто(ГК Урал) | B6: БС-75446(2-8) | C6: БурСервис | D6: BURFLC - бум 25,0 кг | E6: 310824 | F6: 1000 | G6: 40 | H6: Красноярск | I6: отгружено | J6: 45537 | K6: Ситрак Р 309 ТТ 18 89501664888 Тверитин Сергей | L6: 89501664888 | M6: Тверитин Сергей | O6: 1000 | R6: + | S6: 48500 | T6: =S6*(F6/1000) -> 48500
A7: авто(Арсэн) | B7: БС-75446(3-8) | C7: БурСервис | D7: BURFLC - бум 25,0 кг | E7: 290824 | F7: 20000 | G7: 800 | H7: Красноярск | I7: отгружено | J7: 45538 | K7: Камаз М 995 АС 550 | L7: 89532610749 | M7: Аксёнов Павел | O7: 20000 | R7: + | S7: 48500 | T7: =S7*(F7/1000) -> 970000
A8: авто(Арсэн) | B8: БС-75446(3-8) | C8: БурСервис | D8: BURFLC - бум 25,0 кг | E8: 310824 | F8: 1000 | G8: 40 | H8: Красноярск | I8: отгружено | J8: 45538 | K8: Камаз М 995 АС 550 | L8: 89532610749 | M8: Аксёнов Павел | O8: 1000 | R8: + | S8: 48500 | T8: =S8*(F8/1000) -> 48500
A9: авто(Рич Трак) | B9: БС-75446(4-8) | C9: БурСервис | D9: BURFLC - бум 25,0 кг | E9: 300824 | F9: 20000 | G9: 800 | H9: Красноярск | I9: отгружено | J9: 45538 | K9: SANY О 070 РК 29 | L9: 89116843391 | M9: Суровцев Сергей | O9: 20000 | R9: + | S9: 48500 | T9: =S9*(F9/1000) -> 970000
A10: авто(самовывоз) | B10: Счет №305 | C10: МОРСКИЕ ПЛАТФОРМЫ | D10: Оптитрол Ж - 200 кг мет | E10: 260824 | F10: 800 | G10: 4 | H10: Самовывоз | I10: отгружено | J10: 45538 | K10: Газ Некст О 455 СТ 29 | L10: 89116873984 | M10: Гуревич Александр | Q10: 800 | R10: + | S10: 80000 | T10: =S10*(F10/1000) -> 64000
A11: авто(самовывоз) | B11: Счет №305 | C11: МОРСКИЕ ПЛАТФОРМЫ | D11: BLACKTROL ж - 200 кг мет | E11: 260824 | F11: 800 | G11: 4 | H11: Самовывоз | I11: отгружено | J11: 45538 | K11: Газ Некст О 455 СТ 29 | L11: 89116873984 | M11: Гуревич Александр | Q11: 800 | R11: + | S11: 90000 | T11: =S11*(F11/1000) -> 72000
A12: авто(Бакин) | B12: БС-75446(5-8) | C12: БурСервис | D12: BURFLC - бум 25,0 кг | E12: 310824 | F12: 20000 | G12: 800 | H12: Красноярск | I12: отгружено | J12: 45539 | K12: Вольво О 856 УЕ 29 | L12: 89600155752 | M12: Вахтомин Иван | O12: 20000 | R12: + | S12: 48500 | T12: =S12*(F12/1000) -> 970000
A13: авто(ГК Урал) | B13: БС-75446(6-8) | C13: БурСервис | D13: BURFLC - бум 25,0 кг | E13: 020924 | F13: 20000 | G13: 800 | H13: Красноярск | I13: отгружено | J13: 45539 | K13: DAF Р 575 МС 45 | L13: 89080026590 | M13: Голосков Алексей | O13: 20000 | R13: + | S13: 48500 | T13: =S13*(F13/1000) -> 970000
A14: авто(Арсэн) | B14: Спец№144(6-6) | C14: Акрос | D14: Drilling Lube (СС РУО) - 200 кг п/эт | E14: 300824 | F14: 8400 | G14: 42 | H14: Мурманск | I14: отгружено | J14: 45539 | K14: MAN Р 461 СЕ 198 | L14: 89168805065 | M14: Балдуев Александр | Q14: 8400 | R14: + | S14: 369000 | T14: =S14*(F14/1000) -> 3099600
A15: авто(Арсэн) | B15: Спец№144(6-6) | C15: Акрос | D15: Drilling Lube (СС РУО) - 200 кг п/эт | E15: 310824 | F15: 9200 | G15: 46 | H15: Мурманск | I15: отгружено | J15: 45539 | K15: MAN Р 461 СЕ 198 | L15: 89168805065 | M15: Балдуев Александр | Q15: 9200 | R15: + | S15: 369000 | T15: =S15*(F15/1000) -> 3394800
A16: авто(Арсэн) | B16: БС-75446(7-8) | C16: БурСервис | D16: BURFLC - бум 25,0 кг | E16: 030924 | F16: 20000 | G16: 800 | H16: Красноярск | I16: отгружено | J16: 45540 | K16: Scania Н 099 АО 159 | L16: 89082542474 | M16: Вус Сергей | O16: 20000 | R16: + | S16: 48500 | T16: =S16*(F16/1000) -> 970000
A17: авто(Борисов) | B17: Спец№23 обмен | C17: Буринтех | D17: МАКС-ФЛЕКС - 200 кг п/эт | E17: 15082024 | F17: 20000 | G17: 100 | H17: Пурпе | I17: отгружено | J17: 45541 | K17: Mercedes О 515 ОУ 29 | L17: 89539399073 | M17: Борисов Дмитрий | Q17: 20000 | R17: +
A18: конт | B18: Спец№32 | C18: Буринтех | D18: СУЛЬФОБИТ - бум 25,0 кг | E18: 090824 | F18: 17500 | G18: 700 | H18: Пыть-Ях | I18: отгружено | J18: 45541 | N18: TKRU3300602 | O18: 17500 | R18: + | S18: 41000 | T18: =S18*(F18/1000) -> 717500
A19: конт | B19: Спец№32 | C19: Буринтех | D19: СУЛЬФОБИТ - бум 25,0 кг | E19: 080824 | F19: 17500 | G19: 700 | H19: Пыть-Ях | I19: отгружено | J19: 45541 | N19: TKRU3546535 | O19: 17500 | R19: + | S19: 41000 | T19: =S19*(F19/1000) -> 717500
A20: конт (самовывоз) | B20: БС-69083 (2/2) | C20: БурСервис | D20: BURFLC - бум 25,0 кг | E20: 180724 | F20: 17500 | G20: 700 | H20: Пурпе | I20: отгружено | J20: 45541 | N20: TKRU3546330 | O20: 17500 | R20: + | S20: 49500 | T20: =S20*(F20/1000) -> 866250
A21: конт (самовывоз) | B21: БС-71962 | C21: БурСервис | D21: BURFLC - бум 25,0 кг | E21: 210824 | F21: 17500 | G21: 700 | H21: Пурпе | I21: отгружено | J21: 45541 | N21: GQRU3478220 | O21: 17500 | R21: + | S21: 48500 | T21: =S21*(F21/1000) -> 848750
A22: авто(Бакин) | B22: БС-75446(8-8) | C22: БурСервис | D22: BURFLC - бум 25,0 кг | E22: 040924 | F22: 18000 | G22: 720 | H22: Красноярск | I22: отгружено | J22: 45541 | K22: Вольво С 931 ЕМ 51 | L22: 89212974613 | M22: Киреев Сергей | O22: 18000 | R22: + | S22: 48500 | T22: =S22*(F22/1000) -> 873000
A23: авто (самовывоз) | B23: БС- 69717 | C23: БурСервис | D23: RADIAGREEN RA - 175 кг мет | E23: OE20608R01 | F23: 2450 | G23: 14 | H23: Холмск | I23: отгружено | J23: 45541 | K23: ГАЗ М 577 CX 790 | L23: 89162274936 | M23: Аверин Александр | Q23: 2450 | R23: + | S23: 598000 | T23: =S23*(F23/1000) -> 1465100
A24: авто | B24: Спец№14(2-5) | C24: КазПетроДриллинг | D24: Оптитрол Ж - 200 кг п/эт | E24: 090424 | F24: 7200 | G24: 36 | H24: Жанаозен | I24: отгружено | J24: 45544 | K24: DAF Е 375 АМ 198 | L24: 89270908660/87779998937 | M24: Каражан Арман | Q24: 7200 | R24: + | S24: 69000 | T24: =S24*(F24/1000) -> 496800
A25: авто | B25: Спец№14(2-5) | C25: КазПетроДриллинг | D25: Оптитрол Ж - 200 кг п/эт | E25: 200824 | F25: 6400 | G25: 32 | H25: Жанаозен | I25: отгружено | J25: 45544 | K25: DAF Е 375 АМ 198 | L25: 89270908660/87779998937 | M25: Каражан Арман | Q25: 6400 | R25: + | S25: 69000 | T25: =S25*(F25/1000) -> 441600
A26: авто | B26: Спец№14(2-5) | C26: КазПетроДриллинг | D26: Оптитрол Ж - 200 кг п/эт | E26: 280824 | F26: 2800 | G26: 14 | H26: Жанаозен | I26: отгружено | J26: 45544 | K26: DAF Е 375 АМ 198 | L26: 89270908660/87779998937 | M26: Каражан Арман | Q26: 2800 | R26: + | S26: 69000 | T26: =S26*(F26/1000) -> 193200
A27: авто | B27: Спец№14(2-5) | C27: КазПетроДриллинг | D27: Оптитрол Ж - 200 кг п/эт | E27: 290824 | F27: 600 | G27: 3 | H27: Жанаозен | I27: отгружено | J27: 45544 | K27: DAF Е 375 АМ 198 | L27: 89270908660/87779998937 | M27: Каражан Арман | Q27: 600 | R27: + | S27: 69000 | T27: =S27*(F27/1000) -> 41400
A28: авто | B28: Спец№14(2-5) | C28: КазПетроДриллинг | D28: Оптитрол Ж - 200 кг п/эт | E28: 310824 | F28: 600 | G28: 3 | H28: Жанаозен | I28: отгружено | J28: 45544 | K28: DAF Е 375 АМ 198 | L28: 89270908660/8779998937 | M28: Каражан Арман | Q28: 600 | R28: + | S28: 69000 | T28: =S28*(F28/1000) -> 41400
A29: авто (Самовывоз) | B29: Счет №327 | C29: Алмазгеобур | D29: СУПЕРСЛАЙДЕР ГОЛД - 20 кг канистра | E29: 0056430824 | F29: 60 | G29: 3 | H29: Самовывоз | I29: отгружено | J29: 45544 | K29: Возовоз | L29: № наклад. 240745049 | Q29: 60 | R29: + | S29: 105250 | T29: =S29*(F29/1000) -> 6315
A30: авто(Агро) | B30: Спец№21 | C30: ЭКО ФЛУИДЗ | D30: Сульф асф - п/проп марк 25,0 кг | E30: 050424 | F30: 20000 | G30: 800 | H30: Самара | I30: отгружено | J30: 45544 | K30: FOTON К 157 АА 550 | L30: 89173626420 | M30: Гордеев Евгений | O30: 20000 | R30: + | S30: 40700 | T30: =S30*(F30/1000) -> 814000
A31: авто(Гандвик) | B31: спец№34 | C31: ИНКО-Сервис | D31: ЭКСТРАМУЛ-2000 - 200 кг п/эт | E31: 20240814 | F31: 17600 | G31: 88 | H31: Волгоград | I31: отгружено | J31: 45545 | K31: Вольво О 618 СМ 29 | L31: 89212414996 | M31: Бакин Александр | Q31: 17600 | R31: + | S31: 123000 | T31: =S31*(F31/1000) -> 2164800
A32: конт (самовывоз) | B32: БС-71813(1-2) | C32: БурСервис | D32: TORQ TRIM II PLUS (СС Голд) - 185 кг п/эт | E32: 090924 | F32: 7400 | G32: 40 | H32: Пурпе | I32: отгружено | J32: 45547 | N32: TKRU3220657 | Q32: 7400 | R32: + | S32: 125000 | T32: =S32*(F32/1000) -> 925000
A33: конт (самовывоз) | B33: БС-71813(1-2) | C33: БурСервис | D33: TORQ TRIM II PLUS (СС Голд) - 185 кг п/эт | E33: 100924 | F33: 7400 | G33: 40 | H33: Пурпе | I33: отгружено | J33: 45547 | N33: TKRU3220657 | Q33: 7400 | R33: + | S33: 125000 | T33: =S33*(F33/1000) -> 925000
A34: конт (самовывоз) | B34: БС-74413 | C34: БурСервис | D34: BURFLC - бум 25,0 кг | E34: 240824 | F34: 17500 | G34: 700 | H34: Пурпе | I34: отгружено | J34: 45547 | N34: TKRU3421944 | O34: 17500 | R34: + | S34: 48500 | T34: =S34*(F34/1000) -> 848750
A35: конт (самовывоз) | B35: БС-71922 (1-2) | C35: БурСервис | D35: BURFLC - бум 25,0 кг | E35: 060924 | F35: 17500 | G35: 700 | H35: Нягань | I35: отгружено | J35: 45548 | N35: TKRU3541488 | O35: 17500 | R35: + | S35: 48500 | T35: =S35*(F35/1000) -> 848750
A36: конт (самовывоз) | B36: БС-71922 (2-2) | C36: БурСервис | D36: BURFLC - бум 25,0 кг | E36: 070924 | F36: 17500 | G36: 700 | H36: Нягань | I36: отгружено | J36: 45548 | N36: TKRU3340760 | O36: 17500 | R36: + | S36: 48500 | T36: =S36*(F36/1000) -> 848750
A37: авто(Агро) | B37: Спец№22 | C37: ЭКО ФЛУИДЗ | D37: Сульф асф - п/проп марк 25,0 кг | E37: 050424 | F37: 17000 | G37: 680 | H37: Самара | I37: отгружено | J37: 45552 | K37: МАН К 741 АО 763 | L37: 89803786861 | M37: Рангаев Алексей | O37: 17000 | R37: + | S37: 40700 | T37: =S37*(F37/1000) -> 691900
A38: авто(Агро) | B38: Спец№22 | C38: ЭКО ФЛУИДЗ | D38: СУПЕРСЛАЙДЕР ГОЛД - 200 кг п/эт | E38: 290424 | F38: 2400 | G38: 12 | H38: Самара | I38: отгружено | J38: 45552 | K38: МАН К 741 АО 763 | L38: 89803786861 | M38: Рангаев Алексей | Q38: 2400 | R38: + | S38: 99800 | T38: =S38*(F38/1000) -> 239520
A39: авто(Агро) | B39: Спец№34 | C39: Химпром | D39: ТЕРРАПАН - бум 25,0 кг | E39: 160924 | F39: 20000 | G39: 800 | H39: Краснокамск | I39: отгружено | J39: 45553 | K39: Камаз О 970 УК 47 | L39: 89872508769 | M39: Захаров Виталий | P39: 20000 | R39: + | S39: 247000 | T39: =S39*(F39/1000) -> 4940000
A40: авто (Ариал) | B40: Спец№50К | C40: ОМАС | D40: Сульф асф - п/проп обезл 25,0 кг | E40: 04/2024 | F40: 20000 | G40: 800 | H40: Пыть-Ях | I40: отгружено | J40: 45554 | K40: МАН М 353 ОА 29 | L40: 89021980813 | M40: Талашев Николай | O40: 20000 | R40: + | S40: 40700 | T40: =S40*(F40/1000) -> 814000
...

Sheet август 2024
B1: ОТГРУЗКИ ПРОДУКЦИИ | C1: 45505
A2: заметки | B2: НОМЕР ЗАКАЗА | C2: КЛИЕНТ | D2: ПРОДУКТ | E2: ПАРТИЯ | F2: КОЛИЧЕСТВО | H2: ПУНКТ НАЗНАЧЕНИЯ | I2: СТАТУС | J2: ДАТА ОТГРУЗКИ | K2: АВТОДОСТАВКА | N2: ЖД ДОСТАВКА | O2: ИТОГО ОТГРУЖЕНО | R2: АКТЫ
F3: КГ | G3: мешков/бочек | K3: № АВТО | L3: ТЕЛ. ВОДИТЕЛЯ | M3: ВОДИТЕЛЬ | N3: № КОНТЕЙНЕРА | O3: ЧП | P3: ИНАЯ | Q3: Жидкий | S3: Цена со склада за 1 тонну | T3: Итого
A4: вагон | B4: Спец№21 | C4: МКО | D4: Atren SL - бум 25,0 кг | E4: 240524 | F4: 32000 | G4: 1280 | H4: Нижневартовск | I4: отгружено | J4: 45506 | N4: 29002094 20 | O4: 32000 | R4: + | S4: 37200 | T4: =S4*(F4/1000) -> 1190400
A5: вагон | B5: Спец№21 | C5: МКО | D5: Atren SL - бум 25,0 кг | E5: 300524 | F5: 32000 | G5: 1280 | H5: Нижневартовск | I5: отгружено | J5: 45506 | N5: 29002094 20 | O5: 32000 | R5: + | S5: 37200 | T5: =S5*(F5/1000) -> 1190400
A6: авто (самовывоз) | B6: БС-69322 | C6: БурСервис | D6: BURFLC - бум 25,0 кг | E6: 200724 | F6: 17500 | G6: 700 | H6: Нягань | I6: отгружено | J6: 45506 | K6: МАН С 340 ХК 102 | L6: 89174866053 | M6: Петропавловский Олег | O6: 17500 | R6: + | S6: 49500 | T6: =S6*(F6/1000) -> 866250
A7: авто (самовывоз) | B7: БС-69322 | C7: БурСервис | D7: BURFLC - бум 25,0 кг | E7: 190724 | F7: 2500 | G7: 100 | H7: Нягань | I7: отгружено | J7: 45506 | K7: МАН С 340 ХК 103 | L7: 89174866053 | M7: Петропавловский Олег | O7: 2500 | R7: + | S7: 49500 | T7: =S7*(F7/1000) -> 123750
A8: конт (самовывоз) | B8: БС-68110 (14-18) | C8: БурСервис | D8: BURFLC - бум 25,0 кг | E8: 220724 | F8: 17500 | G8: 700 | H8: Пыть-Ях | I8: отгружено | J8: 45509 | N8: TKRU3194460 | O8: 17500 | R8: + | S8: 49500 | T8: =S8*(F8/1000) -> 866250
A9: конт (самовывоз) | B9: БС-68110 (15-18) | C9: БурСервис | D9: BURFLC - бум 25,0 кг | E9: 250724 | F9: 17500 | G9: 700 | H9: Пыть-Ях | I9: отгружено | J9: 45509 | N9: TKRU3418339 | O9: 17500 | R9: + | S9: 49500 | T9: =S9*(F9/1000) -> 866250
A10: конт (самовывоз) | B10: БС-68110 (16-18) | C10: БурСервис | D10: BURFLC - бум 25,0 кг | E10: 260724 | F10: 17500 | G10: 700 | H10: Пыть-Ях | I10: отгружено | J10: 45509 | N10: TKRU3320050 | O10: 17500 | R10: + | S10: 49500 | T10: =S10*(F10/1000) -> 866250
A11: конт (самовывоз) | B11: БС-68110 (17-18) | C11: БурСервис | D11: BURFLC - бум 25,0 кг | E11: 270724 | F11: 17500 | G11: 700 | H11: Пыть-Ях | I11: отгружено | J11: 45509 | N11: TKRU3220240 | O11: 17500 | R11: + | S11: 49500 | T11: =S11*(F11/1000) -> 866250
A12: авто(Ванюхин) | B12: Спец№13 | C12: КазПетроДриллинг | D12: Стабилайт II - п/проп марк 25,0 кг | E12: 070424 | F12: 20000 | G12: 800 | H12: Жанаозен | I12: отгружено | J12: 45509 | K12: DAF Р 783 ОР 790 | L12: 89963427701/87772313238 | M12: Шестопалов Александр | O12: 20000 | R12: + | S12: 45000 | T12: =S12*(F12/1000) -> 900000
A13: авто (Бакин) | B13: Спец№144(1-6) | C13: Акрос | D13: Drilling Lube (СС РУО) - 200 кг п/эт | E13: 290724 | F13: 8400 | G13: 42 | H13: Мурманск | I13: отгружено | J13: 45509 | K13: Вольво С 931 ЕМ 51 | L13: 89212974613 | M13: Киреев Сергей | Q13: 8400 | R13: + | S13: 369000 | T13: =S13*(F13/1000) -> 3099600
A14: авто (Бакин) | B14: Спец№144(1-6) | C14: Акрос | D14: Drilling Lube (СС РУО) - 200 кг п/эт | E14: 020824 | F14: 9200 | G14: 46 | H14: Мурманск | I14: отгружено | J14: 45509 | K14: Вольво С 931 ЕМ 52 | L14: 89212974613 | M14: Киреев Сергей | Q14: 9200 | R14: + | S14: 369000 | T14: =S14*(F14/1000) -> 3394800
A15: авто(Рич Трак) | B15: Спец№12 | C15: КазПетроДриллинг | D15: Оптитрол Ж - 200 кг п/эт | E15: 280524 | F15: 6800 | G15: 34 | H15: Жанаозен | I15: отгружено | J15: 45510 | K15: МАН 012 AAC 06 | L15: 87013440101 | M15: Маханов Манарбек | Q15: 6800 | R15: + | S15: 69000 | T15: =S15*(F15/1000) -> 469200
A16: авто(Рич Трак) | B16: Спец№12 | C16: КазПетроДриллинг | D16: Оптитрол Ж - 200 кг п/эт | E16: 290524 | F16: 6800 | G16: 34 | H16: Жанаозен | I16: отгружено | J16: 45510 | K16: МАН 012 AAC 06 | L16: 87013440101 | M16: Маханов Манарбек | Q16: 6800 | R16: + | S16: 69000 | T16: =S16*(F16/1000) -> 469200
A17: авто(Рич Трак) | B17: Спец№12 | C17: КазПетроДриллинг | D17: Оптитрол Ж - 200 кг п/эт | E17: 300524 | F17: 4000 | G17: 20 | H17: Жанаозен | I17: отгружено | J17: 45510 | K17: МАН 012 AAC 06 | L17: 87013440101 | M17: Маханов Манарбек | Q17: 4000 | R17: + | S17: 69000 | T17: =S17*(F17/1000) -> 276000
A18: авто(Рич Трак) | B18: Спец№1 | C18: ОМАС | D18: КЛА-ФРИ - 200 кг п/эт | E18: 05/2024 | F18: 12800 | G18: 64 | H18: Кызылорда | I18: отгружено | J18: 45510 | K18: Mersedes 723 AAH 06 | L18: 89966200600 | M18: Аманкосулы Ербол | Q18: 12800 | R18: + | S18: 145000 | T18: =S18*(F18/1000) -> 1856000
A19: авто(Рич Трак) | B19: Спец№1 | C19: ОМАС | D19: Сульф асф - п/проп обезл 25,0 кг | E19: 04/2024 | F19: 6000 | G19: 240 | H19: Кызылорда | I19: отгружено | J19: 45510 | K19: Mersedes 723 AAH 06 | L19: 89966200600 | M19: Аманкосулы Ербол | O19: 6000 | R19: + | S19: 40700 | T19: =S19*(F19/1000) -> 244200
A20: конт (самовывоз) | B20: БС- 62175 | C20: БурСервис | D20: RADIAGREEN RA - 175 кг мет | E20: OE20608R01 | F20: 6300 | G20: 36 | H20: Холмск | I20: отгружено | J20: 45510 | K20: Мерседес В 525 ТО 716 | L20: 89600390497 | M20: Сиделёв Игорь | Q20: 6300 | R20: + | S20: 713900 | T20: =S20*(F20/1000) -> 4497570
A21: конт (самовывоз) | B21: БС- 62175 | C21: БурСервис | D21: RADIAGREEN RA - 175 кг мет | E21: OE20608R01 | F21: 7700 | G21: 44 | H21: Холмск | I21: отгружено | J21: 45510 | K21: Мерседес В 525 ТО 716 | L21: 89600390497 | M21: Сиделёв Игорь | Q21: 7700 | R21: + | S21: 713900 | T21: =S21*(F21/1000) -> 5497030
A22: авто(Агро) | B22: Спец№144(2-6) | C22: Акрос | D22: Drilling Lube (СС РУО) - 200 кг п/эт | E22: 050824 | F22: 8400 | G22: 42 | H22: Мурманск | I22: отгружено | J22: 45511 | K22: Ситрак Р 850 АУ 159 | L22: 89120590604 | M22: Петров Вячеслав | Q22: 8400 | R22: + | S22: 369000 | T22: =S22*(F22/1000) -> 3099600
A23: авто(Агро) | B23: Спец№144(2-6) | C23: Акрос | D23: Drilling Lube (СС РУО) - 200 кг п/эт | E23: 050824/1 | F23: 8600 | G23: 43 | H23: Мурманск | I23: отгружено | J23: 45511 | K23: Ситрак Р 850 АУ 159 | L23: 89120590604 | M23: Петров Вячеслав | Q23: 8600 | R23: + | S23: 369000 | T23: =S23*(F23/1000) -> 3173400
A24: авто(Агро) | B24: Спец№144(2-6) | C24: Акрос | D24: Drilling Lube (СС РУО) - 200 кг п/эт | E24: 060824 | F24: 600 | G24: 3 | H24: Мурманск | I24: отгружено | J24: 45511 | K24: Ситрак Р 850 АУ 159 | L24: 89120590604 | M24: Петров Вячеслав | Q24: 600 | R24: + | S24: 369000 | T24: =S24*(F24/1000) -> 221400
A25: авто(Гандвик) | B25: Спец№11 | C25: СБМ | D25: СБМОЙЛРЕО В (Реомод ж) - 180 кг п/эт | E25: 260724 | F25: 7920 | G25: 44 | H25: Пыть-Ях | I25: отгружено | J25: 45511 | K25: VOLVO М 773 ОВ 29 | L25: 89116853272 | M25: Гужихин Сергей | Q25: 7920 | R25: + | S25: 359000 | T25: =S25*(F25/1000) -> 2843280
A26: авто(Гандвик) | B26: Спец№11 | C26: СБМ | D26: СБМОЙЛРЕО В (Реомод ж) - 180 кг п/эт | E26: 310724 | F26: 7920 | G26: 44 | H26: Пыть-Ях | I26: отгружено | J26: 45511 | K26: VOLVO М 773 ОВ 29 | L26: 89116853272 | M26: Гужихин Сергей | Q26: 7920 | R26: + | S26: 359000 | T26: =S26*(F26/1000) -> 2843280
A27: конт (самовывоз) | B27: БС-69649(1-5) | C27: БурСервис | D27: OPTIBUR (Оптитрол ж) - 200 п/эт | E27: 160724/1 | F27: 7000 | G27: 35 | H27: Пурпе | I27: отгружено | J27: 45512 | N27: TKRU3243328 | Q27: 7000 | R27: + | S27: 79000 | T27: =S27*(F27/1000) -> 553000
A28: конт (самовывоз) | B28: БС-69649(1-5) | C28: БурСервис | D28: OPTIBUR (Оптитрол ж) - 200 п/эт | E28: 160724 | F28: 200 | G28: 1 | H28: Пурпе | I28: отгружено | J28: 45512 | N28: TKRU3243328 | Q28: 200 | R28: + | S28: 79000 | T28: =S28*(F28/1000) -> 15800
A29: конт (самовывоз) | B29: БС-69649(1-5) | C29: БурСервис | D29: OPTIBUR (Оптитрол ж) - 200 п/эт | E29: 170724 | F29: 6800 | G29: 34 | H29: Пурпе | I29: отгружено | J29: 45512 | N29: TKRU3243328 | Q29: 6800 | R29: + | S29: 79000 | T29: =S29*(F29/1000) -> 537200
A30: конт (самовывоз) | B30: БС-69649(1-5) | C30: БурСервис | D30: OPTIBUR (Оптитрол ж) - 200 п/эт | E30: 180724 | F30: 2000 | G30: 10 | H30: Пурпе | I30: отгружено | J30: 45512 | N30: TKRU3243328 | Q30: 2000 | R30: + | S30: 79000 | T30: =S30*(F30/1000) -> 158000
A31: конт (самовывоз) | B31: БС-69649(2-5) | C31: БурСервис | D31: OPTIBUR (Оптитрол ж) - 200 п/эт | E31: 180724 | F31: 4800 | G31: 24 | H31: Пурпе | I31: отгружено | J31: 45512 | N31: GQRU3253922 | Q31: 4800 | R31: + | S31: 79000 | T31: =S31*(F31/1000) -> 379200
A32: конт (самовывоз) | B32: БС-69649(2-5) | C32: БурСервис | D32: OPTIBUR (Оптитрол ж) - 200 п/эт | E32: 240724 | F32: 7200 | G32: 36 | H32: Пурпе | I32: отгружено | J32: 45512 | N32: GQRU3253922 | Q32: 7200 | R32: + | S32: 79000 | T32: =S32*(F32/1000) -> 568800
A33: конт (самовывоз) | B33: БС-69649(2-5) | C33: БурСервис | D33: OPTIBUR (Оптитрол ж) - 200 п/эт | E33: 250724 | F33: 4000 | G33: 20 | H33: Пурпе | I33: отгружено | J33: 45512 | N33: GQRU3253922 | Q33: 4000 | R33: + | S33: 79000 | T33: =S33*(F33/1000) -> 316000
A34: авто(самовывоз) | B34: Спец№3 | C34: Алмазгеобур | D34: СУПЕРСЛАЙДЕР ГОЛД - 25 кг канистра | E34: 0046430624 | F34: 11400 | G34: 456 | H34: Самовывоз | I34: отгружено | J34: 45512 | K34: Скания Х 461 ОН 76 | L34: 89051342997 | M34: Львов Андрей Львович | Q34: 11400 | R34: + | S34: 105250 | T34: =S34*(F34/1000) -> 1199850
A35: авто(самовывоз) | B35: Счет№266 и №272 | C35: Алмазгеобур | D35: СУПЕРСЛАЙДЕР ГОЛД - 25 кг канистра | E35: 0046430624 | F35: 1400 | G35: 56 | H35: Самовывоз | I35: отгружено | J35: 45512 | K35: Скания Х 461 ОН 76 | L35: 89051342997 | M35: Львов Андрей Львович | Q35: 1400 | R35: + | S35: 105250 | T35: =S35*(F35/1000) -> 147350
A36: авто(самовывоз) | C36: Алмазгеобур | D36: СУПЕРСЛАЙДЕР ГОЛД - 25 кг канистра | E36: ЗАМЕНА БРАКА | F36: 25 | G36: 1 | H36: Самовывоз | I36: отгружено | J36: 45512 | K36: Скания Х 461 ОН 76 | L36: 89051342997 | M36: Львов Андрей Львович | Q36: 25 | R36: + | T36: =S36*(F36/1000) -> 0
A37: авто(Агро) | B37: Спец№144(3-6) | C37: Акрос | D37: Drilling Lube (СС РУО) - 200 кг п/эт | E37: 060824 | F37: 8000 | G37: 40 | H37: Мурманск | I37: отгружено | J37: 45513 | K37: Камаз О 421 СР 777 | L37: 89815019839 | M37: Сизов Александр | Q37: 8000 | R37: + | S37: 369000 | T37: =S37*(F37/1000) -> 2952000
A38: авто(Агро) | B38: Спец№144(3-6) | C38: Акрос | D38: Drilling Lube (СС РУО) - 200 кг п/эт | E38: 070824 | F38: 9600 | G38: 48 | H38: Мурманск | I38: отгружено | J38: 45513 | K38: Камаз О 421 СР 777 | L38: 89815019839 | M38: Сизов Александр | Q38: 9600 | R38: + | S38: 369000 | T38: =S38*(F38/1000) -> 3542400
A39: авто(Гандвик) | B39: Спец№20 | C39: ЭКО ФЛУИДЗ | D39: Сульф асф - п/проп марк 25,0 кг | E39: 050424 | F39: 20000 | G39: 800 | H39: Самара | I39: отгружено | J39: 45513 | K39: DAF О 922 КМ 29 | L39: 89116853202 | M39: Журавлёв Николай | O39: 20000 | R39: + | S39: 40700 | T39: =S39*(F39/1000) -> 814000
A40: кнт (самовывоз) | B40: БС-69695 (1-2) | C40: БурСервис | D40: BURFLC - бум 25,0 кг | E40: 050824 | F40: 17500 | G40: 700 | H40: Нягань | I40: отгружено | J40: 45513 | N40: TKRU3352041 | O40: 17500 | R40: + | S40: 49500 | T40: =S40*(F40/1000) -> 866250
...

Sheet июль 2024
B1: ОТГРУЗКИ ПРОДУКЦИИ | C1: 45474
A2: заметки | B2: НОМЕР ЗАКАЗА | C2: КЛИЕНТ | D2: ПРОДУКТ | E2: ПАРТИЯ | F2: КОЛИЧЕСТВО | H2: ПУНКТ НАЗНАЧЕНИЯ | I2: СТАТУС | J2: ДАТА ОТГРУЗКИ | K2: АВТОДОСТАВКА | N2: ЖД ДОСТАВКА | O2: ИТОГО ОТГРУЖЕНО | R2: АКТЫ
F3: КГ | G3: мешков/бочек | K3: № АВТО | L3: ТЕЛ. ВОДИТЕЛЯ | M3: ВОДИТЕЛЬ | N3: № КОНТЕЙНЕРА | O3: ЧП | P3: ИНАЯ | Q3: Жидкий | S3: Цена со склада за 1 тонну | T3: Итого
A4: авто (ГЛТМ) | B4: Спец№2 | C4: Химнефтесервис | D4: Оптитрол Ж - 200 кг п/эт | E4: 070424 | F4: 6400 | G4: 32 | H4: Актау | I4: отгружено | J4: 45474 | K4: DAF Е 375 АМ 198 | L4: 89270908660/87779998937 | M4: Каражан Арман | Q4: 6400 | R4: + | S4: 69000 | T4: =S4*(F4/1000) -> 441600
A5: авто (ГЛТМ) | B5: Спец№2 | C5: Химнефтесервис | D5: Оптитрол Ж - 200 кг п/эт | E5: 070424/1 | F5: 7200 | G5: 36 | H5: Актау | I5: отгружено | J5: 45474 | K5: DAF Е 375 АМ 198 | L5: 89270908660/87779998937 | M5: Каражан Арман | Q5: 7200 | R5: + | S5: 69000 | T5: =S5*(F5/1000) -> 496800
A6: авто (ГЛТМ) | B6: Спец№2 | C6: Химнефтесервис | D6: Оптитрол Ж - 200 кг п/эт | E6: 250524 | F6: 2400 | G6: 12 | H6: Актау | I6: отгружено | J6: 45474 | K6: DAF Е 375 АМ 198 | L6: 89270908660/87779998937 | M6: Каражан Арман | Q6: 2400 | R6: + | S6: 69000 | T6: =S6*(F6/1000) -> 165600
A7: авто (ГЛТМ) | B7: Спец№2 | C7: Химнефтесервис | D7: ПОЛИКАП - бум 25,0 кг | E7: 210624 | F7: 2000 | G7: 80 | H7: Актау | I7: отгружено | J7: 45474 | K7: DAF Е 375 АМ 198 | L7: 89270908660/87779998937 | M7: Каражан Арман | P7: 2000 | R7: + | S7: 255000 | T7: =S7*(F7/1000) -> 510000
A8: авто (Агротранс) | B8: Спец№27 | C8: Инко-Сервис | D8: Сульф асф - п/проп обезл 25,0 кг | E8: 20240703 | F8: 15000 | G8: 600 | H8: Волгоград | I8: отгружено | J8: 45474 | K8: МАН А690ОН164 | L8: 79050305630 | M8: Бутенко Антон Иванович | O8: 15000 | R8: + | S8: 39000 | T8: =S8*(F8/1000) -> 585000
A9: авто (Агротранс) | B9: Спец№27 | C9: Инко-Сервис | D9: BLACKTROL ж - 200 кг п/эт | E9: 20240804 | F9: 4800 | G9: 24 | H9: Волгоград | I9: отгружено | J9: 45474 | K9: МАН А690ОН164 | L9: 79050305630 | M9: Бутенко Антон Иванович | Q9: 4800 | R9: + | S9: 87500 | T9: =S9*(F9/1000) -> 420000
