Workbook

Sheet апрель 2026
B1: ОТГРУЗКИ ПРОДУКЦИИ | C1: 46082
A2: заметки | B2: НОМЕР ЗАКАЗА | C2: КЛИЕНТ | D2: ПРОДУКТ | E2: ПАРТИЯ | F2: КОЛИЧЕСТВО | H2: ПУНКТ НАЗНАЧЕНИЯ | I2: СТАТУС | J2: ДАТА ОТГРУЗКИ | K2: АВТОДОСТАВКА | N2: ЖД ДОСТАВКА | O2: ИТОГО ОТГРУЖЕНО | R2: АКТЫ | S2: Цена со склада за 1 тонну
F3: КГ | G3: мешков/бочек | K3: № АВТО | L3: ТЕЛ. ВОДИТЕЛЯ | M3: ВОДИТЕЛЬ | N3: № КОНТЕЙНЕРА/ВАГОНА | O3: ЧП | P3: ИНАЯ | Q3: Жидкий | T3: Итого
A5: авто(Ариал) | B5: БС-133633(2-4) | C5: БурСервис | D5: DRIL-N-SLIDE (СС Платинум) - 175 кг п/эт | E5: 250326 (02.04 №RU117813242) | F5: 7000 | G5: 40 | H5: Пурпе | I5: отгружено | J5: 46113 | K5: Вольво М213АУ196 | L5: 89221247745 | M5: Шулепов Александр | Q5: 7000 | R5: +(02.04) | S5: 255000 | T5: =S5*F5/1000 -> 1785000
A6: авто(Ариал) | B6: БС-133633(2-4) | C6: БурСервис | D6: DRIL-N-SLIDE (СС Платинум) - 175 кг п/эт | E6: 260326 (02.04 №RU117813242) | F6: 7000 | G6: 40 | H6: Пурпе | I6: отгружено | J6: 46113 | K6: Вольво М213АУ196 | L6: 89221247745 | M6: Шулепов Александр | Q6: 7000 | R6: +(02.04) | S6: 255000 | T6: =S6*F6/1000 -> 1785000
A7: авто(Самовывоз) | B7: БС-133633(3-4) | C7: БурСервис | D7: BUR TRIM II PLUS (СС Голд) - 185 кг п/эт | E7: 230326 (02.04 №RU117813242) | F7: 7400 | G7: 40 | H7: Пурпе | I7: отгружено | J7: 46114 | K7: SHACMAN Т706ЕК196 | L7: 89221029900 | M7: Казаков Иван | Q7: 7400 | R7: +(02.04) | S7: 125000 | T7: =S7*F7/1000 -> 925000
A8: авто(Самовывоз) | B8: БС-133633(3-4) | C8: БурСервис | D8: BUR TRIM II PLUS (СС Голд) - 185 кг п/эт | E8: 240326 (02.04 №RU117813242) | F8: 7400 | G8: 40 | H8: Пурпе | I8: отгружено | J8: 46114 | K8: SHACMAN Т706ЕК196 | L8: 89221029900 | M8: Казаков Иван | Q8: 7400 | R8: +(02.04) | S8: 125000 | T8: =S8*F8/1000 -> 925000
A9: кнт(Клото) | B9: Спец№2 | C9: Полихимпром | D9: СУПЕРСЛАЙДЕР СИЛЬВЕР - 200 кг п/эт | E9: 310326 | F9: 16000 | G9: 80 | H9: Усинск | I9: отгружено | J9: 46114 | K9: Накл. №ЭР862709 | N9: TKRU3000626 | Q9: 16000 | R9: + | S9: 85000 | T9: =S9*F9/1000 -> 1360000
A10: Самовывоз | B10: Счет №91 | C10: СГК ГРУПП | D10: СУПЕРСЛАЙДЕР СИЛЬВЕР - 200 кг п/эт | E10: 310326 | F10: 2400 | G10: 12 | H10: Самовывоз | I10: отгружено | J10: 46114 | K10: ТК Энергия ГАЗ М737АЕ29, ГАЗ К412НР29 | L10: № 600-4293558R | M10: Кирчигин Владислав, Алексей Козочкин | Q10: 2400 | R10: + | S10: 87000 | T10: =S10*F10/1000 -> 208800
A11: Самовывоз | B11: Счет №91 | C11: СГК ГРУПП | D11: СУПЕРСЛАЙДЕР ПЛАТИНУМ - 200 кг п/эт | E11: 250326 | F11: 200 | G11: 1 | H11: Самовывоз | I11: отгружено | J11: 46114 | K11: ТК Энергия ГАЗ М737АЕ29, ГАЗ К412НР30 | L11: № 600-4293558R | M11: Кирчигин Владислав, Алексей Козочкин | Q11: 200 | R11: + | S11: 255000 | T11: =S11*F11/1000 -> 51000
A12: Самовывоз | B12: Счет №91 | C12: СГК ГРУПП | D12: BLACKTROL ж - 200 кг п/эт | E12: 200226 | F12: 400 | G12: 2 | H12: Самовывоз | I12: отгружено | J12: 46114 | K12: ТК Энергия ГАЗ М737АЕ29, ГАЗ К412НР31 | L12: № 600-4293558R | M12: Кирчигин Владислав, Алексей Козочкин | Q12: 400 | R12: + | S12: 89000 | T12: =S12*F12/1000 -> 35600
A13: Самовывоз | B13: Счет №91 | C13: СГК ГРУПП | D13: Оптитрол Ж - 200 кг п/эт | E13: 251225 | F13: 200 | G13: 1 | H13: Самовывоз | I13: отгружено | J13: 46114 | K13: ТК Энергия ГАЗ М737АЕ29, ГАЗ К412НР32 | L13: № 600-4293558R | M13: Кирчигин Владислав, Алексей Козочкин | Q13: 200 | R13: + | S13: 79500 | T13: =S13*F13/1000 -> 15900
A14: авто(Агро) | B14: Спец№104К (2-3) | C14: ОМАС | D14: Сульф асф - бум 25,0 кг | E14: 03/2025 | F14: 20000 | G14: 800 | H14: Пыть-Ях | I14: отгружено | J14: 46114 | K14: DAF У515РВ96 | L14: 89221782811 | M14: Лескин Вячеслав | O14: 20000 | R14: + | S14: 44500 | T14: =S14*F14/1000 -> 890000
A15: авто(Агро) | B15: БС-133633(4-4) | C15: БурСервис | D15: BUR TRIM II PLUS (СС Голд) - 185 кг п/эт | E15: 250326(02.04 №RU117813242) | F15: 7400 | G15: 40 | H15: Пурпе | I15: отгружено | J15: 46115 | K15: SHACMAN У463ХО196 | L15: 89829645340 | M15: Солянников Дмитрий | Q15: 7400 | R15: +(03.04) | S15: 125000 | T15: =S15*F15/1000 -> 925000
A16: авто(Агро) | B16: БС-133633(4-4) | C16: БурСервис | D16: BUR TRIM II PLUS (СС Голд) - 185 кг п/эт | E16: 260326(02.04 №RU117813242) | F16: 7400 | G16: 40 | H16: Пурпе | I16: отгружено | J16: 46115 | K16: SHACMAN У463ХО196 | L16: 89829645340 | M16: Солянников Дмитрий | Q16: 7400 | R16: +(03.04) | S16: 125000 | T16: =S16*F16/1000 -> 925000
A17: самовывоз | B17: Спец №4 | C17: FWL | D17: ЭКСТРАМУЛ-2000 - 180 кг мет | E17: 270326 | F17: 14400 | G17: 80 | H17: самовывоз | I17: отгружено | J17: 46115 | K17: Freightliner О551СС 29 | M17: Чурбанов Дмитрий | Q17: 14400 | R17: + | S17: 128500 | T17: =S17*F17/1000 -> 1850400
A18: авто(Агро) | B18: Спец№104К (3-3) | C18: ОМАС | D18: Сульф асф - бум 25,0 кг | E18: 03/2025 | F18: 20000 | G18: 800 | H18: Пыть-Ях | I18: отгружено | J18: 46118 | K18: DONG FENG О546АЕ159 | L18: 89141869306 | M18: Голодяев Иван | O18: 20000 | R18: + | S18: 44500 | T18: =S18*F18/1000 -> 890000
A19: Самовывоз | B19: Спец№1 | C19: Полихимпром | D19: СУПЕРСЛАЙДЕР СИЛЬВЕР - 200 кг п/эт | E19: 310326 | F19: 4000 | G19: 20 | H19: Самовывоз | I19: отгружено | J19: 46118 | K19: Джак У732КС152 | L19: 89065566644 | M19: Соколов Александр | N19: Переданы образцы | Q19: 4000 | R19: + | S19: 85000 | T19: =S19*F19/1000 -> 340000
A20: Самовывоз | B20: Спец№3 | C20: Полихимпром | D20: СУПЕРСЛАЙДЕР СИЛЬВЕР - 200 кг п/эт | E20: 310326 | F20: 1600 | G20: 8 | H20: Самовывоз | I20: отгружено | J20: 46118 | K20: Джак У732КС152 | L20: 89065566644 | M20: Соколов Александр | N20: Переданы образцы | Q20: 1600 | R20: + | S20: 85000 | T20: =S20*F20/1000 -> 136000
A21: самовывоз | B21: Спец №4 | C21: FWL | D21: ВЕЛЛТРИТ - 180 кг мет | E21: 040426 | F21: 14400 | G21: 80 | H21: самовывоз | I21: отгружено | J21: 46119 | K21: DONGFENG С831ВУ 18 | M21: Волков Иван, Филимонов Александр | Q21: 14400 | R21: + | S21: 149900 | T21: =S21*F21/1000 -> 2158560
A22: кнт(Самовывоз) | B22: БС-136247 | C22: БурСервис | D22: BURFLC - бум 25,0 кг | E22: 161025/2 (DPD RU118085965) | F22: 3500 | G22: 140 | H22: Усинск | I22: отгружено | J22: 46121 | K22: Камаз Е999СА29 | L22: 89115583359 | M22: Вайгант Сергей | N22: RZDU0724659 | O22: 3500 | R22: (09.04) | S22: 41000 | T22: =S22*F22/1000 -> 143500
A23: кнт(Самовывоз) | B23: БС-136247 | C23: БурСервис | D23: BURFLC - бум 25,0 кг | E23: 161025/3 (DPD RU118085965) | F23: 4375 | G23: 175 | H23: Усинск | I23: отгружено | J23: 46121 | K23: Камаз Е999СА29 | L23: 89115583359 | M23: Вайгант Сергей | N23: RZDU0724659 | O23: 4375 | R23: (09.04) | S23: 41000 | T23: =S23*F23/1000 -> 179375
A24: кнт(Самовывоз) | B24: БС-136247 | C24: БурСервис | D24: BURFLC - бум 25,0 кг | E24: 161025/4 (DPD RU118085965) | F24: 4375 | G24: 175 | H24: Усинск | I24: отгружено | J24: 46121 | K24: Камаз Е999СА29 | L24: 89115583359 | M24: Вайгант Сергей | N24: RZDU0724659 | O24: 4375 | R24: (09.04) | S24: 41000 | T24: =S24*F24/1000 -> 179375
A25: кнт(Самовывоз) | B25: БС-136247 | C25: БурСервис | D25: BURFLC - бум 25,0 кг | E25: 060426 (DPD RU118085965) | F25: 5250 | G25: 210 | H25: Усинск | I25: отгружено | J25: 46121 | K25: Камаз Е999СА29 | L25: 89115583359 | M25: Вайгант Сергей | N25: RZDU0724659 | O25: 5250 | R25: (09.04) | S25: 41000 | T25: =S25*F25/1000 -> 215250
A26: Самовывоз | B26: Счет №98 от 30.03.26 | C26: НГС | D26: АПП-490, бочка п/э 200кг | E26: 080426 | F26: 1200 | G26: 6 | H26: Самовывоз | I26: отгружено | J26: 46122 | K26: SITRAK К868ВУ702 | L26: 89173476508 | M26: Умурбаев Сергей | Q26: 1200 | S26: 330000 | T26: =S26*F26/1000 -> 396000
A27: Самовывоз | B27: Счет №98 от 30.03.26 | C27: НГС | D27: КАТФЛО, бочка п/э 200 кг | E27: 060426 | F27: 1000 | G27: 5 | H27: Самовывоз | I27: отгружено | J27: 46122 | K27: SITRAK К868ВУ702 | L27: 89173476508 | M27: Умурбаев Сергей | Q27: 1000 | S27: 419000 | T27: =S27*F27/1000 -> 419000
A28: Самовывоз | B28: Счет №98 от 30.03.26 | C28: НГС | D28: ФОРЕСТ-ОЙЛ, бочка п/э 190 кг | E28: 070426 | F28: 8740 | G28: 46 | H28: Самовывоз | I28: отгружено | J28: 46122 | K28: SITRAK К868ВУ702 | L28: 89173476508 | M28: Умурбаев Сергей | Q28: 8740 | S28: 127000 | T28: =S28*F28/1000 -> 1109980
A29: авто(Клото) | B29: Спец№106К (1-3) | C29: ОМАС | D29: Сульф асф - бум 25,0 кг | E29: 03/2025 | F29: 20000 | G29: 800 | H29: Пыть-Ях | I29: отгружено | J29: 46122 | K29: Mercedes О515ОУ29 | L29: 89115800204 | M29: Борисов Дмитрий | O29: 20000 | R29: + | S29: 44500 | T29: =S29*F29/1000 -> 890000
A30: авто (Ариал+ванюхин) | B30: Спец№1 | C30: Химнефтесервис | D30: ПОЛИТРОЛ - 200 кг п/эт | E30: 080426 | F30: 1200 | G30: 6 | H30: Актау | I30: отгружено | J30: 46122 | K30: FORD О483УС29 / Р039ВВ250 | L30: 89115553852/89273633863/77789283367 | M30: Попов Геннадий/Суетин Дмитрий | Q30: 1200 | R30: + | S30: 125000 | T30: =S30*F30/1000 -> 150000
A31: авто() | B31: Спец№60 | C31: Инко-Сервис | D31: Стабилайт II - бум марк 25,0 кг | E31: 240326 | F31: 20000 | G31: 800 | H31: Волгоград | I31: отгружено | J31: 46125 | K31: ДАФ К575ТС763 | L31: 89270004647 | M31: Березанский Евгений | O31: 20000 | S31: 44300 | T31: =S31*F31/1000 -> 886000
T32: =S32*F32/1000 -> 0
T33: =S33*F33/1000 -> 0
A34: кнт(Клото) | B34: Спец№4 | C34: Полихимпром | D34: СУПЕРСЛАЙДЕР СИЛЬВЕР - 200 кг п/эт | E34: 100426 | F34: 16000 | G34: 80 | H34: Усинск | J34: 46126 | N34: RZDU3005129 | S34: 85000 | T34: =S34*F34/1000 -> 1360000
T35: =S35*F35/1000 -> 0
T36: =S36*F36/1000 -> 0
A37: авто() | B37: Спец№20 | C37: ХимБурСервис | D37: BLACKTROL ж - 200 кг п/эт | E37: 100226 | F37: 8800 | G37: 44 | H37: Пыть-Ях | J37: 46127 | K37: 262 | S37: 88400 | T37: =S37*F37/1000 -> 777920
A38: авто() | B38: Спец№20 | C38: ХимБурСервис | D38: BLACKTROL ж - 200 кг п/эт | E38: 120226 | F38: 8800 | G38: 44 | H38: Пыть-Ях | J38: 46127 | S38: 88400 | T38: =S38*F38/1000 -> 777920
T39: =S39*F39/1000 -> 0
T40: =S40*F40/1000 -> 0
A41: самовывоз | B41: Спец №4 | C41: FWL | D41: ЭКСТРАМУЛ-2000 - 180 кг мет | E41: 300326 | F41: 14400 | G41: 80 | H41: самовывоз | J41: 46125 | S41: 128500 | T41: =S41*F41/1000 -> 1850400
...

Sheet март 2026
B1: ОТГРУЗКИ ПРОДУКЦИИ | C1: 46082
A2: заметки | B2: НОМЕР ЗАКАЗА | C2: КЛИЕНТ | D2: ПРОДУКТ | E2: ПАРТИЯ | F2: КОЛИЧЕСТВО | H2: ПУНКТ НАЗНАЧЕНИЯ | I2: СТАТУС | J2: ДАТА ОТГРУЗКИ | K2: АВТОДОСТАВКА | N2: ЖД ДОСТАВКА | O2: ИТОГО ОТГРУЖЕНО | R2: АКТЫ | S2: Цена со склада за 1 тонну
F3: КГ | G3: мешков/бочек | K3: № АВТО | L3: ТЕЛ. ВОДИТЕЛЯ | M3: ВОДИТЕЛЬ | N3: № КОНТЕЙНЕРА/ВАГОНА | O3: ЧП | P3: ИНАЯ | Q3: Жидкий | T3: Итого
A5: авто(Ариал) | B5: Спец№103К (3-3) | C5: ОМАС | D5: Сульф асф - бум 25,0 кг | E5: 03/2025 | F5: 20000 | G5: 800 | H5: Пыть-Ях | I5: отгружено | J5: 46084 | K5: DAF О539ОН29 | L5: 89216700606 | M5: Хрущ Александр | O5: 20000 | R5: + | S5: 44500 | T5: =S5*F5/1000 -> 890000
A6: авто(Транскомплект) | B6: Спец№156 | C6: Акрос | D6: Drilling Lube (СС РУО) - 200 кг п/эт | E6: 200226 | F6: 17600 | G6: 88 | H6: Мурманск | I6: отгружено | J6: 46084 | K6: MAN С938ВУ18 | L6: 89194506037 | M6: Беляев Дмитрий | Q6: 17600 | R6: + | S6: 369000 | T6: =S6*F6/1000 -> 6494400
A7: Самовывоз | B7: Счет №14 | C7: КОМОКС | D7: РЕОМОД п - бум 18,0 кг | E7: 200226 | F7: 504 | G7: 28 | H7: Самовывоз | I7: отгружено | J7: 46087 | K7: Байкал сервис АР-0048772 | P7: 504 | R7: + | S7: 245000 | T7: =S7*F7/1000 -> 123480
A8: авто(Семенова) | B8: Спец№58 | C8: Инко-Сервис | D8: ЭКСТРАМУЛ-2000 - 200 кг п/эт | E8: 20260209 | F8: 14400 | G8: 72 | H8: Демьянка | I8: отгружено | J8: 46087 | K8: DAF У377МХ45 | L8: 89195966929 | M8: Ильин Андрей | Q8: 14400 | R8: + | S8: 122000 | T8: =S8*F8/1000 -> 1756800
A9: авто(Семенова) | B9: Спец№58 | C9: Инко-Сервис | D9: IN-MOD (РЕОМОД) - бум 18,0 кг | E9: 20260210 | F9: 720 | G9: 40 | H9: Демьянка | I9: отгружено | J9: 46087 | K9: DAF У377МХ45 | L9: 89195966929 | M9: Ильин Андрей | P9: 720 | R9: + | S9: 220000 | T9: =S9*F9/1000 -> 158400
A10: авто(Семенова) | B10: Спец№58 | C10: Инко-Сервис | D10: ВЕЛЛТРИТ - 200 кг п/эт | E10: 20260209 | F10: 1600 | G10: 8 | H10: Демьянка | I10: отгружено | J10: 46087 | K10: DAF У377МХ45 | L10: 89195966929 | M10: Ильин Андрей | Q10: 1600 | R10: + | S10: 157000 | T10: =S10*F10/1000 -> 251200
A11: авто(Агро) | B11: Спец№44 (2-4) | C11: МАДСЕРВИС | D11: Сульф асф - бум 25,0 кг | E11: 160226 | F11: 20000 | G11: 800 | H11: Самара | I11: отгружено | J11: 46091 | K11: Скания А074РУ716 | L11: 89058517997 | M11: Шамсутдинов Рустам | O11: 20000 | R11: + | S11: 44500 | T11: =S11*F11/1000 -> 890000
A12: авто(Ариал) | B12: БС-131996 | C12: БурСервис | D12: DRIL-N-SLIDE (СС Платинум) - 175 кг п/эт | E12: 100326 | F12: 7700 | G12: 44 | H12: Губкинский | I12: отгружено | J12: 46091 | K12: Вольво Т838ВМ196 | L12: 89090041850 | M12: Белоусов Денис | Q12: 7700 | R12: + | S12: 255000 | T12: =S12*F12/1000 -> 1963500
A13: авто(Ариал) | B13: БС-131996 | C13: БурСервис | D13: DRIL-N-SLIDE (СС Платинум) - 175 кг п/эт | E13: 110326 | F13: 7700 | G13: 44 | H13: Губкинский | I13: отгружено | J13: 46091 | K13: Вольво Т838ВМ196 | L13: 89090041850 | M13: Белоусов Денис | Q13: 7700 | R13: + | S13: 255000 | T13: =S13*F13/1000 -> 1963500
A14: кнт (Клото) | B14: Спец№4 (1-5) | C14: Комар эпокси | D14: СУПЕРСЛАЙДЕР ГОЛД - 200 кг п/эт | E14: 250226 | F14: 16000 | G14: 80 | H14: Лабытнанги | I14: отгружено | J14: 46092 | K14: 20 поддонов | N14: GQRU0000200 | Q14: 16000 | R14: + | S14: 155000 | T14: =S14*F14/1000 -> 2480000
A15: кнт (Клото) | B15: Спец№4(2-5) | C15: Комар эпокси | D15: КЛСП - бум 20,0 кг | E15: 270226 | F15: 6600 | G15: 330 | H15: Лабытнанги | I15: отгружено | J15: 46092 | K15: 11 поддонов | N15: TKRU3203135 | P15: 6600 | R15: + | S15: 87500 | T15: =S15*F15/1000 -> 577500
A16: кнт (Клото) | B16: Спец№4(2-5) | C16: Комар эпокси | D16: КАРБО-БЛОК Fine - бум 25,0 кг | E16: 240226 | F16: 3000 | G16: 120 | H16: Лабытнанги | I16: отгружено | J16: 46092 | K16: 4 поддона | N16: TKRU3203135 | P16: 3000 | R16: + | S16: 206000 | T16: =S16*F16/1000 -> 618000
A17: кнт (Клото) | B17: Спец№4(2-5) | C17: Комар эпокси | D17: КАРБО-БЛОК Medium - бум 25,0 кг | E17: 240226 | F17: 2250 | G17: 90 | H17: Лабытнанги | I17: отгружено | J17: 46092 | K17: 3 поддона | N17: TKRU3203135 | P17: 2250 | R17: + | S17: 206000 | T17: =S17*F17/1000 -> 463500
A18: кнт (Клото) | B18: Спец№4(2-5) | C18: Комар эпокси | D18: КАРБО-БЛОК Coarse - бум 25,0 кг | E18: 240226 | F18: 1250 | G18: 50 | H18: Лабытнанги | I18: отгружено | J18: 46092 | K18: 1 под х 30 меш + 1 под х 20 меш | N18: TKRU3203135 | P18: 1250 | R18: + | S18: 206000 | T18: =S18*F18/1000 -> 257500
A19: кнт (Клото) | B19: Спец№4(3-5) | C19: Комар эпокси | D19: Оптитрол п - бум 20,0 кг | E19: 030326 | F19: 11600 | G19: 580 | H19: Лабытнанги | I19: отгружено | J19: 46092 | K19: 19 под х 30 меш + 1 под х 10 меш | N19: TKRU3018395 | P19: 11600 | R19: + | S19: 78500 | T19: =S19*F19/1000 -> 910600
A20: кнт (Клото) | B20: Спец№4(3-5) | C20: Комар эпокси | D20: КЛСП - бум 20,0 кг | E20: 270226 | F20: 400 | G20: 20 | H20: Лабытнанги | I20: отгружено | J20: 46092 | K20: 1 под х 20 меш | N20: TKRU3018395 | P20: 400 | R20: + | S20: 87500 | T20: =S20*F20/1000 -> 35000
A21: кнт (Клото) | B21: Спец№4(4-5) | C21: Комар эпокси | D21: КЛСП - бум 20,0 кг | E21: 270226 | F21: 12000 | G21: 600 | H21: Лабытнанги | I21: отгружено | J21: 46092 | K21: 20 поддонов | N21: TKRU3473594 | P21: 12000 | R21: + | S21: 87500 | T21: =S21*F21/1000 -> 1050000
A22: кнт (Клото) | B22: Спец№4(5-5) | C22: Комар эпокси | D22: Оптитрол п - бум 20,0 кг | E22: 030326 | F22: 12000 | G22: 600 | H22: Лабытнанги | I22: отгружено | J22: 46092 | K22: 20 поддонов | N22: GQRU3309472 | P22: 12000 | R22: + | S22: 78500 | T22: =S22*F22/1000 -> 942000
A23: Самовывоз | B23: Счет №24 от 24.02.26 | C23: НГС | D23: АПП-490, бочка п/э 200кг | E23: 03-26 | F23: 600 | G23: 3 | H23: Самовывоз | I23: отгружено | J23: 46094 | K23: DAF В484ХС18 | L23: 89128578010 | M23: Антипов Алексей | Q23: 600 | R23: + | S23: 330000 | T23: =S23*F23/1000 -> 198000
A24: авто(Борисов) | B24: Спец№44 (3-4) | C24: МАДСЕРВИС | D24: Сульф асф - бум 25,0 кг | E24: 160226 | F24: 20000 | G24: 800 | H24: Самара | I24: отгружено | J24: 46098 | K24: Mercedes О515ОУ29 | L24: 89115800204 | M24: Борисов Дмитрий | O24: 20000 | R24: + | S24: 44500 | T24: =S24*F24/1000 -> 890000
A25: авто(Клото) | B25: БС-129358 | C25: БурСервис | D25: EZ BUR DP (Поликап) - бум 25,0 кг | E25: 120326 | F25: 17500 | G25: 700 | H25: Демьянка | I25: отгружено | J25: 46098 | L25: СОГЛАСОВАНА СТАВКА 300 300 | N25: TKRU3100266 | P25: 17500 | R25: + | S25: 265000 | T25: =S25*F25/1000 -> 4637500
A26: авто(Рич Трак) | B26: Спец№44 (4-4) | C26: МАДСЕРВИС | D26: Сульф асф - бум 25,0 кг | E26: 160226 | F26: 20000 | G26: 800 | H26: Самара | I26: отгружено | J26: 46099 | K26: SHACMAN М003ВЕ702 | L26: 89177372854 | M26: Ардаширов Фанил | O26: 20000 | R26: + | S26: 44500 | T26: =S26*F26/1000 -> 890000
A27: кнт(Самовывоз) | B27: БС-133281 | C27: БурСервис | D27: BURFLC - бум 25,0 кг | E27: 171025/1 | F27: 4375 | G27: 175 | H27: Пурпе | I27: отгружено | J27: 46099 | K27: МАЗ М326ОХ29 | L27: 89815516137 | M27: Чернаков Константин | N27: TKRU3050680 | O27: 4375 | R27: + | S27: 41000 | T27: =S27*F27/1000 -> 179375
A28: кнт(Самовывоз) | B28: БС-133281 | C28: БурСервис | D28: BURFLC - бум 25,0 кг | E28: 171025/2 | F28: 4375 | G28: 175 | H28: Пурпе | I28: отгружено | J28: 46099 | K28: МАЗ М326ОХ29 | L28: 89815516137 | M28: Чернаков Константин | N28: TKRU3050680 | O28: 4375 | R28: + | S28: 41000 | T28: =S28*F28/1000 -> 179375
A29: кнт(Самовывоз) | B29: БС-133281 | C29: БурСервис | D29: BURFLC - бум 25,0 кг | E29: 171025/3 | F29: 4375 | G29: 175 | H29: Пурпе | I29: отгружено | J29: 46099 | K29: МАЗ М326ОХ29 | L29: 89815516137 | M29: Чернаков Константин | N29: TKRU3050680 | O29: 4375 | R29: + | S29: 41000 | T29: =S29*F29/1000 -> 179375
A30: кнт(Самовывоз) | B30: БС-133281 | C30: БурСервис | D30: BURFLC - бум 25,0 кг | E30: 171025/4 | F30: 4375 | G30: 175 | H30: Пурпе | I30: отгружено | J30: 46099 | K30: МАЗ М326ОХ29 | L30: 89815516137 | M30: Чернаков Константин | N30: TKRU3050680 | O30: 4375 | R30: + | S30: 41000 | T30: =S30*F30/1000 -> 179375
A31: кнт(Самовывоз) | B31: БС-133959 | C31: БурСервис | D31: BURFLC - бум 25,0 кг | E31: 281025/1 | F31: 4375 | G31: 175 | H31: Пурпе | I31: отгружено | J31: 46099 | K31: МАЗ М326ОХ29 | L31: 89815516137 | M31: Чернаков Константин | N31: TKRU3560370 | O31: 4375 | R31: + | S31: 41000 | T31: =S31*F31/1000 -> 179375
A32: кнт(Самовывоз) | B32: БС-133959 | C32: БурСервис | D32: BURFLC - бум 25,0 кг | E32: 281025/2 | F32: 4375 | G32: 175 | H32: Пурпе | I32: отгружено | J32: 46099 | K32: МАЗ М326ОХ29 | L32: 89815516137 | M32: Чернаков Константин | N32: TKRU3560370 | O32: 4375 | R32: + | S32: 41000 | T32: =S32*F32/1000 -> 179375
A33: кнт(Самовывоз) | B33: БС-133959 | C33: БурСервис | D33: BURFLC - бум 25,0 кг | E33: 281025/3 | F33: 4375 | G33: 175 | H33: Пурпе | I33: отгружено | J33: 46099 | K33: МАЗ М326ОХ29 | L33: 89815516137 | M33: Чернаков Константин | N33: TKRU3560370 | O33: 4375 | R33: + | S33: 41000 | T33: =S33*F33/1000 -> 179375
A34: кнт(Самовывоз) | B34: БС-133959 | C34: БурСервис | D34: BURFLC - бум 25,0 кг | E34: 281025/4 | F34: 4375 | G34: 175 | H34: Пурпе | I34: отгружено | J34: 46099 | K34: МАЗ М326ОХ29 | L34: 89815516137 | M34: Чернаков Константин | N34: TKRU3560370 | O34: 4375 | R34: + | S34: 41000 | T34: =S34*F34/1000 -> 179375
A35: авто(Инкам) | B35: Спец№105К | C35: ОМАС | D35: Сульф асф - бум 25,0 кг | E35: 03/2025 | F35: 20000 | G35: 800 | H35: Нижневартовск | I35: отгружено | J35: 46104 | K35: DAF О539ОН29 | L35: 89216700606 | M35: Хрущ Александр | O35: 20000 | R35: + | S35: 44500 | T35: =S35*F35/1000 -> 890000
A36: авто(Рич Трак) | B36: Спец№47 | C36: МАДСЕРВИС | D36: ПОЛИТРОЛ - 200 кг п/эт | E36: 181225 | F36: 4000 | G36: 20 | H36: Бузулук | I36: отгружено | J36: 46104 | K36: Shacman М770КР763 | L36: 89179672527 | M36: Коженов Андрей | Q36: 4000 | R36: + | S36: 127000 | T36: =S36*F36/1000 -> 508000
A37: авто(Рич Трак) | B37: Спец№47 | C37: МАДСЕРВИС | D37: ДЖИ-ДРИЛЛ - 200 кг п/эт | E37: 051225 | F37: 4000 | G37: 20 | H37: Бузулук | I37: отгружено | J37: 46104 | K37: Shacman М770КР763 | L37: 89179672527 | M37: Коженов Андрей | Q37: 4000 | R37: + | S37: 97000 | T37: =S37*F37/1000 -> 388000
A38: авто(Рич Трак) | B38: Спец№47 | C38: МАДСЕРВИС | D38: Сульф асф - бум 25,0 кг | E38: 160226 | F38: 12000 | G38: 480 | H38: Бузулук | I38: отгружено | J38: 46104 | K38: Shacman М770КР763 | L38: 89179672527 | M38: Коженов Андрей | O38: 12000 | R38: + | S38: 44500 | T38: =S38*F38/1000 -> 534000
A39: авто(Ариал) | B39: БС-131135 | C39: БурСервис | D39: BUR MUL NTR (Экстрамул Суприм), бочка п/э 190 кг | E39: 260226 | F39: 8360 | G39: 44 | H39: Пыть-Ях | I39: отгружено | J39: 46105 | K39: Вольво Т838ВМ196 | L39: 89090041850 | M39: Белоусов Денис | Q39: 8360 | R39: + (24.03) | S39: 125000 | T39: =S39*F39/1000 -> 1045000
A40: авто(Ариал) | B40: БС-131135 | C40: БурСервис | D40: BUR MUL NTR (Экстрамул Суприм), бочка п/э 190 кг | E40: 270226 | F40: 8360 | G40: 44 | H40: Пыть-Ях | I40: отгружено | J40: 46105 | K40: Вольво Т838ВМ196 | L40: 89090041850 | M40: Белоусов Денис | Q40: 8360 | R40: + (24.03) | S40: 125000 | T40: =S40*F40/1000 -> 1045000
A41: авто(Агро) | B41: Спец№49 | C41: МАДСЕРВИС | D41: Сульф асф - бум 25,0 кг | E41: 160226 | F41: 20000 | G41: 800 | H41: Пыть-Ях | I41: отгружено | J41: 46105 | K41: Ситрак Е806ОР156 | L41: 89877987973 | M41: Онохин Евгений | O41: 20000 | R41: + | S41: 44500 | T41: =S41*F41/1000 -> 890000
...

Sheet февраль 2026
B1: ОТГРУЗКИ ПРОДУКЦИИ | C1: 46054
A2: заметки | B2: НОМЕР ЗАКАЗА | C2: КЛИЕНТ | D2: ПРОДУКТ | E2: ПАРТИЯ | F2: КОЛИЧЕСТВО | H2: ПУНКТ НАЗНАЧЕНИЯ | I2: СТАТУС | J2: ДАТА ОТГРУЗКИ | K2: АВТОДОСТАВКА | N2: ЖД ДОСТАВКА | O2: ИТОГО ОТГРУЖЕНО | R2: АКТЫ | S2: Цена со склада за 1 тонну
F3: КГ | G3: мешков/бочек | K3: № АВТО | L3: ТЕЛ. ВОДИТЕЛЯ | M3: ВОДИТЕЛЬ | N3: № КОНТЕЙНЕРА/ВАГОНА | O3: ЧП | P3: ИНАЯ | Q3: Жидкий | T3: Итого
A5: авто(Ариал) | B5: 01/50/14/09/10 (6-10) | C5: Сургутнефтегаз | D5: Оптитрол Ж - 200 кг п/эт | E5: 190126/1 | F5: 2400 | G5: 12 | H5: Сургут. Белый Яр | I5: отгружено | J5: 46055 | K5: ВОЛЬВО О951РК72 | L5: 89966862434 | M5: Добрыдин Станислав | Q5: 2400 | R5: + | S5: 85500 | T5: =S5*F5/1000 -> 205200
A6: авто(Ариал) | B6: 01/50/14/09/10 (6-10) | C6: Сургутнефтегаз | D6: Оптитрол Ж - 200 кг п/эт | E6: 200126 | F6: 7200 | G6: 36 | H6: Сургут. Белый Яр | I6: отгружено | J6: 46055 | K6: ВОЛЬВО О951РК72 | L6: 89966862434 | M6: Добрыдин Станислав | Q6: 7200 | R6: + | S6: 85500 | T6: =S6*F6/1000 -> 615600
A7: авто(Ариал) | B7: 01/50/14/09/10 (6-10) | C7: Сургутнефтегаз | D7: Оптитрол Ж - 200 кг п/эт | E7: 210126 | F7: 4800 | G7: 24 | H7: Сургут. Белый Яр | I7: отгружено | J7: 46055 | K7: ВОЛЬВО О951РК72 | L7: 89966862434 | M7: Добрыдин Станислав | Q7: 4800 | R7: + | S7: 85500 | T7: =S7*F7/1000 -> 410400
A8: авто(Ариал) | B8: 01/50/14/09/10 (6-10) | C8: Сургутнефтегаз | D8: Оптитрол Ж - 200 кг п/эт | E8: 220126 | F8: 3200 | G8: 16 | H8: Сургут. Белый Яр | I8: отгружено | J8: 46055 | K8: ВОЛЬВО О951РК72 | L8: 89966862434 | M8: Добрыдин Станислав | Q8: 3200 | R8: + | S8: 85500 | T8: =S8*F8/1000 -> 273600
A9: авто(Агро) | B9: Спец№51(1-2) | C9: Буринтех | D9: СУЛЬФОБИТ - бум 25,0 кг | E9: 261225 | F9: 20000 | G9: 800 | H9: Пыть-Ях | I9: отгружено | J9: 46055 | K9: Скания Е999СЕ156 | L9: 89228293405 | M9: Корнилов Дмитрий | O9: 20000 | R9: + | S9: 41500 | T9: =S9*F9/1000 -> 830000
A10: авто(Агро) | B10: Спец№43 | C10: МАДСЕРВИС | D10: Сульф асф - бум 25,0 кг | E10: 040625 | F10: 10000 | G10: 400 | H10: Самара | I10: отгружено | J10: 46055 | K10: РЕНО Н451МС196 | L10: 89923370709 | M10: Дудин Андрей | O10: 10000 | R10: + | S10: 44500 | T10: =S10*F10/1000 -> 445000
A11: авто(Агро) | B11: Спец№43 | C11: МАДСЕРВИС | D11: BLACKTROL ж - 200 кг п/эт | E11: 090425 | F11: 9600 | G11: 48 | H11: Самара | I11: отгружено | J11: 46055 | K11: РЕНО Н451МС196 | L11: 89923370709 | M11: Дудин Андрей | Q11: 9600 | R11: + | S11: 89000 | T11: =S11*F11/1000 -> 854400
A12: авто(Ариал) | B12: 01/50/14/09/10 (7-10) | C12: Сургутнефтегаз | D12: Оптитрол Ж - 200 кг п/эт | E12: 220126 | F12: 3200 | G12: 16 | H12: Сургут. Белый Яр | I12: отгружено | J12: 46056 | K12: Камаз М428АН702 | L12: 89174985876 | M12: Андриянов Андрей | Q12: 3200 | R12: + | S12: 85500 | T12: =S12*F12/1000 -> 273600
A13: авто(Ариал) | B13: 01/50/14/09/10 (7-10) | C13: Сургутнефтегаз | D13: Оптитрол Ж - 200 кг п/эт | E13: 230126 | F13: 7200 | G13: 36 | H13: Сургут. Белый Яр | I13: отгружено | J13: 46056 | K13: Камаз М428АН702 | L13: 89174985876 | M13: Андриянов Андрей | Q13: 7200 | R13: + | S13: 85500 | T13: =S13*F13/1000 -> 615600
A14: авто(Ариал) | B14: 01/50/14/09/10 (7-10) | C14: Сургутнефтегаз | D14: Оптитрол Ж - 200 кг п/эт | E14: 290126 | F14: 6400 | G14: 32 | H14: Сургут. Белый Яр | I14: отгружено | J14: 46056 | K14: Камаз М428АН702 | L14: 89174985876 | M14: Андриянов Андрей | Q14: 6400 | R14: + | S14: 85500 | T14: =S14*F14/1000 -> 547200
A15: авто(Ариал) | B15: 01/50/14/09/10 (7-10) | C15: Сургутнефтегаз | D15: Оптитрол Ж - 200 кг п/эт | E15: 300126 | F15: 800 | G15: 4 | H15: Сургут. Белый Яр | I15: отгружено | J15: 46056 | K15: Камаз М428АН702 | L15: 89174985876 | M15: Андриянов Андрей | Q15: 800 | R15: + | S15: 85500 | T15: =S15*F15/1000 -> 68400
A16: авто(Агро) | B16: Спец№2-СТ (3-14) | C16: ССК | D16: Стабилайт II - бум марк 25,0 кг | E16: 300126 | F16: 20000 | G16: 800 | H16: Нягань | I16: отгружено | J16: 46056 | K16: Вольво В434РА702 | L16: 89371557300 | M16: Решетин Александр | O16: 20000 | R16: + | S16: 43500 | T16: =S16*F16/1000 -> 870000
A17: авто(Ариал) | B17: Спец№2-СТ (4-14) | C17: ССК | D17: Стабилайт II - бум марк 25,0 кг | E17: 020226 | F17: 20000 | G17: 800 | H17: Нягань | I17: отгружено | J17: 46057 | K17: Камаз М701УТ69 | L17: 89068273915 | M17: Болдырев Владимир | O17: 20000 | R17: + | S17: 43500 | T17: =S17*F17/1000 -> 870000
A18: авто(Шмакова) | B18: 01/50/14/09/10 (8-10) | C18: Сургутнефтегаз | D18: Оптитрол Ж - 200 кг п/эт | E18: 300126 | F18: 6400 | G18: 32 | H18: Сургут. Белый Яр | I18: отгружено | J18: 46058 | K18: DAF К298МО45 | L18: 89080063420 | M18: Антонов Евгений | Q18: 6400 | R18: + | S18: 85500 | T18: =S18*F18/1000 -> 547200
A19: авто(Шмакова) | B19: 01/50/14/09/10 (8-10) | C19: Сургутнефтегаз | D19: Оптитрол Ж - 200 кг п/эт | E19: 310126 | F19: 7200 | G19: 36 | H19: Сургут. Белый Яр | I19: отгружено | J19: 46058 | K19: DAF К298МО45 | L19: 89080063420 | M19: Антонов Евгений | Q19: 7200 | R19: + | S19: 85500 | T19: =S19*F19/1000 -> 615600
A20: авто(Шмакова) | B20: 01/50/14/09/10 (8-10) | C20: Сургутнефтегаз | D20: Оптитрол Ж - 200 кг п/эт | E20: 310126/1 | F20: 4000 | G20: 20 | H20: Сургут. Белый Яр | I20: отгружено | J20: 46058 | K20: DAF К298МО45 | L20: 89080063420 | M20: Антонов Евгений | Q20: 4000 | R20: + | S20: 85500 | T20: =S20*F20/1000 -> 342000
A21: авто(Коровин) | B21: Спец№2-СТ (5-14) | C21: ССК | D21: Стабилайт II - бум марк 25,0 кг | E21: 030226 | F21: 20000 | G21: 800 | H21: Нягань | I21: отгружено | J21: 46058 | K21: DAF В426МХ45 | L21: 89125754867 | M21: Анфалов Сергей | O21: 20000 | R21: + | S21: 43500 | T21: =S21*F21/1000 -> 870000
A22: самовывоз | B22: Спец. №3 | C22: FWL | D22: ЭКСТРАМУЛ-2000 - 180 кг мет | E22: 020226 | F22: 11520 | G22: 64 | H22: Самовывоз | I22: отгружено | J22: 46058 | K22: КАМАЗ А188УО 43 | M22: Тайбарей Гавриил | Q22: 11520 | R22: + | S22: 127500 | T22: =S22*F22/1000 -> 1468800
A23: самовывоз | B23: Спец. №3 | C23: FWL | D23: ЛИКВИТРОЛ - 180 кг мет | E23: 030226 | F23: 2880 | G23: 16 | H23: Самовывоз | I23: отгружено | J23: 46058 | K23: КАМАЗ А188УО 43 | M23: Тайбарей Гавриил | Q23: 2880 | R23: + | S23: 160000 | T23: =S23*F23/1000 -> 460800
A24: авто(Клото) | B24: Спец№42 | C24: МАДСЕРВИС | D24: Сульф асф - бум 25,0 кг | E24: 050424 | F24: 20000 | G24: 800 | H24: Бузулук | I24: отгружено | J24: 46059 | K24: Mercedes О515ОУ29 | L24: 89115800204 | M24: Борисов Дмитрий | O24: 20000 | R24: + | S24: 44500 | T24: =S24*F24/1000 -> 890000
A25: авто(Ариал) | B25: 01/50/14/09/10 (9-10) | C25: Сургутнефтегаз | D25: Оптитрол Ж - 200 кг п/эт | E25: 310126/1 | F25: 2400 | G25: 12 | H25: Сургут. Белый Яр | I25: отгружено | J25: 46059 | K25: Вольво Т838ВМ196 | L25: 89090041850 | M25: Белоусов Денис | Q25: 2400 | R25: + | S25: 85500 | T25: =S25*F25/1000 -> 205200
A26: авто(Ариал) | B26: 01/50/14/09/10 (9-10) | C26: Сургутнефтегаз | D26: BLACKTROL ж - 200 кг п/эт | E26: 210126 | F26: 8800 | G26: 44 | H26: Сургут. Белый Яр | I26: отгружено | J26: 46059 | K26: Вольво Т838ВМ196 | L26: 89090041850 | M26: Белоусов Денис | Q26: 8800 | R26: + | S26: 94500 | T26: =S26*F26/1000 -> 831600
A27: авто(Ариал) | B27: 01/50/14/09/10 (9-10) | C27: Сургутнефтегаз | D27: BLACKTROL ж - 200 кг п/эт | E27: 220126 | F27: 6400 | G27: 32 | H27: Сургут. Белый Яр | I27: отгружено | J27: 46059 | K27: Вольво Т838ВМ196 | L27: 89090041850 | M27: Белоусов Денис | Q27: 6400 | R27: + | S27: 94500 | T27: =S27*F27/1000 -> 604800
A28: авто(Горкий Транзит) | B28: RSH7.MDS.R-25-0800-013214 | C28: ТКШ | D28: АДВАНТА п - бум 14,0 кг | E28: 040226 | F28: 14000 | G28: 1000 | H28: Холмск | I28: отгружено | J28: 46063 | K28: Скания Т369СО152 | L28: 89224245220/89146819608 | M28: Звонарев Алексей | P28: 14000 | R28: + | S28: 317000 | T28: =S28*F28/1000 -> 4438000
A29: авто(Инкам) | B29: 01/50/14/09/10 (10-10) | C29: Сургутнефтегаз | D29: Оптитрол Ж - 200 кг п/эт | E29: 310126/1 | F29: 800 | G29: 4 | H29: Сургут. Белый Яр | I29: отгружено | J29: 46063 | K29: DAF О539ОН29 | L29: 89216700606 | M29: Хрущ Александр | Q29: 800 | R29: + | S29: 85500 | T29: =S29*F29/1000 -> 68400
A30: авто(Инкам) | B30: 01/50/14/09/10 (10-10) | C30: Сургутнефтегаз | D30: Оптитрол Ж - 200 кг п/эт | E30: 010226 | F30: 4800 | G30: 24 | H30: Сургут. Белый Яр | I30: отгружено | J30: 46063 | K30: DAF О539ОН29 | L30: 89216700606 | M30: Хрущ Александр | Q30: 4800 | R30: + | S30: 85500 | T30: =S30*F30/1000 -> 410400
A31: авто(Инкам) | B31: 01/50/14/09/10 (10-10) | C31: Сургутнефтегаз | D31: Оптитрол Ж - 200 кг п/эт | E31: 010226/1 | F31: 7200 | G31: 36 | H31: Сургут. Белый Яр | I31: отгружено | J31: 46063 | K31: DAF О539ОН29 | L31: 89216700606 | M31: Хрущ Александр | Q31: 7200 | R31: + | S31: 85500 | T31: =S31*F31/1000 -> 615600
A32: авто(Инкам) | B32: 01/50/14/09/10 (10-10) | C32: Сургутнефтегаз | D32: Оптитрол Ж - 200 кг п/эт | E32: 050226 | F32: 4800 | G32: 24 | H32: Сургут. Белый Яр | I32: отгружено | J32: 46063 | K32: DAF О539ОН29 | L32: 89216700606 | M32: Хрущ Александр | Q32: 4800 | R32: + | S32: 85500 | T32: =S32*F32/1000 -> 410400
A33: авто(Бакин) | B33: Спец№2-СТ (6-14) | C33: ССК | D33: Стабилайт II - бум марк 25,0 кг | E33: 151025 | F33: 20000 | G33: 800 | H33: Нягань | I33: отгружено | J33: 46065 | K33: Вольво Р034СВ29 | L33: 89212974613 | M33: Киреев Сергей | O33: 20000 | R33: + | S33: 43500 | T33: =S33*F33/1000 -> 870000
A34: Самовывоз | B34: Спец№2 | C34: Прогресс-2 | D34: BLACKTROL ж - 200 кг п/эт | E34: 180625 | F34: 2000 | G34: 10 | H34: Самовыовз | I34: отгружено | J34: 46066 | K34: Газель У078НУ797 | L34: 89398007409 | M34: Скрябин Иван | Q34: 2000 | R34: + | S34: 111000 | T34: =S34*F34/1000 -> 222000
A35: авто(Ариал) | B35: Спец№2-СТ (7-14) | C35: ССК | D35: Стабилайт II - бум марк 25,0 кг | E35: 050226 | F35: 20000 | G35: 800 | H35: Нягань | I35: отгружено | J35: 46069 | K35: Ситрак С105ОР196 | L35: 89827655793 | M35: Новиков Сергей | O35: 20000 | R35: + | S35: 43500 | T35: =S35*F35/1000 -> 870000
A36: авто(Агро) | B36: Спец№2-СТ (8-14) | C36: ССК | D36: Стабилайт II - бум марк 25,0 кг | E36: 120226 | F36: 20000 | G36: 800 | H36: Нягань | I36: отгружено | J36: 46069 | K36: РЕНО Н451МС196 | L36: 89923370709 | M36: Дудин Андрей | O36: 20000 | R36: + | S36: 43500 | T36: =S36*F36/1000 -> 870000
A37: авто(Ариал) | B37: Спец№55 | C37: Инко-Сервис | D37: ЭКСТРАМУЛ-2000 - 200 кг п/эт | E37: 20260209 | F37: 12000 | G37: 60 | H37: Демьянка | I37: отгружено | J37: 46069 | K37: Даф Х901КС72 | L37: 89129296888 | M37: Солянников Дмитрий | Q37: 12000 | R37: + | S37: 122000 | T37: =S37*F37/1000 -> 1464000
A38: авто(Ариал) | B38: Спец№55 | C38: Инко-Сервис | D38: IN-MOD (РЕОМОД) - бум 18,0 кг | E38: 20260210 | F38: 2880 | G38: 160 | H38: Демьянка | I38: отгружено | J38: 46069 | K38: Даф Х901КС72 | L38: 89129296888 | M38: Солянников Дмитрий | P38: 2880 | R38: + | S38: 220000 | T38: =S38*F38/1000 -> 633600
A39: авто(Ариал) | B39: Спец№55 | C39: Инко-Сервис | D39: ВЕЛЛТРИТ - 200 кг п/эт | E39: 20260209 | F39: 2400 | G39: 12 | H39: Демьянка | I39: отгружено | J39: 46069 | K39: Даф Х901КС72 | L39: 89129296888 | M39: Солянников Дмитрий | Q39: 2400 | R39: + | S39: 157000 | T39: =S39*F39/1000 -> 376800
A40: авто(Рич Трак) | B40: Спец№102К (1-2) | C40: ОМАС | D40: Сульф асф - бум 25,0 кг | E40: 03/2025 | F40: 10000 | G40: 400 | H40: Нижневартовск | I40: отгружено | J40: 46070 | K40: SHACMAN К789ОЕ702 | L40: 89273333787 | M40: Ременников Александр | O40: 10000 | R40: + | S40: 44500 | T40: =S40*F40/1000 -> 445000
A41: авто(Рич Трак) | B41: Спец№102К (1-2) | C41: ОМАС | D41: ТЕРРАПАН - бум 25,0 кг | E41: 10/2025 | F41: 10000 | G41: 400 | H41: Нижневартовск | I41: отгружено | J41: 46070 | K41: SHACMAN К789ОЕ702 | L41: 89273333787 | M41: Ременников Александр | P41: 10000 | R41: + | S41: 250000 | T41: =S41*F41/1000 -> 2500000
...

Sheet январь 2026
B1: ОТГРУЗКИ ПРОДУКЦИИ | C1: 46023
A2: заметки | B2: НОМЕР ЗАКАЗА | C2: КЛИЕНТ | D2: ПРОДУКТ | E2: ПАРТИЯ | F2: КОЛИЧЕСТВО | H2: ПУНКТ НАЗНАЧЕНИЯ | I2: СТАТУС | J2: ДАТА ОТГРУЗКИ | K2: АВТОДОСТАВКА | N2: ЖД ДОСТАВКА | O2: ИТОГО ОТГРУЖЕНО | R2: АКТЫ | S2: Цена со склада за 1 тонну
F3: КГ | G3: мешков/бочек | K3: № АВТО | L3: ТЕЛ. ВОДИТЕЛЯ | M3: ВОДИТЕЛЬ | N3: № КОНТЕЙНЕРА/ВАГОНА | O3: ЧП | P3: ИНАЯ | Q3: Жидкий | T3: Итого
A5: авто(Гандвик) | B5: Спец№98К(3-4) | C5: ОМАС | D5: Сульф асф - бум 25,0 кг | E5: 03/2025 | F5: 20000 | G5: 800 | H5: Пыть-Ях | I5: отгружен | J5: 46034 | K5: DAF 0898AO29 | L5: 89991681050 | M5: Парфенов Роман | O5: 20000 | R5: + | S5: 44500 | T5: =S5*F5/1000 -> 890000
A6: авто(Гандвик) | B6: Спец№98К(4-4) | C6: ОМАС | D6: Сульф асф - бум 25,0 кг | E6: 03/2025 | F6: 20000 | G6: 800 | H6: Пыть-Ях | I6: отгружен | J6: 46034 | K6: DAF 0922KM29 | L6: 89214819561 | M6: Тимохин Виталий | O6: 20000 | R6: + | S6: 44500 | T6: =S6*F6/1000 -> 890000
A7: авто(Гандвик) | B7: Спец№99К | C7: ОМАС | D7: Сульф асф - бум 25,0 кг | E7: 03/2025 | F7: 20000 | G7: 800 | H7: Нижневартовск | I7: отгружен | J7: 46034 | K7: DAF M910РУ29 | L7: 89116853405 | M7: Вишняков Денис | O7: 20000 | R7: + | S7: 44500 | T7: =S7*F7/1000 -> 890000
A8: авто(Гандвик) | B8: Спец№54 | C8: Инко-Сервис | D8: ЭКСТРАМУЛ-2000 - 200 кг п/эт | E8: 20250627 | F8: 17600 | G8: 88 | H8: Волгоград | I8: отгружен | J8: 46035 | K8: VOLVO О917МХ29 | L8: 89116853272 | M8: Гужихин Сергей | Q8: 17600 | R8: + | S8: 128000 | T8: =S8*F8/1000 -> 2252800
A9: авто(Ванюхин) | B9: Спец№24 (5-6) | C9: КазПетроДриллинг | D9: Оптитрол Ж - 200 кг п/эт | E9: 221225 | F9: 800 | G9: 4 | H9: Жанаозен | I9: отгружен | J9: 46037 | K9: Меrсеdеs Р039ВВ250 | L9: 89773804045 | M9: Котов Денис | Q9: 800 | R9: + | S9: 82000 | T9: =S9*F9/1000 -> 65600
A10: авто(Ванюхин) | B10: Спец№24 (5-6) | C10: КазПетроДриллинг | D10: Оптитрол Ж - 200 кг п/эт | E10: 231225 | F10: 6400 | G10: 32 | H10: Жанаозен | I10: отгружен | J10: 46037 | K10: Меrсеdеs Р039ВВ250 | L10: 89773804045 | M10: Котов Денис | Q10: 6400 | R10: + | S10: 82000 | T10: =S10*F10/1000 -> 524800
A11: авто(Ванюхин) | B11: Спец№24 (5-6) | C11: КазПетроДриллинг | D11: Оптитрол Ж - 200 кг п/эт | E11: 241225 | F11: 7200 | G11: 36 | H11: Жанаозен | I11: отгружен | J11: 46037 | K11: Меrсеdеs Р039ВВ250 | L11: 89773804045 | M11: Котов Денис | Q11: 7200 | R11: + | S11: 82000 | T11: =S11*F11/1000 -> 590400
A12: авто(Ванюхин) | B12: Спец№24 (5-6) | C12: КазПетроДриллинг | D12: Оптитрол Ж - 200 кг п/эт | E12: 251225 | F12: 3200 | G12: 16 | H12: Жанаозен | I12: отгружен | J12: 46037 | K12: Меrсеdеs Р039ВВ250 | L12: 89773804045 | M12: Котов Денис | Q12: 3200 | R12: + | S12: 82000 | T12: =S12*F12/1000 -> 262400
A13: авто(Ванюхин) | B13: Спец№24 (6-6) | C13: КазПетроДриллинг | D13: Оптитрол Ж - 200 кг п/эт | E13: 041225 | F13: 2400 | G13: 12 | H13: Жанаозен | I13: отгружен | J13: 46038 | K13: DAF У690РК790 | L13: 89273817812/87773777323 | M13: Поpтнов Дмитрий | Q13: 2400 | R13: + | S13: 82000 | T13: =S13*F13/1000 -> 196800
A14: авто(Ванюхин) | B14: Спец№24 (6-6) | C14: КазПетроДриллинг | D14: Оптитрол Ж - 200 кг п/эт | E14: 091225 | F14: 2400 | G14: 12 | H14: Жанаозен | I14: отгружен | J14: 46038 | K14: DAF У690РК790 | L14: 89273817812/87773777323 | M14: Поpтнов Дмитрий | Q14: 2400 | R14: + | S14: 82000 | T14: =S14*F14/1000 -> 196800
A15: авто(Ванюхин) | B15: Спец№24 (6-6) | C15: КазПетроДриллинг | D15: Оптитрол Ж - 200 кг п/эт | E15: 211225 | F15: 6400 | G15: 32 | H15: Жанаозен | I15: отгружен | J15: 46038 | K15: DAF У690РК790 | L15: 89273817812/87773777323 | M15: Поpтнов Дмитрий | Q15: 6400 | R15: + | S15: 82000 | T15: =S15*F15/1000 -> 524800
A16: авто(Ванюхин) | B16: Спец№24 (6-6) | C16: КазПетроДриллинг | D16: Оптитрол Ж - 200 кг п/эт | E16: 221225 | F16: 6400 | G16: 32 | H16: Жанаозен | I16: отгружен | J16: 46038 | K16: DAF У690РК790 | L16: 89273817812/87773777323 | M16: Поpтнов Дмитрий | Q16: 6400 | R16: + | S16: 82000 | T16: =S16*F16/1000 -> 524800
A17: авто(Бакин) | B17: Спец№54 | C17: Инко-Сервис | D17: Сульф асф - бум 25,0 кг | E17: 20240819 | F17: 20000 | G17: 800 | H17: Волгоград | I17: отгружен | J17: 46041 | K17: Вольво О618СМ29 | L17: 89991686190 | M17: Попов Александр | O17: 20000 | R17: + | S17: 44300 | T17: =S17*F17/1000 -> 886000
A18: авто(Ариал) | B18: Спец№2-СТ (1-14) | C18: ССК | D18: Стабилайт II - бум марк 25,0 кг | E18: 150126 | F18: 20000 | G18: 800 | H18: Нягань | I18: отгружен | J18: 46041 | K18: Даф Х901КС72 | L18: 89129296888 | M18: Солянников Дмитрий | O18: 20000 | R18: + | S18: 43500 | T18: =S18*F18/1000 -> 870000
A19: авто(Легион) | B19: Спец№2-СТ (2-14) | C19: ССК | D19: Стабилайт II - бум марк 25,0 кг | E19: 160126 | F19: 20000 | G19: 800 | H19: Нягань | I19: отгружен | J19: 46048 | K19: Скания М503СМ159 | L19: 89197101726 | M19: Ракшин Андрей | O19: 20000 | R19: + | S19: 43500 | T19: =S19*F19/1000 -> 870000
A20: авто(авто 45) | B20: 01/50/14/09/10 (1-10) | C20: Сургутнефтегаз | D20: BLACKTROL ж - 200 кг п/эт | E20: 170126 | F20: 8800 | G20: 44 | H20: Сургут. Белый Яр | I20: отгружен | J20: 46049 | K20: КАМАЗ О773НМ45 | L20: 89125770562 | M20: Осипов Дмитрий | Q20: 8800 | R20: + | S20: 94500 | T20: =S20*F20/1000 -> 831600
A21: авто(авто 45) | B21: 01/50/14/09/10 (1-10) | C21: Сургутнефтегаз | D21: BLACKTROL ж - 200 кг п/эт | E21: 180126 | F21: 8800 | G21: 44 | H21: Сургут. Белый Яр | I21: отгружен | J21: 46049 | K21: КАМАЗ О773НМ45 | L21: 89125770562 | M21: Осипов Дмитрий | Q21: 8800 | R21: + | S21: 94500 | T21: =S21*F21/1000 -> 831600
A22: авто(Ариал) | B22: Спец№101К (1-2) | C22: ОМАС | D22: Сульф асф - бум 25,0 кг | E22: 03/2025 | F22: 20000 | G22: 800 | H22: Пыть-Ях | I22: отгружен | J22: 46050 | K22: ВОЛЬВО Е935РО196 | L22: 89126616900 | M22: Соколов Виктор | O22: 20000 | R22: + | S22: 44500 | T22: =S22*F22/1000 -> 890000
A23: авто(Агро) | B23: 01/50/14/09/10 (2-10) | C23: Сургутнефтегаз | D23: Оптитрол Ж - 200 кг п/эт | E23: 150126 | F23: 6400 | G23: 32 | H23: Сургут. Белый Яр | I23: отгружен | J23: 46051 | K23: Камаз Р904НС142 | L23: 89235219222 | M23: Осадчий Александр | Q23: 6400 | R23: + | S23: 85500 | T23: =S23*F23/1000 -> 547200
A24: авто(Агро) | B24: 01/50/14/09/10 (2-10) | C24: Сургутнефтегаз | D24: Оптитрол Ж - 200 кг п/эт | E24: 160126 | F24: 7200 | G24: 36 | H24: Сургут. Белый Яр | I24: отгружен | J24: 46051 | K24: Камаз Р904НС142 | L24: 89235219222 | M24: Осадчий Александр | Q24: 7200 | R24: + | S24: 85500 | T24: =S24*F24/1000 -> 615600
A25: авто(Агро) | B25: 01/50/14/09/10 (2-10) | C25: Сургутнефтегаз | D25: Оптитрол Ж - 200 кг п/эт | E25: 170126 | F25: 4000 | G25: 20 | H25: Сургут. Белый Яр | I25: отгружен | J25: 46051 | K25: Камаз Р904НС142 | L25: 89235219222 | M25: Осадчий Александр | Q25: 4000 | R25: + | S25: 85500 | T25: =S25*F25/1000 -> 342000
A26: авто(Инкам) | B26: 01/50/14/09/10 (3-10) | C26: Сургутнефтегаз | D26: Оптитрол Ж - 200 кг п/эт | E26: 170126 | F26: 2400 | G26: 12 | H26: Сургут. Белый Яр | I26: отгружен | J26: 46051 | K26: DAF К008МА29 | L26: 89116825992 | M26: Белоцерковский Алексей | Q26: 2400 | R26: + | S26: 85500 | T26: =S26*F26/1000 -> 205200
A27: авто(Инкам) | B27: 01/50/14/09/10 (3-10) | C27: Сургутнефтегаз | D27: Оптитрол Ж - 200 кг п/эт | E27: 170126/1 | F27: 8000 | G27: 40 | H27: Сургут. Белый Яр | I27: отгружен | J27: 46051 | K27: DAF К008МА29 | L27: 89116825992 | M27: Белоцерковский Алексей | Q27: 8000 | R27: + | S27: 85500 | T27: =S27*F27/1000 -> 684000
A28: авто(Инкам) | B28: 01/50/14/09/10 (3-10) | C28: Сургутнефтегаз | D28: Оптитрол Ж - 200 кг п/эт | E28: 180126 | F28: 6400 | G28: 32 | H28: Сургут. Белый Яр | I28: отгружен | J28: 46051 | K28: DAF К008МА29 | L28: 89116825992 | M28: Белоцерковский Алексей | Q28: 6400 | R28: + | S28: 85500 | T28: =S28*F28/1000 -> 547200
A29: авто(Инкам) | B29: 01/50/14/09/10 (3-10) | C29: Сургутнефтегаз | D29: Оптитрол Ж - 200 кг п/эт | E29: 180126/1 | F29: 800 | G29: 4 | H29: Сургут. Белый Яр | I29: отгружен | J29: 46051 | K29: DAF К008МА29 | L29: 89116825992 | M29: Белоцерковский Алексей | Q29: 800 | R29: + | S29: 85500 | T29: =S29*F29/1000 -> 68400
A30: авто(Рич Трак) | B30: 01/50/14/09/10 (4-10) | C30: Сургутнефтегаз | D30: Оптитрол Ж - 200 кг п/эт | E30: 180126/1 | F30: 6400 | G30: 32 | H30: Сургут. Белый Яр | I30: отгружен | J30: 46051 | K30: SHACMAN М137ВА702 | L30: 89624401330 | M30: Забелин Степан | Q30: 6400 | R30: + | S30: 85500 | T30: =S30*F30/1000 -> 547200
A31: авто(Рич Трак) | B31: 01/50/14/09/10 (4-10) | C31: Сургутнефтегаз | D31: Оптитрол Ж - 200 кг п/эт | E31: 190126 | F31: 7200 | G31: 36 | H31: Сургут. Белый Яр | I31: отгружен | J31: 46051 | K31: SHACMAN М137ВА702 | L31: 89624401330 | M31: Забелин Степан | Q31: 7200 | R31: + | S31: 85500 | T31: =S31*F31/1000 -> 615600
A32: авто(Рич Трак) | B32: 01/50/14/09/10 (4-10) | C32: Сургутнефтегаз | D32: Оптитрол Ж - 200 кг п/эт | E32: 190126/1 | F32: 4000 | G32: 20 | H32: Сургут. Белый Яр | I32: отгружен | J32: 46051 | K32: SHACMAN М137ВА702 | L32: 89624401330 | M32: Забелин Степан | Q32: 4000 | R32: + | S32: 85500 | T32: =S32*F32/1000 -> 342000
A33: авто(Агро) | B33: Спец№40 | C33: МАДСЕРВИС | D33: ПОЛИТРОЛ - 200 кг п/эт | E33: 181225 | F33: 6400 | G33: 32 | H33: Бузулук | I33: отгружен | J33: 46051 | K33: SHACMAN Н522СР21 | L33: 89877134071 | M33: Куприяшкин Сергей | Q33: 6400 | R33: + | S33: 127000 | T33: =S33*F33/1000 -> 812800
A34: авто(Агро) | B34: Спец№40 | C34: МАДСЕРВИС | D34: ДЖИ-ДРИЛЛ - 200 кг п/эт | E34: 051225 | F34: 6400 | G34: 32 | H34: Бузулук | I34: отгружен | J34: 46051 | K34: SHACMAN Н522СР21 | L34: 89877134071 | M34: Куприяшкин Сергей | Q34: 6400 | R34: + | S34: 97000 | T34: =S34*F34/1000 -> 620800
A35: авто(Агро) | B35: Спец№40 | C35: МАДСЕРВИС | D35: ПОЛИКАП - бум 25,0 кг | E35: 020725 | F35: 2000 | G35: 80 | H35: Бузулук | I35: отгружен | J35: 46051 | K35: SHACMAN Н522СР21 | L35: 89877134071 | M35: Куприяшкин Сергей | P35: 2000 | R35: + | S35: 250000 | T35: =S35*F35/1000 -> 500000
A36: авто(Агро) | B36: Спец№40 | C36: МАДСЕРВИС | D36: Сульф асф - бум 25,0 кг | E36: 050424 | F36: 4000 | G36: 160 | H36: Бузулук | I36: отгружен | J36: 46051 | K36: SHACMAN Н522СР21 | L36: 89877134071 | M36: Куприяшкин Сергей | O36: 4000 | R36: + | S36: 44500 | T36: =S36*F36/1000 -> 178000
A37: авто(Агро) | B37: Спец№41 | C37: МАДСЕРВИС | D37: ТЕРМАВИС РУО - бум 20,0 кг | E37: 301025 | F37: 3000 | G37: 150 | H37: Уфа | I37: отгружен | J37: 46052 | K37: Ситрак C105OP196 | L37: 89827655793 | M37: Новиков Сергей | P37: 3000 | R37: + | S37: 270000 | T37: =S37*F37/1000 -> 810000
A38: авто(Агро) | B38: Спец№41 | C38: МАДСЕРВИС | D38: РЕОМОД ж - 180 кг п/эт | E38: 311025 | F38: 2160 | G38: 12 | H38: Уфа | I38: отгружен | J38: 46052 | K38: Ситрак C105OP196 | L38: 89827655793 | M38: Новиков Сергей | Q38: 2160 | R38: + | S38: 310000 | T38: =S38*F38/1000 -> 669600
A39: авто(Агро) | B39: Спец№41 | C39: МАДСЕРВИС | D39: СТАБИЛАЙТ РУО - бум 25,0 кг | E39: 281025 | F39: 3000 | G39: 120 | H39: Уфа | I39: отгружен | J39: 46052 | K39: Ситрак C105OP196 | L39: 89827655793 | M39: Новиков Сергей | P39: 3000 | R39: + | S39: 70000 | T39: =S39*F39/1000 -> 210000
A40: авто(Агро) | B40: Спец№41 | C40: МАДСЕРВИС | D40: ЭКСТРАМУЛ-2000 - 200 кг п/эт | E40: 291025 | F40: 5600 | G40: 28 | H40: Уфа | I40: отгружен | J40: 46052 | K40: Ситрак C105OP196 | L40: 89827655793 | M40: Новиков Сергей | Q40: 5600 | R40: + | S40: 135000 | T40: =S40*F40/1000 -> 756000
A41: авто(Агро) | B41: Спец№41 | C41: МАДСЕРВИС | D41: Сульф асф - бум 25,0 кг | E41: 050424 | F41: 6000 | G41: 240 | H41: Уфа | I41: отгружен | J41: 46052 | K41: Ситрак C105OP196 | L41: 89827655793 | M41: Новиков Сергей | O41: 6000 | R41: + | S41: 44500 | T41: =S41*F41/1000 -> 267000
...

Sheet справочник
E1: Продукция
A2: Номер авто | B2: ФИО водителя | C2: Телефон | E2: Стабилайт II - бум 25,0 кг
E3: Стабилайт II - бум марк 25,0 кг
A4: АН486473 | B4: Айдаркин | C4: 89626347052 | E4: Стабилайт II - п/проп обезл 25,0 кг
A5: Н555КМ67 | B5: Асташов С | E5: Стабилайт II - п/проп марк 25,0 кг
E6: Стабилайт II - п/проп обезл 22,7 кг
A7: Н252ТУ31 | B7: Бабкин | C7: 89611891048 | E7: Стабилайт II - п/проп марк 22,7 кг
A8: М960ВА159 | B8: Бабушкин | C8: 89822583038 | E8: Сульф асф - п/проп обезл 25,0 кг
E9: Сульф асф - п/проп марк 25,0 кг
A10: С738ХВ96 | B10: Баранов В | C10: 89126876877 | E10: Сульф асф - бум 25,0 кг
A11: О262ЕМ73 | B11: Бахтияров Фарит | C11: 89279885591 | E11: BaraFLC - бум 22,68 кг
A12: Х833ЕС116 | B12: Бачинин | C12: 89172998065 | E12: BaraFLC(0) - бум 22,7 кг
E13: BaraFLC(0) - бум 25,0 кг
E14: BaraFLC - бум 25,0 кг
E15: BURFLC - бум 25,0 кг
A16: Т298ХН96 | B16: Бедарев | C16: 89126661600 | E16: Reasolt - п/проп 22,7 кг
A17: В837УУ159 | B17: Бобыкин | C17: 89824504395 | E17: Reasolt - бум 22,7 кг
A18: М232ЕВ159 | B18: Болотов | C18: 89194660828 | E18: СУЛЬФОБИТ - бум 22,7 кг
E19: СУЛЬФОБИТ - бум 25,0 кг
A20: Е885УР196 | B20: Буртовой | C20: 89012010372 | E20: LG-DRILL - бум 25,0 кг
A21: М773ОВ | B21: Бусыгин | E21: LG-DRILL - п/проп 25,0 кг
A22: У745РВ43 | B22: Бушмелев | E22: СБМСУЛЬФ - бум 25,0 кг
E23: АСФАСОЛ - бум 25,0 кг
E24: Асфальтен SAS Bur - бум 25,0 кг
E25: Petro ASF - бум 25,0 кг
E26: Atren SL - бум 25,0 кг
A27: Р768ТР18 | B27: Верещагин | C27: 89128724099 | E27: UNITROL - п/проп 25,0 кг
A28: 3844 НР/HD120 | B28: Воронин | C28: 89536879872 | E28: MEX-ASR - п/проп 25,0 кг
A29: К300КХ67 | B29: Гришкин | C29: 89107215115 | E29: ASPHO-SLIDE - бум 25,0 кг
A30: АВ1548/67 | B30: Гришкин | C30: 89107215115 | E30: Сода кальцинированная
A31: Е868ХК73 | B31: Иванов | C31: 89278017746
A32: Е836ХХ73 | B32: Иванов В | C32: 89093602509
A33: В919МР67 | B33: Корнильев | C33: 89156522978 | E33: КЛОТОНЕКС - бум 25,0 кг
E34: DURATONE - бум 25,0 кг
E35: BURTONE R - бум 25,0 кг
A36: М774НА159 | B36: Костицын | C36: 89194653759 | E36: СТАБИЛАЙТ РУО - бум 25,0 кг
E37: СБМОЙЛБЛОК (Ст РУО) - бум 25,0 кг
A38: К800ЕК67 | B38: Кравцов | C38: 89107115070 | E38: VERSATROL M (Ст РУО) - бум 22,68 кг
E39: ТЕРРАПАН - бум 20,0 кг
A40: Х064ЕС116 | B40: Крюков | C40: 89053743019 | E40: ТЕРРАПАН - бум 25,0 кг
...

Sheet промеж.06
D1: 43617 | E1: 43618 | F1: 43619 | G1: 43620 | H1: 43621 | I1: 43622 | J1: 43623 | K1: 43624 | L1: 43625 | M1: 43626 | N1: 43627 | O1: 43628 | P1: 43629 | Q1: 43630 | R1: 43631 | S1: 43632 | T1: 43633 | U1: 43634 | V1: 43635 | W1: 43636 | X1: 43637 | Y1: 43638 | Z1: 43639 | AA1: 43640 | AB1: 43641 | AC1: 43642 | AD1: 43643 | AE1: 43644 | AF1: 43645 | AG1: 43646 | AH1: 31.06.2019
D2: 1 | E2: 2 | F2: 3 | G2: 4 | H2: 5 | I2: 6 | J2: 7 | K2: 8 | L2: 9 | M2: 10 | N2: 11 | O2: 12 | P2: 13 | Q2: 14 | R2: 15 | S2: 16 | T2: 17 | U2: 18 | V2: 19 | W2: 20 | X2: 21 | Y2: 22 | Z2: 23 | AA2: 24 | AB2: 25 | AC2: 26 | AD2: 27 | AE2: 28 | AF2: 29 | AG2: 30 | AH2: 31
B3: BaraFLC | C3: 22.68 | D3: =SUMIFS(#REF!,#REF!,$B3,#REF!,D$1) -> #REF! | E3: =SUMIFS(#REF!,#REF!,$B3,#REF!,E$1) -> #REF! | F3: =SUMIFS(#REF!,#REF!,$B3,#REF!,F$1) -> #REF! | G3: =SUMIFS(#REF!,#REF!,$B3,#REF!,G$1) -> #REF! | H3: =SUMIFS(#REF!,#REF!,$B3,#REF!,H$1) -> #REF! | I3: =SUMIFS(#REF!,#REF!,$B3,#REF!,I$1) -> #REF! | J3: =SUMIFS(#REF!,#REF!,$B3,#REF!,J$1) -> #REF! | K3: =SUMIFS(#REF!,#REF!,$B3,#REF!,K$1) -> #REF! | ... AH3: =SUMIFS(#REF!,#REF!,$B3,#REF!,AH$1) -> #REF! | AI3: =SUM(D3:AH3) -> #REF!
B4: Стабилайт II п/проп 25 кг | C4: 25 | D4: =SUMIFS(#REF!,#REF!,$B4,#REF!,D$1) -> #REF! | E4: =SUMIFS(#REF!,#REF!,$B4,#REF!,E$1) -> #REF! | F4: =SUMIFS(#REF!,#REF!,$B4,#REF!,F$1) -> #REF! | G4: =SUMIFS(#REF!,#REF!,$B4,#REF!,G$1) -> #REF! | H4: =SUMIFS(#REF!,#REF!,$B4,#REF!,H$1) -> #REF! | I4: =SUMIFS(#REF!,#REF!,$B4,#REF!,I$1) -> #REF! | J4: =SUMIFS(#REF!,#REF!,$B4,#REF!,J$1) -> #REF! | K4: =SUMIFS(#REF!,#REF!,$B4,#REF!,K$1) -> #REF! | ... AH4: =SUMIFS(#REF!,#REF!,$B4,#REF!,AH$1) -> #REF! | AI4: =SUM(D4:AH4) -> #REF!
B5: Стабилайт II марк 25 кг | C5: 25 | D5: =SUMIFS(#REF!,#REF!,$B5,#REF!,D$1) -> #REF! | E5: =SUMIFS(#REF!,#REF!,$B5,#REF!,E$1) -> #REF! | F5: =SUMIFS(#REF!,#REF!,$B5,#REF!,F$1) -> #REF! | G5: =SUMIFS(#REF!,#REF!,$B5,#REF!,G$1) -> #REF! | H5: =SUMIFS(#REF!,#REF!,$B5,#REF!,H$1) -> #REF! | I5: =SUMIFS(#REF!,#REF!,$B5,#REF!,I$1) -> #REF! | J5: =SUMIFS(#REF!,#REF!,$B5,#REF!,J$1) -> #REF! | K5: =SUMIFS(#REF!,#REF!,$B5,#REF!,K$1) -> #REF! | ... AH5: =SUMIFS(#REF!,#REF!,$B5,#REF!,AH$1) -> #REF! | AI5: =SUM(D5:AH5) -> #REF!
B6: Стабилайт II п/проп 22,7 кг | C6: 22.7 | D6: =SUMIFS(#REF!,#REF!,$B6,#REF!,D$1) -> #REF! | E6: =SUMIFS(#REF!,#REF!,$B6,#REF!,E$1) -> #REF! | F6: =SUMIFS(#REF!,#REF!,$B6,#REF!,F$1) -> #REF! | G6: =SUMIFS(#REF!,#REF!,$B6,#REF!,G$1) -> #REF! | H6: =SUMIFS(#REF!,#REF!,$B6,#REF!,H$1) -> #REF! | I6: =SUMIFS(#REF!,#REF!,$B6,#REF!,I$1) -> #REF! | J6: =SUMIFS(#REF!,#REF!,$B6,#REF!,J$1) -> #REF! | K6: =SUMIFS(#REF!,#REF!,$B6,#REF!,K$1) -> #REF! | ... AH6: =SUMIFS(#REF!,#REF!,$B6,#REF!,AH$1) -> #REF! | AI6: =SUM(D6:AH6) -> #REF!
B7: Стабилайт II марк 22,7 кг | C7: 22.7 | D7: =SUMIFS(#REF!,#REF!,$B7,#REF!,D$1) -> #REF! | E7: =SUMIFS(#REF!,#REF!,$B7,#REF!,E$1) -> #REF! | F7: =SUMIFS(#REF!,#REF!,$B7,#REF!,F$1) -> #REF! | G7: =SUMIFS(#REF!,#REF!,$B7,#REF!,G$1) -> #REF! | H7: =SUMIFS(#REF!,#REF!,$B7,#REF!,H$1) -> #REF! | I7: =SUMIFS(#REF!,#REF!,$B7,#REF!,I$1) -> #REF! | J7: =SUMIFS(#REF!,#REF!,$B7,#REF!,J$1) -> #REF! | K7: =SUMIFS(#REF!,#REF!,$B7,#REF!,K$1) -> #REF! | ... AH7: =SUMIFS(#REF!,#REF!,$B7,#REF!,AH$1) -> #REF! | AI7: =SUM(D7:AH7) -> #REF!
B8: Реасолт | C8: 22.7 | D8: =SUMIFS(#REF!,#REF!,$B8,#REF!,D$1) -> #REF! | E8: =SUMIFS(#REF!,#REF!,$B8,#REF!,E$1) -> #REF! | F8: =SUMIFS(#REF!,#REF!,$B8,#REF!,F$1) -> #REF! | G8: =SUMIFS(#REF!,#REF!,$B8,#REF!,G$1) -> #REF! | H8: =SUMIFS(#REF!,#REF!,$B8,#REF!,H$1) -> #REF! | I8: =SUMIFS(#REF!,#REF!,$B8,#REF!,I$1) -> #REF! | J8: =SUMIFS(#REF!,#REF!,$B8,#REF!,J$1) -> #REF! | K8: =SUMIFS(#REF!,#REF!,$B8,#REF!,K$1) -> #REF! | ... AH8: =SUMIFS(#REF!,#REF!,$B8,#REF!,AH$1) -> #REF! | AI8: =SUM(D8:AH8) -> #REF!
B9: UNITROL | C9: 25 | D9: =SUMIFS(#REF!,#REF!,$B9,#REF!,D$1) -> #REF! | E9: =SUMIFS(#REF!,#REF!,$B9,#REF!,E$1) -> #REF! | F9: =SUMIFS(#REF!,#REF!,$B9,#REF!,F$1) -> #REF! | G9: =SUMIFS(#REF!,#REF!,$B9,#REF!,G$1) -> #REF! | H9: =SUMIFS(#REF!,#REF!,$B9,#REF!,H$1) -> #REF! | I9: =SUMIFS(#REF!,#REF!,$B9,#REF!,I$1) -> #REF! | J9: =SUMIFS(#REF!,#REF!,$B9,#REF!,J$1) -> #REF! | K9: =SUMIFS(#REF!,#REF!,$B9,#REF!,K$1) -> #REF! | ... AH9: =SUMIFS(#REF!,#REF!,$B9,#REF!,AH$1) -> #REF! | AI9: =SUM(D9:AH9) -> #REF!
B10: MEX-ASR | C10: 22.7 | D10: =SUMIFS(#REF!,#REF!,$B10,#REF!,D$1) -> #REF! | E10: =SUMIFS(#REF!,#REF!,$B10,#REF!,E$1) -> #REF! | F10: =SUMIFS(#REF!,#REF!,$B10,#REF!,F$1) -> #REF! | G10: =SUMIFS(#REF!,#REF!,$B10,#REF!,G$1) -> #REF! | H10: =SUMIFS(#REF!,#REF!,$B10,#REF!,H$1) -> #REF! | I10: =SUMIFS(#REF!,#REF!,$B10,#REF!,I$1) -> #REF! | J10: =SUMIFS(#REF!,#REF!,$B10,#REF!,J$1) -> #REF! | K10: =SUMIFS(#REF!,#REF!,$B10,#REF!,K$1) -> #REF! | ... AH10: =SUMIFS(#REF!,#REF!,$B10,#REF!,AH$1) -> #REF! | AI10: =SUM(D10:AH10) -> #REF!
B12: КЛСП | C12: 20 | D12: =SUMIFS(#REF!,#REF!,$B12,#REF!,D$1) -> #REF! | E12: =SUMIFS(#REF!,#REF!,$B12,#REF!,E$1) -> #REF! | F12: =SUMIFS(#REF!,#REF!,$B12,#REF!,F$1) -> #REF! | G12: =SUMIFS(#REF!,#REF!,$B12,#REF!,G$1) -> #REF! | H12: =SUMIFS(#REF!,#REF!,$B12,#REF!,H$1) -> #REF! | I12: =SUMIFS(#REF!,#REF!,$B12,#REF!,I$1) -> #REF! | J12: =SUMIFS(#REF!,#REF!,$B12,#REF!,J$1) -> #REF! | K12: =SUMIFS(#REF!,#REF!,$B12,#REF!,K$1) -> #REF! | ... AH12: =SUMIFS(#REF!,#REF!,$B12,#REF!,AH$1) -> #REF! | AI12: =SUM(D12:AH12) -> #REF!
B13: R2D2 | C13: 20 | D13: =SUMIFS(#REF!,#REF!,$B13,#REF!,D$1) -> #REF! | E13: =SUMIFS(#REF!,#REF!,$B13,#REF!,E$1) -> #REF! | F13: =SUMIFS(#REF!,#REF!,$B13,#REF!,F$1) -> #REF! | G13: =SUMIFS(#REF!,#REF!,$B13,#REF!,G$1) -> #REF! | H13: =SUMIFS(#REF!,#REF!,$B13,#REF!,H$1) -> #REF! | I13: =SUMIFS(#REF!,#REF!,$B13,#REF!,I$1) -> #REF! | J13: =SUMIFS(#REF!,#REF!,$B13,#REF!,J$1) -> #REF! | K13: =SUMIFS(#REF!,#REF!,$B13,#REF!,K$1) -> #REF! | ... AH13: =SUMIFS(#REF!,#REF!,$B13,#REF!,AH$1) -> #REF! | AI13: =SUM(D13:AH13) -> #REF!
B14: Оптитрол Порошок 20 кг | C14: 20 | D14: =SUMIFS(#REF!,#REF!,$B14,#REF!,D$1) -> #REF! | E14: =SUMIFS(#REF!,#REF!,$B14,#REF!,E$1) -> #REF! | F14: =SUMIFS(#REF!,#REF!,$B14,#REF!,F$1) -> #REF! | G14: =SUMIFS(#REF!,#REF!,$B14,#REF!,G$1) -> #REF! | H14: =SUMIFS(#REF!,#REF!,$B14,#REF!,H$1) -> #REF! | I14: =SUMIFS(#REF!,#REF!,$B14,#REF!,I$1) -> #REF! | J14: =SUMIFS(#REF!,#REF!,$B14,#REF!,J$1) -> #REF! | K14: =SUMIFS(#REF!,#REF!,$B14,#REF!,K$1) -> #REF! | ... AH14: =SUMIFS(#REF!,#REF!,$B14,#REF!,AH$1) -> #REF! | AI14: =SUM(D14:AH14) -> #REF!
B15: Оптитрол (УЩР 30%) | C15: 20 | D15: =SUMIFS(#REF!,#REF!,$B15,#REF!,D$1) -> #REF! | E15: =SUMIFS(#REF!,#REF!,$B15,#REF!,E$1) -> #REF! | F15: =SUMIFS(#REF!,#REF!,$B15,#REF!,F$1) -> #REF! | G15: =SUMIFS(#REF!,#REF!,$B15,#REF!,G$1) -> #REF! | H15: =SUMIFS(#REF!,#REF!,$B15,#REF!,H$1) -> #REF! | I15: =SUMIFS(#REF!,#REF!,$B15,#REF!,I$1) -> #REF! | J15: =SUMIFS(#REF!,#REF!,$B15,#REF!,J$1) -> #REF! | K15: =SUMIFS(#REF!,#REF!,$B15,#REF!,K$1) -> #REF! | ... AH15: =SUMIFS(#REF!,#REF!,$B15,#REF!,AH$1) -> #REF! | AI15: =SUM(D15:AH15) -> #REF!
... B26: КЛСП без КМЦ на переработку | C26: 20 | D26: =SUMIFS(#REF!,#REF!,$B26,#REF!,D$1) -> #REF! | E26: =SUMIFS(#REF!,#REF!,$B26,#REF!,E$1) -> #REF! | F26: =SUMIFS(#REF!,#REF!,$B26,#REF!,F$1) -> #REF! | G26: =SUMIFS(#REF!,#REF!,$B26,#REF!,G$1) -> #REF! | H26: =SUMIFS(#REF!,#REF!,$B26,#REF!,H$1) -> #REF! | I26: =SUMIFS(#REF!,#REF!,$B26,#REF!,I$1) -> #REF! | J26: =SUMIFS(#REF!,#REF!,$B26,#REF!,J$1) -> #REF! | K26: =SUMIFS(#REF!,#REF!,$B26,#REF!,K$1) -> #REF! | ... AH26: =SUMIFS(#REF!,#REF!,$B26,#REF!,AH$1) -> #REF! | AI26: =SUM(D26:AH26) -> #REF!

Sheet промеж.
D1: 43586 | E1: 43587 | F1: 43588 | G1: 43589 | H1: 43590 | I1: 43591 | J1: 43592 | K1: 43593 | L1: 43594 | M1: 43595 | N1: 43596 | O1: 43597 | P1: 43598 | Q1: 43599 | R1: 43600 | S1: 43601 | T1: 43602 | U1: 43603 | V1: 43604 | W1: 43605 | X1: 43606 | Y1: 43607 | Z1: 43608 | AA1: 43609 | AB1: 43610 | AC1: 43611 | AD1: 43612 | AE1: 43613 | AF1: 43614 | AG1: 43615 | AH1: 43616
D2: 1 | E2: 2 | F2: 3 | G2: 4 | H2: 5 | I2: 6 | J2: 7 | K2: 8 | L2: 9 | M2: 10 | N2: 11 | O2: 12 | P2: 13 | Q2: 14 | R2: 15 | S2: 16 | T2: 17 | U2: 18 | V2: 19 | W2: 20 | X2: 21 | Y2: 22 | Z2: 23 | AA2: 24 | AB2: 25 | AC2: 26 | AD2: 27 | AE2: 28 | AF2: 29 | AG2: 30 | AH2: 31
B3: BaraFLC | C3: 22.68 | D3: =SUMIFS(#REF!,#REF!,$B3,#REF!,D$1) -> #REF! | E3: =SUMIFS(#REF!,#REF!,$B3,#REF!,E$1) -> #REF! | F3: =SUMIFS(#REF!,#REF!,$B3,#REF!,F$1) -> #REF! | G3: =SUMIFS(#REF!,#REF!,$B3,#REF!,G$1) -> #REF! | H3: =SUMIFS(#REF!,#REF!,$B3,#REF!,H$1) -> #REF! | I3: =SUMIFS(#REF!,#REF!,$B3,#REF!,I$1) -> #REF! | J3: =SUMIFS(#REF!,#REF!,$B3,#REF!,J$1) -> #REF! | K3: =SUMIFS(#REF!,#REF!,$B3,#REF!,K$1) -> #REF! | ... AH3: =SUMIFS(#REF!,#REF!,$B3,#REF!,AH$1) -> #REF! | AI3: =SUM(D3:AH3) -> #REF!
B4: Стабилайт II п/проп 25 кг | C4: 25 | D4: =SUMIFS(#REF!,#REF!,$B4,#REF!,D$1) -> #REF! | E4: =SUMIFS(#REF!,#REF!,$B4,#REF!,E$1) -> #REF! | F4: =SUMIFS(#REF!,#REF!,$B4,#REF!,F$1) -> #REF! | G4: =SUMIFS(#REF!,#REF!,$B4,#REF!,G$1) -> #REF! | H4: =SUMIFS(#REF!,#REF!,$B4,#REF!,H$1) -> #REF! | I4: =SUMIFS(#REF!,#REF!,$B4,#REF!,I$1) -> #REF! | J4: =SUMIFS(#REF!,#REF!,$B4,#REF!,J$1) -> #REF! | K4: =SUMIFS(#REF!,#REF!,$B4,#REF!,K$1) -> #REF! | ... AH4: =SUMIFS(#REF!,#REF!,$B4,#REF!,AH$1) -> #REF! | AI4: =SUM(D4:AH4) -> #REF!
B5: Стабилайт II марк 25 кг | C5: 25 | D5: =SUMIFS(#REF!,#REF!,$B5,#REF!,D$1) -> #REF! | E5: =SUMIFS(#REF!,#REF!,$B5,#REF!,E$1) -> #REF! | F5: =SUMIFS(#REF!,#REF!,$B5,#REF!,F$1) -> #REF! | G5: =SUMIFS(#REF!,#REF!,$B5,#REF!,G$1) -> #REF! | H5: =SUMIFS(#REF!,#REF!,$B5,#REF!,H$1) -> #REF! | I5: =SUMIFS(#REF!,#REF!,$B5,#REF!,I$1) -> #REF! | J5: =SUMIFS(#REF!,#REF!,$B5,#REF!,J$1) -> #REF! | K5: =SUMIFS(#REF!,#REF!,$B5,#REF!,K$1) -> #REF! | ... AH5: =SUMIFS(#REF!,#REF!,$B5,#REF!,AH$1) -> #REF! | AI5: =SUM(D5:AH5) -> #REF!
B6: Стабилайт II п/проп 22,7 кг | C6: 22.7 | D6: =SUMIFS(#REF!,#REF!,$B6,#REF!,D$1) -> #REF! | E6: =SUMIFS(#REF!,#REF!,$B6,#REF!,E$1) -> #REF! | F6: =SUMIFS(#REF!,#REF!,$B6,#REF!,F$1) -> #REF! | G6: =SUMIFS(#REF!,#REF!,$B6,#REF!,G$1) -> #REF! | H6: =SUMIFS(#REF!,#REF!,$B6,#REF!,H$1) -> #REF! | I6: =SUMIFS(#REF!,#REF!,$B6,#REF!,I$1) -> #REF! | J6: =SUMIFS(#REF!,#REF!,$B6,#REF!,J$1) -> #REF! | K6: =SUMIFS(#REF!,#REF!,$B6,#REF!,K$1) -> #REF! | ... AH6: =SUMIFS(#REF!,#REF!,$B6,#REF!,AH$1) -> #REF! | AI6: =SUM(D6:AH6) -> #REF!
B7: Стабилайт II марк 22,7 кг | C7: 22.7 | D7: =SUMIFS(#REF!,#REF!,$B7,#REF!,D$1) -> #REF! | E7: =SUMIFS(#REF!,#REF!,$B7,#REF!,E$1) -> #REF! | F7: =SUMIFS(#REF!,#REF!,$B7,#REF!,F$1) -> #REF! | G7: =SUMIFS(#REF!,#REF!,$B7,#REF!,G$1) -> #REF! | H7: =SUMIFS(#REF!,#REF!,$B7,#REF!,H$1) -> #REF! | I7: =SUMIFS(#REF!,#REF!,$B7,#REF!,I$1) -> #REF! | J7: =SUMIFS(#REF!,#REF!,$B7,#REF!,J$1) -> #REF! | K7: =SUMIFS(#REF!,#REF!,$B7,#REF!,K$1) -> #REF! | ... AH7: =SUMIFS(#REF!,#REF!,$B7,#REF!,AH$1) -> #REF! | AI7: =SUM(D7:AH7) -> #REF!
B8: Реасолт | C8: 22.7 | D8: =SUMIFS(#REF!,#REF!,$B8,#REF!,D$1) -> #REF! | E8: =SUMIFS(#REF!,#REF!,$B8,#REF!,E$1) -> #REF! | F8: =SUMIFS(#REF!,#REF!,$B8,#REF!,F$1) -> #REF! | G8: =SUMIFS(#REF!,#REF!,$B8,#REF!,G$1) -> #REF! | H8: =SUMIFS(#REF!,#REF!,$B8,#REF!,H$1) -> #REF! | I8: =SUMIFS(#REF!,#REF!,$B8,#REF!,I$1) -> #REF! | J8: =SUMIFS(#REF!,#REF!,$B8,#REF!,J$1) -> #REF! | K8: =SUMIFS(#REF!,#REF!,$B8,#REF!,K$1) -> #REF! | ... AH8: =SUMIFS(#REF!,#REF!,$B8,#REF!,AH$1) -> #REF! | AI8: =SUM(D8:AH8) -> #REF!
B9: UNITROL | C9: 25 | D9: =SUMIFS(#REF!,#REF!,$B9,#REF!,D$1) -> #REF! | E9: =SUMIFS(#REF!,#REF!,$B9,#REF!,E$1) -> #REF! | F9: =SUMIFS(#REF!,#REF!,$B9,#REF!,F$1) -> #REF! | G9: =SUMIFS(#REF!,#REF!,$B9,#REF!,G$1) -> #REF! | H9: =SUMIFS(#REF!,#REF!,$B9,#REF!,H$1) -> #REF! | I9: =SUMIFS(#REF!,#REF!,$B9,#REF!,I$1) -> #REF! | J9: =SUMIFS(#REF!,#REF!,$B9,#REF!,J$1) -> #REF! | K9: =SUMIFS(#REF!,#REF!,$B9,#REF!,K$1) -> #REF! | ... AH9: =SUMIFS(#REF!,#REF!,$B9,#REF!,AH$1) -> #REF! | AI9: =SUM(D9:AH9) -> #REF!
B10: MEX-ASR | C10: 22.7 | D10: =SUMIFS(#REF!,#REF!,$B10,#REF!,D$1) -> #REF! | E10: =SUMIFS(#REF!,#REF!,$B10,#REF!,E$1) -> #REF! | F10: =SUMIFS(#REF!,#REF!,$B10,#REF!,F$1) -> #REF! | G10: =SUMIFS(#REF!,#REF!,$B10,#REF!,G$1) -> #REF! | H10: =SUMIFS(#REF!,#REF!,$B10,#REF!,H$1) -> #REF! | I10: =SUMIFS(#REF!,#REF!,$B10,#REF!,I$1) -> #REF! | J10: =SUMIFS(#REF!,#REF!,$B10,#REF!,J$1) -> #REF! | K10: =SUMIFS(#REF!,#REF!,$B10,#REF!,K$1) -> #REF! | ... AH10: =SUMIFS(#REF!,#REF!,$B10,#REF!,AH$1) -> #REF! | AI10: =SUM(D10:AH10) -> #REF!
